Workbook

Sheet Control
A2: Bank | B2: Banca Sarda
A3: Rate | B3: 0.03
A4: Week | B4: 40

Sheet Data
A1: Bank | B1: Week | C1: Loans | D1: Deposits | E1: Fees
A2: Banca Alpi | B2: 1 | C2: 887.06 | D2: 1153.2 | E2: 8.871
A3: Banca Alpi | B3: 2 | C3: 868.51 | D3: 1129.1 | E3: 8.685
A4: Banca Alpi | B4: 3 | C4: 859.91 | D4: 1117.9 | E4: 8.599
A5: Banca Alpi | B5: 4 | C5: 873.02 | D5: 1134.9 | E5: 8.73
A6: Banca Alpi | B6: 5 | C6: 869.66 | D6: 1130.6 | E6: 8.697
A7: Banca Alpi | B7: 6 | C7: 956.86 | D7: 1243.9 | E7: 9.569
A8: Banca Alpi | B8: 7 | C8: 958.08 | D8: 1245.5 | E8: 9.581
A9: Banca Alpi | B9: 8 | C9: 895.82 | D9: 1164.6 | E9: 8.958
A10: Banca Alpi | B10: 9 | C10: 894.18 | D10: 1162.4 | E10: 8.942
A11: Banca Alpi | B11: 10 | C11: 896.6 | D11: 1165.6 | E11: 8.966
A12: Banca Alpi | B12: 11 | C12: 906.71 | D12: 1178.7 | E12: 9.067
A13: Banca Alpi | B13: 12 | C13: 890.44 | D13: 1157.6 | E13: 8.904
... A1041: Banca Città | B1041: 52 | C1041: 3702.13 | D1041: 4812.8 | E1041: 37.021

Sheet Base
A2: Bank \ week | B2: 1 | C2: 2 | D2: 3 | E2: 4 | F2: 5 | G2: 6 | H2: 7 | I2: 8 | J2: 9 | K2: 10 | L2: 11 | M2: 12 | N2: 13 | O2: 14 | P2: 15 | Q2: 16 | R2: 17 | S2: 18 | T2: 19 | U2: 20 | V2: 21 | W2: 22 | X2: 23 | Y2: 24 | Z2: 25 | AA2: 26 | AB2: 27 | AC2: 28 | AD2: 29 | AE2: 30 | AF2: 31 | AG2: 32 | AH2: 33 | AI2: 34 | AJ2: 35 | AK2: 36 | AL2: 37 | AM2: 38 | AN2: 39 | AO2: 40 | AP2: 41 | AQ2: 42 | AR2: 43 | AS2: 44 | AT2: 45 | AU2: 46 | AV2: 47 | AW2: 48 | AX2: 49 | AY2: 50 | AZ2: 51 | BA2: 52
A3: Banca Alpi | B3: =SUMIFS(Data!$C$2:$C$1041,Data!$A$2:$A$1041,$A3,Data!$B$2:$B$1041,B$2)*IF($A3=Control!$B$2,1+Control!$B$3,1) -> 887.06 | C3: =SUMIFS(Data!$C$2:$C$1041,Data!$A$2:$A$1041,$A3,Data!$B$2:$B$1041,C$2)*IF($A3=Control!$B$2,1+Control!$B$3,1) -> 868.51 | D3: =SUMIFS(Data!$C$2:$C$1041,Data!$A$2:$A$1041,$A3,Data!$B$2:$B$1041,D$2)*IF($A3=Control!$B$2,1+Control!$B$3,1) -> 859.91 | E3: =SUMIFS(Data!$C$2:$C$1041,Data!$A$2:$A$1041,$A3,Data!$B$2:$B$1041,E$2)*IF($A3=Control!$B$2,1+Control!$B$3,1) -> 873.02 | F3: =SUMIFS(Data!$C$2:$C$1041,Data!$A$2:$A$1041,$A3,Data!$B$2:$B$1041,F$2)*IF($A3=Control!$B$2,1+Control!$B$3,1) -> 869.66 | G3: =SUMIFS(Data!$C$2:$C$1041,Data!$A$2:$A$1041,$A3,Data!$B$2:$B$1041,G$2)*IF($A3=Control!$B$2,1+Control!$B$3,1) -> 956.86 | H3: =SUMIFS(Data!$C$2:$C$1041,Data!$A$2:$A$1041,$A3,Data!$B$2:$B$1041,H$2)*IF($A3=Control!$B$2,1+Control!$B$3,1) -> 958.08 | I3: =SUMIFS(Data!$C$2:$C$1041,Data!$A$2:$A$1041,$A3,Data!$B$2:$B$1041,I$2)*IF($A3=Control!$B$2,1+Control!$B$3,1) -> 895.82 | ... BA3: =SUMIFS(Data!$C$2:$C$1041,Data!$A$2:$A$1041,$A3,Data!$B$2:$B$1041,BA$2)*IF($A3=Control!$B$2,1+Control!$B$3,1) -> 1065.32
A4: Banca Adriatica | B4: =SUMIFS(Data!$C$2:$C$1041,Data!$A$2:$A$1041,$A4,Data!$B$2:$B$1041,B$2)*IF($A4=Control!$B$2,1+Control!$B$3,1) -> 1037.36 | C4: =SUMIFS(Data!$C$2:$C$1041,Data!$A$2:$A$1041,$A4,Data!$B$2:$B$1041,C$2)*IF($A4=Control!$B$2,1+Control!$B$3,1) -> 1070.65 | D4: =SUMIFS(Data!$C$2:$C$1041,Data!$A$2:$A$1041,$A4,Data!$B$2:$B$1041,D$2)*IF($A4=Control!$B$2,1+Control!$B$3,1) -> 1053.11 | E4: =SUMIFS(Data!$C$2:$C$1041,Data!$A$2:$A$1041,$A4,Data!$B$2:$B$1041,E$2)*IF($A4=Control!$B$2,1+Control!$B$3,1) -> 1058.96 | F4: =SUMIFS(Data!$C$2:$C$1041,Data!$A$2:$A$1041,$A4,Data!$B$2:$B$1041,F$2)*IF($A4=Control!$B$2,1+Control!$B$3,1) -> 1009.78 | G4: =SUMIFS(Data!$C$2:$C$1041,Data!$A$2:$A$1041,$A4,Data!$B$2:$B$1041,G$2)*IF($A4=Control!$B$2,1+Control!$B$3,1) -> 1048.91 | H4: =SUMIFS(Data!$C$2:$C$1041,Data!$A$2:$A$1041,$A4,Data!$B$2:$B$1041,H$2)*IF($A4=Control!$B$2,1+Control!$B$3,1) -> 1081.75 | I4: =SUMIFS(Data!$C$2:$C$1041,Data!$A$2:$A$1041,$A4,Data!$B$2:$B$1041,I$2)*IF($A4=Control!$B$2,1+Control!$B$3,1) -> 1053.13 | ... BA4: =SUMIFS(Data!$C$2:$C$1041,Data!$A$2:$A$1041,$A4,Data!$B$2:$B$1041,BA$2)*IF($A4=Control!$B$2,1+Control!$B$3,1) -> 1178.52
A5: Banca Tirrena | B5: =SUMIFS(Data!$C$2:$C$1041,Data!$A$2:$A$1041,$A5,Data!$B$2:$B$1041,B$2)*IF($A5=Control!$B$2,1+Control!$B$3,1) -> 1157.79 | C5: =SUMIFS(Data!$C$2:$C$1041,Data!$A$2:$A$1041,$A5,Data!$B$2:$B$1041,C$2)*IF($A5=Control!$B$2,1+Control!$B$3,1) -> 1193.58 | D5: =SUMIFS(Data!$C$2:$C$1041,Data!$A$2:$A$1041,$A5,Data!$B$2:$B$1041,D$2)*IF($A5=Control!$B$2,1+Control!$B$3,1) -> 1139.21 | E5: =SUMIFS(Data!$C$2:$C$1041,Data!$A$2:$A$1041,$A5,Data!$B$2:$B$1041,E$2)*IF($A5=Control!$B$2,1+Control!$B$3,1) -> 1163.47 | F5: =SUMIFS(Data!$C$2:$C$1041,Data!$A$2:$A$1041,$A5,Data!$B$2:$B$1041,F$2)*IF($A5=Control!$B$2,1+Control!$B$3,1) -> 1158.55 | G5: =SUMIFS(Data!$C$2:$C$1041,Data!$A$2:$A$1041,$A5,Data!$B$2:$B$1041,G$2)*IF($A5=Control!$B$2,1+Control!$B$3,1) -> 1162.1 | H5: =SUMIFS(Data!$C$2:$C$1041,Data!$A$2:$A$1041,$A5,Data!$B$2:$B$1041,H$2)*IF($A5=Control!$B$2,1+Control!$B$3,1) -> 1169.49 | I5: =SUMIFS(Data!$C$2:$C$1041,Data!$A$2:$A$1041,$A5,Data!$B$2:$B$1041,I$2)*IF($A5=Control!$B$2,1+Control!$B$3,1) -> 1193.87 | ... BA5: =SUMIFS(Data!$C$2:$C$1041,Data!$A$2:$A$1041,$A5,Data!$B$2:$B$1041,BA$2)*IF($A5=Control!$B$2,1+Control!$B$3,1) -> 1279.22
A6: Banca Padana | B6: =SUMIFS(Data!$C$2:$C$1041,Data!$A$2:$A$1041,$A6,Data!$B$2:$B$1041,B$2)*IF($A6=Control!$B$2,1+Control!$B$3,1) -> 1233.46 | C6: =SUMIFS(Data!$C$2:$C$1041,Data!$A$2:$A$1041,$A6,Data!$B$2:$B$1041,C$2)*IF($A6=Control!$B$2,1+Control!$B$3,1) -> 1279.76 | D6: =SUMIFS(Data!$C$2:$C$1041,Data!$A$2:$A$1041,$A6,Data!$B$2:$B$1041,D$2)*IF($A6=Control!$B$2,1+Control!$B$3,1) -> 1248.7 | E6: =SUMIFS(Data!$C$2:$C$1041,Data!$A$2:$A$1041,$A6,Data!$B$2:$B$1041,E$2)*IF($A6=Control!$B$2,1+Control!$B$3,1) -> 1302.74 | F6: =SUMIFS(Data!$C$2:$C$1041,Data!$A$2:$A$1041,$A6,Data!$B$2:$B$1041,F$2)*IF($A6=Control!$B$2,1+Control!$B$3,1) -> 1321.57 | G6: =SUMIFS(Data!$C$2:$C$1041,Data!$A$2:$A$1041,$A6,Data!$B$2:$B$1041,G$2)*IF($A6=Control!$B$2,1+Control!$B$3,1) -> 1269.69 | H6: =SUMIFS(Data!$C$2:$C$1041,Data!$A$2:$A$1041,$A6,Data!$B$2:$B$1041,H$2)*IF($A6=Control!$B$2,1+Control!$B$3,1) -> 1316.48 | I6: =SUMIFS(Data!$C$2:$C$1041,Data!$A$2:$A$1041,$A6,Data!$B$2:$B$1041,I$2)*IF($A6=Control!$B$2,1+Control!$B$3,1) -> 1272.44 | ... BA6: =SUMIFS(Data!$C$2:$C$1041,Data!$A$2:$A$1041,$A6,Data!$B$2:$B$1041,BA$2)*IF($A6=Control!$B$2,1+Control!$B$3,1) -> 1472.09
A7: Banca Etrusca | B7: =SUMIFS(Data!$C$2:$C$1041,Data!$A$2:$A$1041,$A7,Data!$B$2:$B$1041,B$2)*IF($A7=Control!$B$2,1+Control!$B$3,1) -> 1368.66 | C7: =SUMIFS(Data!$C$2:$C$1041,Data!$A$2:$A$1041,$A7,Data!$B$2:$B$1041,C$2)*IF($A7=Control!$B$2,1+Control!$B$3,1) -> 1357.34 | D7: =SUMIFS(Data!$C$2:$C$1041,Data!$A$2:$A$1041,$A7,Data!$B$2:$B$1041,D$2)*IF($A7=Control!$B$2,1+Control!$B$3,1) -> 1381.97 | E7: =SUMIFS(Data!$C$2:$C$1041,Data!$A$2:$A$1041,$A7,Data!$B$2:$B$1041,E$2)*IF($A7=Control!$B$2,1+Control!$B$3,1) -> 1354.47 | F7: =SUMIFS(Data!$C$2:$C$1041,Data!$A$2:$A$1041,$A7,Data!$B$2:$B$1041,F$2)*IF($A7=Control!$B$2,1+Control!$B$3,1) -> 1391.99 | G7: =SUMIFS(Data!$C$2:$C$1041,Data!$A$2:$A$1041,$A7,Data!$B$2:$B$1041,G$2)*IF($A7=Control!$B$2,1+Control!$B$3,1) -> 1402.61 | H7: =SUMIFS(Data!$C$2:$C$1041,Data!$A$2:$A$1041,$A7,Data!$B$2:$B$1041,H$2)*IF($A7=Control!$B$2,1+Control!$B$3,1) -> 1456.62 | I7: =SUMIFS(Data!$C$2:$C$1041,Data!$A$2:$A$1041,$A7,Data!$B$2:$B$1041,I$2)*IF($A7=Control!$B$2,1+Control!$B$3,1) -> 1436.22 | ... BA7: =SUMIFS(Data!$C$2:$C$1041,Data!$A$2:$A$1041,$A7,Data!$B$2:$B$1041,BA$2)*IF($A7=Control!$B$2,1+Control!$B$3,1) -> 1594.77
A8: Banca Lariana | B8: =SUMIFS(Data!$C$2:$C$1041,Data!$A$2:$A$1041,$A8,Data!$B$2:$B$1041,B$2)*IF($A8=Control!$B$2,1+Control!$B$3,1) -> 1496.27 | C8: =SUMIFS(Data!$C$2:$C$1041,Data!$A$2:$A$1041,$A8,Data!$B$2:$B$1041,C$2)*IF($A8=Control!$B$2,1+Control!$B$3,1) -> 1465.82 | D8: =SUMIFS(Data!$C$2:$C$1041,Data!$A$2:$A$1041,$A8,Data!$B$2:$B$1041,D$2)*IF($A8=Control!$B$2,1+Control!$B$3,1) -> 1550.98 | E8: =SUMIFS(Data!$C$2:$C$1041,Data!$A$2:$A$1041,$A8,Data!$B$2:$B$1041,E$2)*IF($A8=Control!$B$2,1+Control!$B$3,1) -> 1537.94 | F8: =SUMIFS(Data!$C$2:$C$1041,Data!$A$2:$A$1041,$A8,Data!$B$2:$B$1041,F$2)*IF($A8=Control!$B$2,1+Control!$B$3,1) -> 1482.26 | G8: =SUMIFS(Data!$C$2:$C$1041,Data!$A$2:$A$1041,$A8,Data!$B$2:$B$1041,G$2)*IF($A8=Control!$B$2,1+Control!$B$3,1) -> 1541.62 | H8: =SUMIFS(Data!$C$2:$C$1041,Data!$A$2:$A$1041,$A8,Data!$B$2:$B$1041,H$2)*IF($A8=Control!$B$2,1+Control!$B$3,1) -> 1488.59 | I8: =SUMIFS(Data!$C$2:$C$1041,Data!$A$2:$A$1041,$A8,Data!$B$2:$B$1041,I$2)*IF($A8=Control!$B$2,1+Control!$B$3,1) -> 1556.23 | ... BA8: =SUMIFS(Data!$C$2:$C$1041,Data!$A$2:$A$1041,$A8,Data!$B$2:$B$1041,BA$2)*IF($A8=Control!$B$2,1+Control!$B$3,1) -> 1700.48
A9: Banca Sabina | B9: =SUMIFS(Data!$C$2:$C$1041,Data!$A$2:$A$1041,$A9,Data!$B$2:$B$1041,B$2)*IF($A9=Control!$B$2,1+Control!$B$3,1) -> 1660.82 | C9: =SUMIFS(Data!$C$2:$C$1041,Data!$A$2:$A$1041,$A9,Data!$B$2:$B$1041,C$2)*IF($A9=Control!$B$2,1+Control!$B$3,1) -> 1655.25 | D9: =SUMIFS(Data!$C$2:$C$1041,Data!$A$2:$A$1041,$A9,Data!$B$2:$B$1041,D$2)*IF($A9=Control!$B$2,1+Control!$B$3,1) -> 1604.27 | E9: =SUMIFS(Data!$C$2:$C$1041,Data!$A$2:$A$1041,$A9,Data!$B$2:$B$1041,E$2)*IF($A9=Control!$B$2,1+Control!$B$3,1) -> 1676.73 | F9: =SUMIFS(Data!$C$2:$C$1041,Data!$A$2:$A$1041,$A9,Data!$B$2:$B$1041,F$2)*IF($A9=Control!$B$2,1+Control!$B$3,1) -> 1624.83 | G9: =SUMIFS(Data!$C$2:$C$1041,Data!$A$2:$A$1041,$A9,Data!$B$2:$B$1041,G$2)*IF($A9=Control!$B$2,1+Control!$B$3,1) -> 1682.33 | H9: =SUMIFS(Data!$C$2:$C$1041,Data!$A$2:$A$1041,$A9,Data!$B$2:$B$1041,H$2)*IF($A9=Control!$B$2,1+Control!$B$3,1) -> 1639.17 | I9: =SUMIFS(Data!$C$2:$C$1041,Data!$A$2:$A$1041,$A9,Data!$B$2:$B$1041,I$2)*IF($A9=Control!$B$2,1+Control!$B$3,1) -> 1706.42 | ... BA9: =SUMIFS(Data!$C$2:$C$1041,Data!$A$2:$A$1041,$A9,Data!$B$2:$B$1041,BA$2)*IF($A9=Control!$B$2,1+Control!$B$3,1) -> 1912.95
A10: Banca Irpina | B10: =SUMIFS(Data!$C$2:$C$1041,Data!$A$2:$A$1041,$A10,Data!$B$2:$B$1041,B$2)*IF($A10=Control!$B$2,1+Control!$B$3,1) -> 1697.53 | C10: =SUMIFS(Data!$C$2:$C$1041,Data!$A$2:$A$1041,$A10,Data!$B$2:$B$1041,C$2)*IF($A10=Control!$B$2,1+Control!$B$3,1) -> 1786.13 | D10: =SUMIFS(Data!$C$2:$C$1041,Data!$A$2:$A$1041,$A10,Data!$B$2:$B$1041,D$2)*IF($A10=Control!$B$2,1+Control!$B$3,1) -> 1802.26 | E10: =SUMIFS(Data!$C$2:$C$1041,Data!$A$2:$A$1041,$A10,Data!$B$2:$B$1041,E$2)*IF($A10=Control!$B$2,1+Control!$B$3,1) -> 1751.19 | F10: =SUMIFS(Data!$C$2:$C$1041,Data!$A$2:$A$1041,$A10,Data!$B$2:$B$1041,F$2)*IF($A10=Control!$B$2,1+Control!$B$3,1) -> 1778.96 | G10: =SUMIFS(Data!$C$2:$C$1041,Data!$A$2:$A$1041,$A10,Data!$B$2:$B$1041,G$2)*IF($A10=Control!$B$2,1+Control!$B$3,1) -> 1765.61 | H10: =SUMIFS(Data!$C$2:$C$1041,Data!$A$2:$A$1041,$A10,Data!$B$2:$B$1041,H$2)*IF($A10=Control!$B$2,1+Control!$B$3,1) -> 1759.44 | I10: =SUMIFS(Data!$C$2:$C$1041,Data!$A$2:$A$1041,$A10,Data!$B$2:$B$1041,I$2)*IF($A10=Control!$B$2,1+Control!$B$3,1) -> 1765.6 | ... BA10: =SUMIFS(Data!$C$2:$C$1041,Data!$A$2:$A$1041,$A10,Data!$B$2:$B$1041,BA$2)*IF($A10=Control!$B$2,1+Control!$B$3,1) -> 2042.47
A11: Banca Sannita | B11: =SUMIFS(Data!$C$2:$C$1041,Data!$A$2:$A$1041,$A11,Data!$B$2:$B$1041,B$2)*IF($A11=Control!$B$2,1+Control!$B$3,1) -> 1840.76 | C11: =SUMIFS(Data!$C$2:$C$1041,Data!$A$2:$A$1041,$A11,Data!$B$2:$B$1041,C$2)*IF($A11=Control!$B$2,1+Control!$B$3,1) -> 1892.46 | D11: =SUMIFS(Data!$C$2:$C$1041,Data!$A$2:$A$1041,$A11,Data!$B$2:$B$1041,D$2)*IF($A11=Control!$B$2,1+Control!$B$3,1) -> 1854.83 | E11: =SUMIFS(Data!$C$2:$C$1041,Data!$A$2:$A$1041,$A11,Data!$B$2:$B$1041,E$2)*IF($A11=Control!$B$2,1+Control!$B$3,1) -> 1868.21 | F11: =SUMIFS(Data!$C$2:$C$1041,Data!$A$2:$A$1041,$A11,Data!$B$2:$B$1041,F$2)*IF($A11=Control!$B$2,1+Control!$B$3,1) -> 1892.64 | G11: =SUMIFS(Data!$C$2:$C$1041,Data!$A$2:$A$1041,$A11,Data!$B$2:$B$1041,G$2)*IF($A11=Control!$B$2,1+Control!$B$3,1) -> 1931 | H11: =SUMIFS(Data!$C$2:$C$1041,Data!$A$2:$A$1041,$A11,Data!$B$2:$B$1041,H$2)*IF($A11=Control!$B$2,1+Control!$B$3,1) -> 1927.94 | I11: =SUMIFS(Data!$C$2:$C$1041,Data!$A$2:$A$1041,$A11,Data!$B$2:$B$1041,I$2)*IF($A11=Control!$B$2,1+Control!$B$3,1) -> 1874.72 | ... BA11: =SUMIFS(Data!$C$2:$C$1041,Data!$A$2:$A$1041,$A11,Data!$B$2:$B$1041,BA$2)*IF($A11=Control!$B$2,1+Control!$B$3,1) -> 2169.76
A12: Banca Ligure | B12: =SUMIFS(Data!$C$2:$C$1041,Data!$A$2:$A$1041,$A12,Data!$B$2:$B$1041,B$2)*IF($A12=Control!$B$2,1+Control!$B$3,1) -> 1938.33 | C12: =SUMIFS(Data!$C$2:$C$1041,Data!$A$2:$A$1041,$A12,Data!$B$2:$B$1041,C$2)*IF($A12=Control!$B$2,1+Control!$B$3,1) -> 2020.11 | D12: =SUMIFS(Data!$C$2:$C$1041,Data!$A$2:$A$1041,$A12,Data!$B$2:$B$1041,D$2)*IF($A12=Control!$B$2,1+Control!$B$3,1) -> 2011.23 | E12: =SUMIFS(Data!$C$2:$C$1041,Data!$A$2:$A$1041,$A12,Data!$B$2:$B$1041,E$2)*IF($A12=Control!$B$2,1+Control!$B$3,1) -> 2038.06 | F12: =SUMIFS(Data!$C$2:$C$1041,Data!$A$2:$A$1041,$A12,Data!$B$2:$B$1041,F$2)*IF($A12=Control!$B$2,1+Control!$B$3,1) -> 1978.37 | G12: =SUMIFS(Data!$C$2:$C$1041,Data!$A$2:$A$1041,$A12,Data!$B$2:$B$1041,G$2)*IF($A12=Control!$B$2,1+Control!$B$3,1) -> 2061.71 | H12: =SUMIFS(Data!$C$2:$C$1041,Data!$A$2:$A$1041,$A12,Data!$B$2:$B$1041,H$2)*IF($A12=Control!$B$2,1+Control!$B$3,1) -> 2049.89 | I12: =SUMIFS(Data!$C$2:$C$1041,Data!$A$2:$A$1041,$A12,Data!$B$2:$B$1041,I$2)*IF($A12=Control!$B$2,1+Control!$B$3,1) -> 2045.1 | ... BA12: =SUMIFS(Data!$C$2:$C$1041,Data!$A$2:$A$1041,$A12,Data!$B$2:$B$1041,BA$2)*IF($A12=Control!$B$2,1+Control!$B$3,1) -> 2269.55
A13: Banca Veneta | B13: =SUMIFS(Data!$C$2:$C$1041,Data!$A$2:$A$1041,$A13,Data!$B$2:$B$1041,B$2)*IF($A13=Control!$B$2,1+Control!$B$3,1) -> 2114.16 | C13: =SUMIFS(Data!$C$2:$C$1041,Data!$A$2:$A$1041,$A13,Data!$B$2:$B$1041,C$2)*IF($A13=Control!$B$2,1+Control!$B$3,1) -> 2160.13 | D13: =SUMIFS(Data!$C$2:$C$1041,Data!$A$2:$A$1041,$A13,Data!$B$2:$B$1041,D$2)*IF($A13=Control!$B$2,1+Control!$B$3,1) -> 2148.36 | E13: =SUMIFS(Data!$C$2:$C$1041,Data!$A$2:$A$1041,$A13,Data!$B$2:$B$1041,E$2)*IF($A13=Control!$B$2,1+Control!$B$3,1) -> 2117.86 | F13: =SUMIFS(Data!$C$2:$C$1041,Data!$A$2:$A$1041,$A13,Data!$B$2:$B$1041,F$2)*IF($A13=Control!$B$2,1+Control!$B$3,1) -> 2099.55 | G13: =SUMIFS(Data!$C$2:$C$1041,Data!$A$2:$A$1041,$A13,Data!$B$2:$B$1041,G$2)*IF($A13=Control!$B$2,1+Control!$B$3,1) -> 2118.87 | H13: =SUMIFS(Data!$C$2:$C$1041,Data!$A$2:$A$1041,$A13,Data!$B$2:$B$1041,H$2)*IF($A13=Control!$B$2,1+Control!$B$3,1) -> 2115.91 | I13: =SUMIFS(Data!$C$2:$C$1041,Data!$A$2:$A$1041,$A13,Data!$B$2:$B$1041,I$2)*IF($A13=Control!$B$2,1+Control!$B$3,1) -> 2162.32 | ... BA13: =SUMIFS(Data!$C$2:$C$1041,Data!$A$2:$A$1041,$A13,Data!$B$2:$B$1041,BA$2)*IF($A13=Control!$B$2,1+Control!$B$3,1) -> 2431.59
A14: Banca Friulana | B14: =SUMIFS(Data!$C$2:$C$1041,Data!$A$2:$A$1041,$A14,Data!$B$2:$B$1041,B$2)*IF($A14=Control!$B$2,1+Control!$B$3,1) -> 2206.7 | C14: =SUMIFS(Data!$C$2:$C$1041,Data!$A$2:$A$1041,$A14,Data!$B$2:$B$1041,C$2)*IF($A14=Control!$B$2,1+Control!$B$3,1) -> 2205.64 | D14: =SUMIFS(Data!$C$2:$C$1041,Data!$A$2:$A$1041,$A14,Data!$B$2:$B$1041,D$2)*IF($A14=Control!$B$2,1+Control!$B$3,1) -> 2247.91 | E14: =SUMIFS(Data!$C$2:$C$1041,Data!$A$2:$A$1041,$A14,Data!$B$2:$B$1041,E$2)*IF($A14=Control!$B$2,1+Control!$B$3,1) -> 2262.02 | F14: =SUMIFS(Data!$C$2:$C$1041,Data!$A$2:$A$1041,$A14,Data!$B$2:$B$1041,F$2)*IF($A14=Control!$B$2,1+Control!$B$3,1) -> 2206.32 | G14: =SUMIFS(Data!$C$2:$C$1041,Data!$A$2:$A$1041,$A14,Data!$B$2:$B$1041,G$2)*IF($A14=Control!$B$2,1+Control!$B$3,1) -> 2305.53 | H14: =SUMIFS(Data!$C$2:$C$1041,Data!$A$2:$A$1041,$A14,Data!$B$2:$B$1041,H$2)*IF($A14=Control!$B$2,1+Control!$B$3,1) -> 2283.85 | I14: =SUMIFS(Data!$C$2:$C$1041,Data!$A$2:$A$1041,$A14,Data!$B$2:$B$1041,I$2)*IF($A14=Control!$B$2,1+Control!$B$3,1) -> 2277.19 | ... BA14: =SUMIFS(Data!$C$2:$C$1041,Data!$A$2:$A$1041,$A14,Data!$B$2:$B$1041,BA$2)*IF($A14=Control!$B$2,1+Control!$B$3,1) -> 2557.91
... A22: Banca Città | B22: =SUMIFS(Data!$C$2:$C$1041,Data!$A$2:$A$1041,$A22,Data!$B$2:$B$1041,B$2)*IF($A22=Control!$B$2,1+Control!$B$3,1) -> 3154.7 | C22: =SUMIFS(Data!$C$2:$C$1041,Data!$A$2:$A$1041,$A22,Data!$B$2:$B$1041,C$2)*IF($A22=Control!$B$2,1+Control!$B$3,1) -> 3219.94 | D22: =SUMIFS(Data!$C$2:$C$1041,Data!$A$2:$A$1041,$A22,Data!$B$2:$B$1041,D$2)*IF($A22=Control!$B$2,1+Control!$B$3,1) -> 3190.8 | E22: =SUMIFS(Data!$C$2:$C$1041,Data!$A$2:$A$1041,$A22,Data!$B$2:$B$1041,E$2)*IF($A22=Control!$B$2,1+Control!$B$3,1) -> 3182.53 | F22: =SUMIFS(Data!$C$2:$C$1041,Data!$A$2:$A$1041,$A22,Data!$B$2:$B$1041,F$2)*IF($A22=Control!$B$2,1+Control!$B$3,1) -> 3194.91 | G22: =SUMIFS(Data!$C$2:$C$1041,Data!$A$2:$A$1041,$A22,Data!$B$2:$B$1041,G$2)*IF($A22=Control!$B$2,1+Control!$B$3,1) -> 3263.1 | H22: =SUMIFS(Data!$C$2:$C$1041,Data!$A$2:$A$1041,$A22,Data!$B$2:$B$1041,H$2)*IF($A22=Control!$B$2,1+Control!$B$3,1) -> 3260.31 | I22: =SUMIFS(Data!$C$2:$C$1041,Data!$A$2:$A$1041,$A22,Data!$B$2:$B$1041,I$2)*IF($A22=Control!$B$2,1+Control!$B$3,1) -> 3217.51 | ... BA22: =SUMIFS(Data!$C$2:$C$1041,Data!$A$2:$A$1041,$A22,Data!$B$2:$B$1041,BA$2)*IF($A22=Control!$B$2,1+Control!$B$3,1) -> 3702.13

Sheet Step01
A1: Sheet 1
A3: Banca Alpi | B3: {=Base!B3*(1+Control!$B$3/12)+IF(MOD(ROW()+COLUMN(),7)=0,INDEX(Base!$B$3:$BA$22,MOD(ROW(),20)+1,MOD(COLUMN(),52)+1)*0.001,0)} -> 889.27765 | C3: {=Base!C3*(1+Control!$B$3/12)+IF(MOD(ROW()+COLUMN(),7)=0,INDEX(Base!$B$3:$BA$22,MOD(ROW(),20)+1,MOD(COLUMN(),52)+1)*0.001,0)} -> 870.68127 | D3: {=Base!D3*(1+Control!$B$3/12)+IF(MOD(ROW()+COLUMN(),7)=0,INDEX(Base!$B$3:$BA$22,MOD(ROW(),20)+1,MOD(COLUMN(),52)+1)*0.001,0)} -> 863.38134 | E3: {=Base!E3*(1+Control!$B$3/12)+IF(MOD(ROW()+COLUMN(),7)=0,INDEX(Base!$B$3:$BA$22,MOD(ROW(),20)+1,MOD(COLUMN(),52)+1)*0.001,0)} -> 875.20255 | F3: {=Base!F3*(1+Control!$B$3/12)+IF(MOD(ROW()+COLUMN(),7)=0,INDEX(Base!$B$3:$BA$22,MOD(ROW(),20)+1,MOD(COLUMN(),52)+1)*0.001,0)} -> 871.83415 | G3: {=Base!G3*(1+Control!$B$3/12)+IF(MOD(ROW()+COLUMN(),7)=0,INDEX(Base!$B$3:$BA$22,MOD(ROW(),20)+1,MOD(COLUMN(),52)+1)*0.001,0)} -> 959.25215 | H3: {=Base!H3*(1+Control!$B$3/12)+IF(MOD(ROW()+COLUMN(),7)=0,INDEX(Base!$B$3:$BA$22,MOD(ROW(),20)+1,MOD(COLUMN(),52)+1)*0.001,0)} -> 960.4752 | I3: {=Base!I3*(1+Control!$B$3/12)+IF(MOD(ROW()+COLUMN(),7)=0,INDEX(Base!$B$3:$BA$22,MOD(ROW(),20)+1,MOD(COLUMN(),52)+1)*0.001,0)} -> 898.05955 | ... AY3: {=Base!AY3*(1+Control!$B$3/12)+IF(MOD(ROW()+COLUMN(),7)=0,INDEX(Base!$B$3:$BA$22,MOD(ROW(),20)+1,MOD(COLUMN(),52)+1)*0.001,0)} -> 1039.9133
A4: Banca Adriatica | B4: {=Base!B4*(1+Control!$B$3/12)+IF(MOD(ROW()+COLUMN(),7)=0,INDEX(Base!$B$3:$BA$22,MOD(ROW(),20)+1,MOD(COLUMN(),52)+1)*0.001,0)} -> 1039.9534 | C4: {=Base!C4*(1+Control!$B$3/12)+IF(MOD(ROW()+COLUMN(),7)=0,INDEX(Base!$B$3:$BA$22,MOD(ROW(),20)+1,MOD(COLUMN(),52)+1)*0.001,0)} -> 1074.6811 | D4: {=Base!D4*(1+Control!$B$3/12)+IF(MOD(ROW()+COLUMN(),7)=0,INDEX(Base!$B$3:$BA$22,MOD(ROW(),20)+1,MOD(COLUMN(),52)+1)*0.001,0)} -> 1055.7428 | E4: {=Base!E4*(1+Control!$B$3/12)+IF(MOD(ROW()+COLUMN(),7)=0,INDEX(Base!$B$3:$BA$22,MOD(ROW(),20)+1,MOD(COLUMN(),52)+1)*0.001,0)} -> 1061.6074 | F4: {=Base!F4*(1+Control!$B$3/12)+IF(MOD(ROW()+COLUMN(),7)=0,INDEX(Base!$B$3:$BA$22,MOD(ROW(),20)+1,MOD(COLUMN(),52)+1)*0.001,0)} -> 1012.3044 | G4: {=Base!G4*(1+Control!$B$3/12)+IF(MOD(ROW()+COLUMN(),7)=0,INDEX(Base!$B$3:$BA$22,MOD(ROW(),20)+1,MOD(COLUMN(),52)+1)*0.001,0)} -> 1051.5323 | H4: {=Base!H4*(1+Control!$B$3/12)+IF(MOD(ROW()+COLUMN(),7)=0,INDEX(Base!$B$3:$BA$22,MOD(ROW(),20)+1,MOD(COLUMN(),52)+1)*0.001,0)} -> 1084.4544 | I4: {=Base!I4*(1+Control!$B$3/12)+IF(MOD(ROW()+COLUMN(),7)=0,INDEX(Base!$B$3:$BA$22,MOD(ROW(),20)+1,MOD(COLUMN(),52)+1)*0.001,0)} -> 1055.7628 | ... AY4: {=Base!AY4*(1+Control!$B$3/12)+IF(MOD(ROW()+COLUMN(),7)=0,INDEX(Base!$B$3:$BA$22,MOD(ROW(),20)+1,MOD(COLUMN(),52)+1)*0.001,0)} -> 1178.7495
A5: Banca Tirrena | B5: {=Base!B5*(1+Control!$B$3/12)+IF(MOD(ROW()+COLUMN(),7)=0,INDEX(Base!$B$3:$BA$22,MOD(ROW(),20)+1,MOD(COLUMN(),52)+1)*0.001,0)} -> 1162.2355 | C5: {=Base!C5*(1+Control!$B$3/12)+IF(MOD(ROW()+COLUMN(),7)=0,INDEX(Base!$B$3:$BA$22,MOD(ROW(),20)+1,MOD(COLUMN(),52)+1)*0.001,0)} -> 1196.5639 | D5: {=Base!D5*(1+Control!$B$3/12)+IF(MOD(ROW()+COLUMN(),7)=0,INDEX(Base!$B$3:$BA$22,MOD(ROW(),20)+1,MOD(COLUMN(),52)+1)*0.001,0)} -> 1142.058 | E5: {=Base!E5*(1+Control!$B$3/12)+IF(MOD(ROW()+COLUMN(),7)=0,INDEX(Base!$B$3:$BA$22,MOD(ROW(),20)+1,MOD(COLUMN(),52)+1)*0.001,0)} -> 1166.3787 | F5: {=Base!F5*(1+Control!$B$3/12)+IF(MOD(ROW()+COLUMN(),7)=0,INDEX(Base!$B$3:$BA$22,MOD(ROW(),20)+1,MOD(COLUMN(),52)+1)*0.001,0)} -> 1161.4464 | G5: {=Base!G5*(1+Control!$B$3/12)+IF(MOD(ROW()+COLUMN(),7)=0,INDEX(Base!$B$3:$BA$22,MOD(ROW(),20)+1,MOD(COLUMN(),52)+1)*0.001,0)} -> 1165.0052 | H5: {=Base!H5*(1+Control!$B$3/12)+IF(MOD(ROW()+COLUMN(),7)=0,INDEX(Base!$B$3:$BA$22,MOD(ROW(),20)+1,MOD(COLUMN(),52)+1)*0.001,0)} -> 1172.4137 | I5: {=Base!I5*(1+Control!$B$3/12)+IF(MOD(ROW()+COLUMN(),7)=0,INDEX(Base!$B$3:$BA$22,MOD(ROW(),20)+1,MOD(COLUMN(),52)+1)*0.001,0)} -> 1198.3545 | ... AY5: {=Base!AY5*(1+Control!$B$3/12)+IF(MOD(ROW()+COLUMN(),7)=0,INDEX(Base!$B$3:$BA$22,MOD(ROW(),20)+1,MOD(COLUMN(),52)+1)*0.001,0)} -> 1346.0831
A6: Banca Padana | B6: {=Base!B6*(1+Control!$B$3/12)+IF(MOD(ROW()+COLUMN(),7)=0,INDEX(Base!$B$3:$BA$22,MOD(ROW(),20)+1,MOD(COLUMN(),52)+1)*0.001,0)} -> 1236.5437 | C6: {=Base!C6*(1+Control!$B$3/12)+IF(MOD(ROW()+COLUMN(),7)=0,INDEX(Base!$B$3:$BA$22,MOD(ROW(),20)+1,MOD(COLUMN(),52)+1)*0.001,0)} -> 1282.9594 | D6: {=Base!D6*(1+Control!$B$3/12)+IF(MOD(ROW()+COLUMN(),7)=0,INDEX(Base!$B$3:$BA$22,MOD(ROW(),20)+1,MOD(COLUMN(),52)+1)*0.001,0)} -> 1251.8218 | E6: {=Base!E6*(1+Control!$B$3/12)+IF(MOD(ROW()+COLUMN(),7)=0,INDEX(Base!$B$3:$BA$22,MOD(ROW(),20)+1,MOD(COLUMN(),52)+1)*0.001,0)} -> 1305.9968 | F6: {=Base!F6*(1+Control!$B$3/12)+IF(MOD(ROW()+COLUMN(),7)=0,INDEX(Base!$B$3:$BA$22,MOD(ROW(),20)+1,MOD(COLUMN(),52)+1)*0.001,0)} -> 1324.8739 | G6: {=Base!G6*(1+Control!$B$3/12)+IF(MOD(ROW()+COLUMN(),7)=0,INDEX(Base!$B$3:$BA$22,MOD(ROW(),20)+1,MOD(COLUMN(),52)+1)*0.001,0)} -> 1272.8642 | H6: {=Base!H6*(1+Control!$B$3/12)+IF(MOD(ROW()+COLUMN(),7)=0,INDEX(Base!$B$3:$BA$22,MOD(ROW(),20)+1,MOD(COLUMN(),52)+1)*0.001,0)} -> 1321.4346 | I6: {=Base!I6*(1+Control!$B$3/12)+IF(MOD(ROW()+COLUMN(),7)=0,INDEX(Base!$B$3:$BA$22,MOD(ROW(),20)+1,MOD(COLUMN(),52)+1)*0.001,0)} -> 1275.6211 | ... AY6: {=Base!AY6*(1+Control!$B$3/12)+IF(MOD(ROW()+COLUMN(),7)=0,INDEX(Base!$B$3:$BA$22,MOD(ROW(),20)+1,MOD(COLUMN(),52)+1)*0.001,0)} -> 1406.9787
A7: Banca Etrusca | B7: {=Base!B7*(1+Control!$B$3/12)+IF(MOD(ROW()+COLUMN(),7)=0,INDEX(Base!$B$3:$BA$22,MOD(ROW(),20)+1,MOD(COLUMN(),52)+1)*0.001,0)} -> 1372.0817 | C7: {=Base!C7*(1+Control!$B$3/12)+IF(MOD(ROW()+COLUMN(),7)=0,INDEX(Base!$B$3:$BA$22,MOD(ROW(),20)+1,MOD(COLUMN(),52)+1)*0.001,0)} -> 1360.7333 | D7: {=Base!D7*(1+Control!$B$3/12)+IF(MOD(ROW()+COLUMN(),7)=0,INDEX(Base!$B$3:$BA$22,MOD(ROW(),20)+1,MOD(COLUMN(),52)+1)*0.001,0)} -> 1385.4249 | E7: {=Base!E7*(1+Control!$B$3/12)+IF(MOD(ROW()+COLUMN(),7)=0,INDEX(Base!$B$3:$BA$22,MOD(ROW(),20)+1,MOD(COLUMN(),52)+1)*0.001,0)} -> 1357.8562 | F7: {=Base!F7*(1+Control!$B$3/12)+IF(MOD(ROW()+COLUMN(),7)=0,INDEX(Base!$B$3:$BA$22,MOD(ROW(),20)+1,MOD(COLUMN(),52)+1)*0.001,0)} -> 1395.47 | G7: {=Base!G7*(1+Control!$B$3/12)+IF(MOD(ROW()+COLUMN(),7)=0,INDEX(Base!$B$3:$BA$22,MOD(ROW(),20)+1,MOD(COLUMN(),52)+1)*0.001,0)} -> 1407.8821 | H7: {=Base!H7*(1+Control!$B$3/12)+IF(MOD(ROW()+COLUMN(),7)=0,INDEX(Base!$B$3:$BA$22,MOD(ROW(),20)+1,MOD(COLUMN(),52)+1)*0.001,0)} -> 1460.2615 | I7: {=Base!I7*(1+Control!$B$3/12)+IF(MOD(ROW()+COLUMN(),7)=0,INDEX(Base!$B$3:$BA$22,MOD(ROW(),20)+1,MOD(COLUMN(),52)+1)*0.001,0)} -> 1439.8105 | ... AY7: {=Base!AY7*(1+Control!$B$3/12)+IF(MOD(ROW()+COLUMN(),7)=0,INDEX(Base!$B$3:$BA$22,MOD(ROW(),20)+1,MOD(COLUMN(),52)+1)*0.001,0)} -> 1554.2158
A8: Banca Lariana | B8: {=Base!B8*(1+Control!$B$3/12)+IF(MOD(ROW()+COLUMN(),7)=0,INDEX(Base!$B$3:$BA$22,MOD(ROW(),20)+1,MOD(COLUMN(),52)+1)*0.001,0)} -> 1500.0107 | C8: {=Base!C8*(1+Control!$B$3/12)+IF(MOD(ROW()+COLUMN(),7)=0,INDEX(Base!$B$3:$BA$22,MOD(ROW(),20)+1,MOD(COLUMN(),52)+1)*0.001,0)} -> 1469.4845 | D8: {=Base!D8*(1+Control!$B$3/12)+IF(MOD(ROW()+COLUMN(),7)=0,INDEX(Base!$B$3:$BA$22,MOD(ROW(),20)+1,MOD(COLUMN(),52)+1)*0.001,0)} -> 1554.8574 | E8: {=Base!E8*(1+Control!$B$3/12)+IF(MOD(ROW()+COLUMN(),7)=0,INDEX(Base!$B$3:$BA$22,MOD(ROW(),20)+1,MOD(COLUMN(),52)+1)*0.001,0)} -> 1541.7849 | F8: {=Base!F8*(1+Control!$B$3/12)+IF(MOD(ROW()+COLUMN(),7)=0,INDEX(Base!$B$3:$BA$22,MOD(ROW(),20)+1,MOD(COLUMN(),52)+1)*0.001,0)} -> 1487.8936 | G8: {=Base!G8*(1+Control!$B$3/12)+IF(MOD(ROW()+COLUMN(),7)=0,INDEX(Base!$B$3:$BA$22,MOD(ROW(),20)+1,MOD(COLUMN(),52)+1)*0.001,0)} -> 1545.474 | H8: {=Base!H8*(1+Control!$B$3/12)+IF(MOD(ROW()+COLUMN(),7)=0,INDEX(Base!$B$3:$BA$22,MOD(ROW(),20)+1,MOD(COLUMN(),52)+1)*0.001,0)} -> 1492.3115 | I8: {=Base!I8*(1+Control!$B$3/12)+IF(MOD(ROW()+COLUMN(),7)=0,INDEX(Base!$B$3:$BA$22,MOD(ROW(),20)+1,MOD(COLUMN(),52)+1)*0.001,0)} -> 1560.1206 | ... AY8: {=Base!AY8*(1+Control!$B$3/12)+IF(MOD(ROW()+COLUMN(),7)=0,INDEX(Base!$B$3:$BA$22,MOD(ROW(),20)+1,MOD(COLUMN(),52)+1)*0.001,0)} -> 1687.5283
A9: Banca Sabina | B9: {=Base!B9*(1+Control!$B$3/12)+IF(MOD(ROW()+COLUMN(),7)=0,INDEX(Base!$B$3:$BA$22,MOD(ROW(),20)+1,MOD(COLUMN(),52)+1)*0.001,0)} -> 1664.972 | C9: {=Base!C9*(1+Control!$B$3/12)+IF(MOD(ROW()+COLUMN(),7)=0,INDEX(Base!$B$3:$BA$22,MOD(ROW(),20)+1,MOD(COLUMN(),52)+1)*0.001,0)} -> 1659.3881 | D9: {=Base!D9*(1+Control!$B$3/12)+IF(MOD(ROW()+COLUMN(),7)=0,INDEX(Base!$B$3:$BA$22,MOD(ROW(),20)+1,MOD(COLUMN(),52)+1)*0.001,0)} -> 1608.2807 | E9: {=Base!E9*(1+Control!$B$3/12)+IF(MOD(ROW()+COLUMN(),7)=0,INDEX(Base!$B$3:$BA$22,MOD(ROW(),20)+1,MOD(COLUMN(),52)+1)*0.001,0)} -> 1682.9835 | F9: {=Base!F9*(1+Control!$B$3/12)+IF(MOD(ROW()+COLUMN(),7)=0,INDEX(Base!$B$3:$BA$22,MOD(ROW(),20)+1,MOD(COLUMN(),52)+1)*0.001,0)} -> 1628.8921 | G9: {=Base!G9*(1+Control!$B$3/12)+IF(MOD(ROW()+COLUMN(),7)=0,INDEX(Base!$B$3:$BA$22,MOD(ROW(),20)+1,MOD(COLUMN(),52)+1)*0.001,0)} -> 1686.5358 | H9: {=Base!H9*(1+Control!$B$3/12)+IF(MOD(ROW()+COLUMN(),7)=0,INDEX(Base!$B$3:$BA$22,MOD(ROW(),20)+1,MOD(COLUMN(),52)+1)*0.001,0)} -> 1643.2679 | I9: {=Base!I9*(1+Control!$B$3/12)+IF(MOD(ROW()+COLUMN(),7)=0,INDEX(Base!$B$3:$BA$22,MOD(ROW(),20)+1,MOD(COLUMN(),52)+1)*0.001,0)} -> 1710.6861 | ... AY9: {=Base!AY9*(1+Control!$B$3/12)+IF(MOD(ROW()+COLUMN(),7)=0,INDEX(Base!$B$3:$BA$22,MOD(ROW(),20)+1,MOD(COLUMN(),52)+1)*0.001,0)} -> 1864.8304
A10: Banca Irpina | B10: {=Base!B10*(1+Control!$B$3/12)+IF(MOD(ROW()+COLUMN(),7)=0,INDEX(Base!$B$3:$BA$22,MOD(ROW(),20)+1,MOD(COLUMN(),52)+1)*0.001,0)} -> 1701.7738 | C10: {=Base!C10*(1+Control!$B$3/12)+IF(MOD(ROW()+COLUMN(),7)=0,INDEX(Base!$B$3:$BA$22,MOD(ROW(),20)+1,MOD(COLUMN(),52)+1)*0.001,0)} -> 1790.5953 | D10: {=Base!D10*(1+Control!$B$3/12)+IF(MOD(ROW()+COLUMN(),7)=0,INDEX(Base!$B$3:$BA$22,MOD(ROW(),20)+1,MOD(COLUMN(),52)+1)*0.001,0)} -> 1808.8652 | E10: {=Base!E10*(1+Control!$B$3/12)+IF(MOD(ROW()+COLUMN(),7)=0,INDEX(Base!$B$3:$BA$22,MOD(ROW(),20)+1,MOD(COLUMN(),52)+1)*0.001,0)} -> 1755.568 | F10: {=Base!F10*(1+Control!$B$3/12)+IF(MOD(ROW()+COLUMN(),7)=0,INDEX(Base!$B$3:$BA$22,MOD(ROW(),20)+1,MOD(COLUMN(),52)+1)*0.001,0)} -> 1783.4074 | G10: {=Base!G10*(1+Control!$B$3/12)+IF(MOD(ROW()+COLUMN(),7)=0,INDEX(Base!$B$3:$BA$22,MOD(ROW(),20)+1,MOD(COLUMN(),52)+1)*0.001,0)} -> 1770.024 | H10: {=Base!H10*(1+Control!$B$3/12)+IF(MOD(ROW()+COLUMN(),7)=0,INDEX(Base!$B$3:$BA$22,MOD(ROW(),20)+1,MOD(COLUMN(),52)+1)*0.001,0)} -> 1763.8386 | I10: {=Base!I10*(1+Control!$B$3/12)+IF(MOD(ROW()+COLUMN(),7)=0,INDEX(Base!$B$3:$BA$22,MOD(ROW(),20)+1,MOD(COLUMN(),52)+1)*0.001,0)} -> 1770.014 | ... AY10: {=Base!AY10*(1+Control!$B$3/12)+IF(MOD(ROW()+COLUMN(),7)=0,INDEX(Base!$B$3:$BA$22,MOD(ROW(),20)+1,MOD(COLUMN(),52)+1)*0.001,0)} -> 2020.3783
A11: Banca Sannita | B11: {=Base!B11*(1+Control!$B$3/12)+IF(MOD(ROW()+COLUMN(),7)=0,INDEX(Base!$B$3:$BA$22,MOD(ROW(),20)+1,MOD(COLUMN(),52)+1)*0.001,0)} -> 1845.3619 | C11: {=Base!C11*(1+Control!$B$3/12)+IF(MOD(ROW()+COLUMN(),7)=0,INDEX(Base!$B$3:$BA$22,MOD(ROW(),20)+1,MOD(COLUMN(),52)+1)*0.001,0)} -> 1899.4532 | D11: {=Base!D11*(1+Control!$B$3/12)+IF(MOD(ROW()+COLUMN(),7)=0,INDEX(Base!$B$3:$BA$22,MOD(ROW(),20)+1,MOD(COLUMN(),52)+1)*0.001,0)} -> 1859.4671 | E11: {=Base!E11*(1+Control!$B$3/12)+IF(MOD(ROW()+COLUMN(),7)=0,INDEX(Base!$B$3:$BA$22,MOD(ROW(),20)+1,MOD(COLUMN(),52)+1)*0.001,0)} -> 1872.8805 | F11: {=Base!F11*(1+Control!$B$3/12)+IF(MOD(ROW()+COLUMN(),7)=0,INDEX(Base!$B$3:$BA$22,MOD(ROW(),20)+1,MOD(COLUMN(),52)+1)*0.001,0)} -> 1897.3716 | G11: {=Base!G11*(1+Control!$B$3/12)+IF(MOD(ROW()+COLUMN(),7)=0,INDEX(Base!$B$3:$BA$22,MOD(ROW(),20)+1,MOD(COLUMN(),52)+1)*0.001,0)} -> 1935.8275 | H11: {=Base!H11*(1+Control!$B$3/12)+IF(MOD(ROW()+COLUMN(),7)=0,INDEX(Base!$B$3:$BA$22,MOD(ROW(),20)+1,MOD(COLUMN(),52)+1)*0.001,0)} -> 1932.7598 | I11: {=Base!I11*(1+Control!$B$3/12)+IF(MOD(ROW()+COLUMN(),7)=0,INDEX(Base!$B$3:$BA$22,MOD(ROW(),20)+1,MOD(COLUMN(),52)+1)*0.001,0)} -> 1879.4068 | ... AY11: {=Base!AY11*(1+Control!$B$3/12)+IF(MOD(ROW()+COLUMN(),7)=0,INDEX(Base!$B$3:$BA$22,MOD(ROW(),20)+1,MOD(COLUMN(),52)+1)*0.001,0)} -> 2156.7685
A12: Banca Ligure | B12: {=Base!B12*(1+Control!$B$3/12)+IF(MOD(ROW()+COLUMN(),7)=0,INDEX(Base!$B$3:$BA$22,MOD(ROW(),20)+1,MOD(COLUMN(),52)+1)*0.001,0)} -> 1945.488 | C12: {=Base!C12*(1+Control!$B$3/12)+IF(MOD(ROW()+COLUMN(),7)=0,INDEX(Base!$B$3:$BA$22,MOD(ROW(),20)+1,MOD(COLUMN(),52)+1)*0.001,0)} -> 2025.1603 | D12: {=Base!D12*(1+Control!$B$3/12)+IF(MOD(ROW()+COLUMN(),7)=0,INDEX(Base!$B$3:$BA$22,MOD(ROW(),20)+1,MOD(COLUMN(),52)+1)*0.001,0)} -> 2016.2581 | E12: {=Base!E12*(1+Control!$B$3/12)+IF(MOD(ROW()+COLUMN(),7)=0,INDEX(Base!$B$3:$BA$22,MOD(ROW(),20)+1,MOD(COLUMN(),52)+1)*0.001,0)} -> 2043.1551 | F12: {=Base!F12*(1+Control!$B$3/12)+IF(MOD(ROW()+COLUMN(),7)=0,INDEX(Base!$B$3:$BA$22,MOD(ROW(),20)+1,MOD(COLUMN(),52)+1)*0.001,0)} -> 1983.3159 | G12: {=Base!G12*(1+Control!$B$3/12)+IF(MOD(ROW()+COLUMN(),7)=0,INDEX(Base!$B$3:$BA$22,MOD(ROW(),20)+1,MOD(COLUMN(),52)+1)*0.001,0)} -> 2066.8643 | H12: {=Base!H12*(1+Control!$B$3/12)+IF(MOD(ROW()+COLUMN(),7)=0,INDEX(Base!$B$3:$BA$22,MOD(ROW(),20)+1,MOD(COLUMN(),52)+1)*0.001,0)} -> 2055.0147 | I12: {=Base!I12*(1+Control!$B$3/12)+IF(MOD(ROW()+COLUMN(),7)=0,INDEX(Base!$B$3:$BA$22,MOD(ROW(),20)+1,MOD(COLUMN(),52)+1)*0.001,0)} -> 2052.6111 | ... AY12: {=Base!AY12*(1+Control!$B$3/12)+IF(MOD(ROW()+COLUMN(),7)=0,INDEX(Base!$B$3:$BA$22,MOD(ROW(),20)+1,MOD(COLUMN(),52)+1)*0.001,0)} -> 2241.0993
A13: Banca Veneta | B13: {=Base!B13*(1+Control!$B$3/12)+IF(MOD(ROW()+COLUMN(),7)=0,INDEX(Base!$B$3:$BA$22,MOD(ROW(),20)+1,MOD(COLUMN(),52)+1)*0.001,0)} -> 2119.4454 | C13: {=Base!C13*(1+Control!$B$3/12)+IF(MOD(ROW()+COLUMN(),7)=0,INDEX(Base!$B$3:$BA$22,MOD(ROW(),20)+1,MOD(COLUMN(),52)+1)*0.001,0)} -> 2165.5303 | D13: {=Base!D13*(1+Control!$B$3/12)+IF(MOD(ROW()+COLUMN(),7)=0,INDEX(Base!$B$3:$BA$22,MOD(ROW(),20)+1,MOD(COLUMN(),52)+1)*0.001,0)} -> 2153.7309 | E13: {=Base!E13*(1+Control!$B$3/12)+IF(MOD(ROW()+COLUMN(),7)=0,INDEX(Base!$B$3:$BA$22,MOD(ROW(),20)+1,MOD(COLUMN(),52)+1)*0.001,0)} -> 2123.1546 | F13: {=Base!F13*(1+Control!$B$3/12)+IF(MOD(ROW()+COLUMN(),7)=0,INDEX(Base!$B$3:$BA$22,MOD(ROW(),20)+1,MOD(COLUMN(),52)+1)*0.001,0)} -> 2104.7989 | G13: {=Base!G13*(1+Control!$B$3/12)+IF(MOD(ROW()+COLUMN(),7)=0,INDEX(Base!$B$3:$BA$22,MOD(ROW(),20)+1,MOD(COLUMN(),52)+1)*0.001,0)} -> 2124.1672 | H13: {=Base!H13*(1+Control!$B$3/12)+IF(MOD(ROW()+COLUMN(),7)=0,INDEX(Base!$B$3:$BA$22,MOD(ROW(),20)+1,MOD(COLUMN(),52)+1)*0.001,0)} -> 2123.7144 | I13: {=Base!I13*(1+Control!$B$3/12)+IF(MOD(ROW()+COLUMN(),7)=0,INDEX(Base!$B$3:$BA$22,MOD(ROW(),20)+1,MOD(COLUMN(),52)+1)*0.001,0)} -> 2167.7258 | ... AY13: {=Base!AY13*(1+Control!$B$3/12)+IF(MOD(ROW()+COLUMN(),7)=0,INDEX(Base!$B$3:$BA$22,MOD(ROW(),20)+1,MOD(COLUMN(),52)+1)*0.001,0)} -> 2401.4086
A14: Banca Friulana | B14: {=Base!B14*(1+Control!$B$3/12)+IF(MOD(ROW()+COLUMN(),7)=0,INDEX(Base!$B$3:$BA$22,MOD(ROW(),20)+1,MOD(COLUMN(),52)+1)*0.001,0)} -> 2212.2167 | C14: {=Base!C14*(1+Control!$B$3/12)+IF(MOD(ROW()+COLUMN(),7)=0,INDEX(Base!$B$3:$BA$22,MOD(ROW(),20)+1,MOD(COLUMN(),52)+1)*0.001,0)} -> 2211.1541 | D14: {=Base!D14*(1+Control!$B$3/12)+IF(MOD(ROW()+COLUMN(),7)=0,INDEX(Base!$B$3:$BA$22,MOD(ROW(),20)+1,MOD(COLUMN(),52)+1)*0.001,0)} -> 2253.5298 | E14: {=Base!E14*(1+Control!$B$3/12)+IF(MOD(ROW()+COLUMN(),7)=0,INDEX(Base!$B$3:$BA$22,MOD(ROW(),20)+1,MOD(COLUMN(),52)+1)*0.001,0)} -> 2267.675 | F14: {=Base!F14*(1+Control!$B$3/12)+IF(MOD(ROW()+COLUMN(),7)=0,INDEX(Base!$B$3:$BA$22,MOD(ROW(),20)+1,MOD(COLUMN(),52)+1)*0.001,0)} -> 2211.8358 | G14: {=Base!G14*(1+Control!$B$3/12)+IF(MOD(ROW()+COLUMN(),7)=0,INDEX(Base!$B$3:$BA$22,MOD(ROW(),20)+1,MOD(COLUMN(),52)+1)*0.001,0)} -> 2313.9268 | H14: {=Base!H14*(1+Control!$B$3/12)+IF(MOD(ROW()+COLUMN(),7)=0,INDEX(Base!$B$3:$BA$22,MOD(ROW(),20)+1,MOD(COLUMN(),52)+1)*0.001,0)} -> 2289.5596 | I14: {=Base!I14*(1+Control!$B$3/12)+IF(MOD(ROW()+COLUMN(),7)=0,INDEX(Base!$B$3:$BA$22,MOD(ROW(),20)+1,MOD(COLUMN(),52)+1)*0.001,0)} -> 2282.883 | ... AY14: {=Base!AY14*(1+Control!$B$3/12)+IF(MOD(ROW()+COLUMN(),7)=0,INDEX(Base!$B$3:$BA$22,MOD(ROW(),20)+1,MOD(COLUMN(),52)+1)*0.001,0)} -> 2530.9315
... A32: Extra 10 | B32: {=Base!B32*(1+Control!$B$3/12)+IF(MOD(ROW()+COLUMN(),7)=0,INDEX(Base!$B$3:$BA$22,MOD(ROW(),20)+1,MOD(COLUMN(),52)+1)*0.001,0)} -> 0 | C32: {=Base!C32*(1+Control!$B$3/12)+IF(MOD(ROW()+COLUMN(),7)=0,INDEX(Base!$B$3:$BA$22,MOD(ROW(),20)+1,MOD(COLUMN(),52)+1)*0.001,0)} -> 2.33998 | D32: {=Base!D32*(1+Control!$B$3/12)+IF(MOD(ROW()+COLUMN(),7)=0,INDEX(Base!$B$3:$BA$22,MOD(ROW(),20)+1,MOD(COLUMN(),52)+1)*0.001,0)} -> 0 | E32: {=Base!E32*(1+Control!$B$3/12)+IF(MOD(ROW()+COLUMN(),7)=0,INDEX(Base!$B$3:$BA$22,MOD(ROW(),20)+1,MOD(COLUMN(),52)+1)*0.001,0)} -> 0 | F32: {=Base!F32*(1+Control!$B$3/12)+IF(MOD(ROW()+COLUMN(),7)=0,INDEX(Base!$B$3:$BA$22,MOD(ROW(),20)+1,MOD(COLUMN(),52)+1)*0.001,0)} -> 0 | G32: {=Base!G32*(1+Control!$B$3/12)+IF(MOD(ROW()+COLUMN(),7)=0,INDEX(Base!$B$3:$BA$22,MOD(ROW(),20)+1,MOD(COLUMN(),52)+1)*0.001,0)} -> 0 | H32: {=Base!H32*(1+Control!$B$3/12)+IF(MOD(ROW()+COLUMN(),7)=0,INDEX(Base!$B$3:$BA$22,MOD(ROW(),20)+1,MOD(COLUMN(),52)+1)*0.001,0)} -> 0 | I32: {=Base!I32*(1+Control!$B$3/12)+IF(MOD(ROW()+COLUMN(),7)=0,INDEX(Base!$B$3:$BA$22,MOD(ROW(),20)+1,MOD(COLUMN(),52)+1)*0.001,0)} -> 0 | ... AY32: {=Base!AY32*(1+Control!$B$3/12)+IF(MOD(ROW()+COLUMN(),7)=0,INDEX(Base!$B$3:$BA$22,MOD(ROW(),20)+1,MOD(COLUMN(),52)+1)*0.001,0)} -> 0

Sheet Step02
A1: Sheet 2
A3: Banca Alpi | B3: =ROUND(Step01!B3+Step01!$B3*0.0005,6) -> 889.72229 | C3: =ROUND(Step01!C3+Step01!$B3*0.0005,6) -> 871.12591 | D3: =ROUND(Step01!D3+Step01!$B3*0.0005,6) -> 863.82598 | E3: =ROUND(Step01!E3+Step01!$B3*0.0005,6) -> 875.64719 | F3: =ROUND(Step01!F3+Step01!$B3*0.0005,6) -> 872.27879 | G3: =ROUND(Step01!G3+Step01!$B3*0.0005,6) -> 959.69679 | H3: =ROUND(Step01!H3+Step01!$B3*0.0005,6) -> 960.91984 | I3: =ROUND(Step01!I3+Step01!$B3*0.0005,6) -> 898.50419 | ... AY3: =ROUND(Step01!AY3+Step01!$B3*0.0005,6) -> 1040.3579
A4: Banca Adriatica | B4: =ROUND(Step01!B4+Step01!$B4*0.0005,6) -> 1040.4734 | C4: =ROUND(Step01!C4+Step01!$B4*0.0005,6) -> 1075.2011 | D4: =ROUND(Step01!D4+Step01!$B4*0.0005,6) -> 1056.2628 | E4: =ROUND(Step01!E4+Step01!$B4*0.0005,6) -> 1062.1274 | F4: =ROUND(Step01!F4+Step01!$B4*0.0005,6) -> 1012.8244 | G4: =ROUND(Step01!G4+Step01!$B4*0.0005,6) -> 1052.0523 | H4: =ROUND(Step01!H4+Step01!$B4*0.0005,6) -> 1084.9744 | I4: =ROUND(Step01!I4+Step01!$B4*0.0005,6) -> 1056.2828 | ... AY4: =ROUND(Step01!AY4+Step01!$B4*0.0005,6) -> 1179.2695
A5: Banca Tirrena | B5: =ROUND(Step01!B5+Step01!$B5*0.0005,6) -> 1162.8166 | C5: =ROUND(Step01!C5+Step01!$B5*0.0005,6) -> 1197.1451 | D5: =ROUND(Step01!D5+Step01!$B5*0.0005,6) -> 1142.6391 | E5: =ROUND(Step01!E5+Step01!$B5*0.0005,6) -> 1166.9598 | F5: =ROUND(Step01!F5+Step01!$B5*0.0005,6) -> 1162.0275 | G5: =ROUND(Step01!G5+Step01!$B5*0.0005,6) -> 1165.5864 | H5: =ROUND(Step01!H5+Step01!$B5*0.0005,6) -> 1172.9948 | I5: =ROUND(Step01!I5+Step01!$B5*0.0005,6) -> 1198.9356 | ... AY5: =ROUND(Step01!AY5+Step01!$B5*0.0005,6) -> 1346.6642
A6: Banca Padana | B6: =ROUND(Step01!B6+Step01!$B6*0.0005,6) -> 1237.1619 | C6: =ROUND(Step01!C6+Step01!$B6*0.0005,6) -> 1283.5777 | D6: =ROUND(Step01!D6+Step01!$B6*0.0005,6) -> 1252.44 | E6: =ROUND(Step01!E6+Step01!$B6*0.0005,6) -> 1306.6151 | F6: =ROUND(Step01!F6+Step01!$B6*0.0005,6) -> 1325.4922 | G6: =ROUND(Step01!G6+Step01!$B6*0.0005,6) -> 1273.4825 | H6: =ROUND(Step01!H6+Step01!$B6*0.0005,6) -> 1322.0529 | I6: =ROUND(Step01!I6+Step01!$B6*0.0005,6) -> 1276.2394 | ... AY6: =ROUND(Step01!AY6+Step01!$B6*0.0005,6) -> 1407.5969
A7: Banca Etrusca | B7: =ROUND(Step01!B7+Step01!$B7*0.0005,6) -> 1372.7677 | C7: =ROUND(Step01!C7+Step01!$B7*0.0005,6) -> 1361.4194 | D7: =ROUND(Step01!D7+Step01!$B7*0.0005,6) -> 1386.111 | E7: =ROUND(Step01!E7+Step01!$B7*0.0005,6) -> 1358.5422 | F7: =ROUND(Step01!F7+Step01!$B7*0.0005,6) -> 1396.156 | G7: =ROUND(Step01!G7+Step01!$B7*0.0005,6) -> 1408.5682 | H7: =ROUND(Step01!H7+Step01!$B7*0.0005,6) -> 1460.9476 | I7: =ROUND(Step01!I7+Step01!$B7*0.0005,6) -> 1440.4966 | ... AY7: =ROUND(Step01!AY7+Step01!$B7*0.0005,6) -> 1554.9019
A8: Banca Lariana | B8: =ROUND(Step01!B8+Step01!$B8*0.0005,6) -> 1500.7607 | C8: =ROUND(Step01!C8+Step01!$B8*0.0005,6) -> 1470.2346 | D8: =ROUND(Step01!D8+Step01!$B8*0.0005,6) -> 1555.6075 | E8: =ROUND(Step01!E8+Step01!$B8*0.0005,6) -> 1542.5349 | F8: =ROUND(Step01!F8+Step01!$B8*0.0005,6) -> 1488.6436 | G8: =ROUND(Step01!G8+Step01!$B8*0.0005,6) -> 1546.2241 | H8: =ROUND(Step01!H8+Step01!$B8*0.0005,6) -> 1493.0615 | I8: =ROUND(Step01!I8+Step01!$B8*0.0005,6) -> 1560.8706 | ... AY8: =ROUND(Step01!AY8+Step01!$B8*0.0005,6) -> 1688.2783
A9: Banca Sabina | B9: =ROUND(Step01!B9+Step01!$B9*0.0005,6) -> 1665.8045 | C9: =ROUND(Step01!C9+Step01!$B9*0.0005,6) -> 1660.2206 | D9: =ROUND(Step01!D9+Step01!$B9*0.0005,6) -> 1609.1132 | E9: =ROUND(Step01!E9+Step01!$B9*0.0005,6) -> 1683.816 | F9: =ROUND(Step01!F9+Step01!$B9*0.0005,6) -> 1629.7246 | G9: =ROUND(Step01!G9+Step01!$B9*0.0005,6) -> 1687.3683 | H9: =ROUND(Step01!H9+Step01!$B9*0.0005,6) -> 1644.1004 | I9: =ROUND(Step01!I9+Step01!$B9*0.0005,6) -> 1711.5185 | ... AY9: =ROUND(Step01!AY9+Step01!$B9*0.0005,6) -> 1865.6629
A10: Banca Irpina | B10: =ROUND(Step01!B10+Step01!$B10*0.0005,6) -> 1702.6247 | C10: =ROUND(Step01!C10+Step01!$B10*0.0005,6) -> 1791.4462 | D10: =ROUND(Step01!D10+Step01!$B10*0.0005,6) -> 1809.7161 | E10: =ROUND(Step01!E10+Step01!$B10*0.0005,6) -> 1756.4189 | F10: =ROUND(Step01!F10+Step01!$B10*0.0005,6) -> 1784.2583 | G10: =ROUND(Step01!G10+Step01!$B10*0.0005,6) -> 1770.8749 | H10: =ROUND(Step01!H10+Step01!$B10*0.0005,6) -> 1764.6895 | I10: =ROUND(Step01!I10+Step01!$B10*0.0005,6) -> 1770.8649 | ... AY10: =ROUND(Step01!AY10+Step01!$B10*0.0005,6) -> 2021.2292
A11: Banca Sannita | B11: =ROUND(Step01!B11+Step01!$B11*0.0005,6) -> 1846.2846 | C11: =ROUND(Step01!C11+Step01!$B11*0.0005,6) -> 1900.3759 | D11: =ROUND(Step01!D11+Step01!$B11*0.0005,6) -> 1860.3898 | E11: =ROUND(Step01!E11+Step01!$B11*0.0005,6) -> 1873.8032 | F11: =ROUND(Step01!F11+Step01!$B11*0.0005,6) -> 1898.2943 | G11: =ROUND(Step01!G11+Step01!$B11*0.0005,6) -> 1936.7502 | H11: =ROUND(Step01!H11+Step01!$B11*0.0005,6) -> 1933.6825 | I11: =ROUND(Step01!I11+Step01!$B11*0.0005,6) -> 1880.3295 | ... AY11: =ROUND(Step01!AY11+Step01!$B11*0.0005,6) -> 2157.6912
A12: Banca Ligure | B12: =ROUND(Step01!B12+Step01!$B12*0.0005,6) -> 1946.4608 | C12: =ROUND(Step01!C12+Step01!$B12*0.0005,6) -> 2026.133 | D12: =ROUND(Step01!D12+Step01!$B12*0.0005,6) -> 2017.2308 | E12: =ROUND(Step01!E12+Step01!$B12*0.0005,6) -> 2044.1279 | F12: =ROUND(Step01!F12+Step01!$B12*0.0005,6) -> 1984.2887 | G12: =ROUND(Step01!G12+Step01!$B12*0.0005,6) -> 2067.837 | H12: =ROUND(Step01!H12+Step01!$B12*0.0005,6) -> 2055.9875 | I12: =ROUND(Step01!I12+Step01!$B12*0.0005,6) -> 2053.5839 | ... AY12: =ROUND(Step01!AY12+Step01!$B12*0.0005,6) -> 2242.072
A13: Banca Veneta | B13: =ROUND(Step01!B13+Step01!$B13*0.0005,6) -> 2120.5051 | C13: =ROUND(Step01!C13+Step01!$B13*0.0005,6) -> 2166.59 | D13: =ROUND(Step01!D13+Step01!$B13*0.0005,6) -> 2154.7906 | E13: =ROUND(Step01!E13+Step01!$B13*0.0005,6) -> 2124.2144 | F13: =ROUND(Step01!F13+Step01!$B13*0.0005,6) -> 2105.8586 | G13: =ROUND(Step01!G13+Step01!$B13*0.0005,6) -> 2125.2269 | H13: =ROUND(Step01!H13+Step01!$B13*0.0005,6) -> 2124.7741 | I13: =ROUND(Step01!I13+Step01!$B13*0.0005,6) -> 2168.7855 | ... AY13: =ROUND(Step01!AY13+Step01!$B13*0.0005,6) -> 2402.4683
A14: Banca Friulana | B14: =ROUND(Step01!B14+Step01!$B14*0.0005,6) -> 2213.3229 | C14: =ROUND(Step01!C14+Step01!$B14*0.0005,6) -> 2212.2602 | D14: =ROUND(Step01!D14+Step01!$B14*0.0005,6) -> 2254.6359 | E14: =ROUND(Step01!E14+Step01!$B14*0.0005,6) -> 2268.7812 | F14: =ROUND(Step01!F14+Step01!$B14*0.0005,6) -> 2212.9419 | G14: =ROUND(Step01!G14+Step01!$B14*0.0005,6) -> 2315.033 | H14: =ROUND(Step01!H14+Step01!$B14*0.0005,6) -> 2290.6657 | I14: =ROUND(Step01!I14+Step01!$B14*0.0005,6) -> 2283.9891 | ... AY14: =ROUND(Step01!AY14+Step01!$B14*0.0005,6) -> 2532.0377
... A32: Extra 10 | B32: =ROUND(Step01!B32+Step01!$B32*0.0005,6) -> 0 | C32: =ROUND(Step01!C32+Step01!$B32*0.0005,6) -> 2.33998 | D32: =ROUND(Step01!D32+Step01!$B32*0.0005,6) -> 0 | E32: =ROUND(Step01!E32+Step01!$B32*0.0005,6) -> 0 | F32: =ROUND(Step01!F32+Step01!$B32*0.0005,6) -> 0 | G32: =ROUND(Step01!G32+Step01!$B32*0.0005,6) -> 0 | H32: =ROUND(Step01!H32+Step01!$B32*0.0005,6) -> 0 | I32: =ROUND(Step01!I32+Step01!$B32*0.0005,6) -> 0 | ... AY32: =ROUND(Step01!AY32+Step01!$B32*0.0005,6) -> 0

Sheet Step03
A1: Sheet 3
A3: Banca Alpi | B3: =IF(Step02!B3>Step02!$B$3,Step02!B3-0.5,Step02!B3+0.5) -> 890.22229 | C3: =IF(Step02!C3>Step02!$B$3,Step02!C3-0.5,Step02!C3+0.5) -> 871.62591 | D3: =IF(Step02!D3>Step02!$B$3,Step02!D3-0.5,Step02!D3+0.5) -> 864.32598 | E3: =IF(Step02!E3>Step02!$B$3,Step02!E3-0.5,Step02!E3+0.5) -> 876.14719 | F3: =IF(Step02!F3>Step02!$B$3,Step02!F3-0.5,Step02!F3+0.5) -> 872.77879 | G3: =IF(Step02!G3>Step02!$B$3,Step02!G3-0.5,Step02!G3+0.5) -> 959.19679 | H3: =IF(Step02!H3>Step02!$B$3,Step02!H3-0.5,Step02!H3+0.5) -> 960.41984 | I3: =IF(Step02!I3>Step02!$B$3,Step02!I3-0.5,Step02!I3+0.5) -> 898.00419 | ... AY3: =IF(Step02!AY3>Step02!$B$3,Step02!AY3-0.5,Step02!AY3+0.5) -> 1039.8579
A4: Banca Adriatica | B4: =IF(Step02!B4>Step02!$B$3,Step02!B4-0.5,Step02!B4+0.5) -> 1039.9734 | C4: =IF(Step02!C4>Step02!$B$3,Step02!C4-0.5,Step02!C4+0.5) -> 1074.7011 | D4: =IF(Step02!D4>Step02!$B$3,Step02!D4-0.5,Step02!D4+0.5) -> 1055.7628 | E4: =IF(Step02!E4>Step02!$B$3,Step02!E4-0.5,Step02!E4+0.5) -> 1061.6274 | F4: =IF(Step02!F4>Step02!$B$3,Step02!F4-0.5,Step02!F4+0.5) -> 1012.3244 | G4: =IF(Step02!G4>Step02!$B$3,Step02!G4-0.5,Step02!G4+0.5) -> 1051.5523 | H4: =IF(Step02!H4>Step02!$B$3,Step02!H4-0.5,Step02!H4+0.5) -> 1084.4744 | I4: =IF(Step02!I4>Step02!$B$3,Step02!I4-0.5,Step02!I4+0.5) -> 1055.7828 | ... AY4: =IF(Step02!AY4>Step02!$B$3,Step02!AY4-0.5,Step02!AY4+0.5) -> 1178.7695
A5: Banca Tirrena | B5: =IF(Step02!B5>Step02!$B$3,Step02!B5-0.5,Step02!B5+0.5) -> 1162.3166 | C5: =IF(Step02!C5>Step02!$B$3,Step02!C5-0.5,Step02!C5+0.5) -> 1196.6451 | D5: =IF(Step02!D5>Step02!$B$3,Step02!D5-0.5,Step02!D5+0.5) -> 1142.1391 | E5: =IF(Step02!E5>Step02!$B$3,Step02!E5-0.5,Step02!E5+0.5) -> 1166.4598 | F5: =IF(Step02!F5>Step02!$B$3,Step02!F5-0.5,Step02!F5+0.5) -> 1161.5275 | G5: =IF(Step02!G5>Step02!$B$3,Step02!G5-0.5,Step02!G5+0.5) -> 1165.0864 | H5: =IF(Step02!H5>Step02!$B$3,Step02!H5-0.5,Step02!H5+0.5) -> 1172.4948 | I5: =IF(Step02!I5>Step02!$B$3,Step02!I5-0.5,Step02!I5+0.5) -> 1198.4356 | ... AY5: =IF(Step02!AY5>Step02!$B$3,Step02!AY5-0.5,Step02!AY5+0.5) -> 1346.1642
A6: Banca Padana | B6: =IF(Step02!B6>Step02!$B$3,Step02!B6-0.5,Step02!B6+0.5) -> 1236.6619 | C6: =IF(Step02!C6>Step02!$B$3,Step02!C6-0.5,Step02!C6+0.5) -> 1283.0777 | D6: =IF(Step02!D6>Step02!$B$3,Step02!D6-0.5,Step02!D6+0.5) -> 1251.94 | E6: =IF(Step02!E6>Step02!$B$3,Step02!E6-0.5,Step02!E6+0.5) -> 1306.1151 | F6: =IF(Step02!F6>Step02!$B$3,Step02!F6-0.5,Step02!F6+0.5) -> 1324.9922 | G6: =IF(Step02!G6>Step02!$B$3,Step02!G6-0.5,Step02!G6+0.5) -> 1272.9825 | H6: =IF(Step02!H6>Step02!$B$3,Step02!H6-0.5,Step02!H6+0.5) -> 1321.5529 | I6: =IF(Step02!I6>Step02!$B$3,Step02!I6-0.5,Step02!I6+0.5) -> 1275.7394 | ... AY6: =IF(Step02!AY6>Step02!$B$3,Step02!AY6-0.5,Step02!AY6+0.5) -> 1407.0969
A7: Banca Etrusca | B7: =IF(Step02!B7>Step02!$B$3,Step02!B7-0.5,Step02!B7+0.5) -> 1372.2677 | C7: =IF(Step02!C7>Step02!$B$3,Step02!C7-0.5,Step02!C7+0.5) -> 1360.9194 | D7: =IF(Step02!D7>Step02!$B$3,Step02!D7-0.5,Step02!D7+0.5) -> 1385.611 | E7: =IF(Step02!E7>Step02!$B$3,Step02!E7-0.5,Step02!E7+0.5) -> 1358.0422 | F7: =IF(Step02!F7>Step02!$B$3,Step02!F7-0.5,Step02!F7+0.5) -> 1395.656 | G7: =IF(Step02!G7>Step02!$B$3,Step02!G7-0.5,Step02!G7+0.5) -> 1408.0682 | H7: =IF(Step02!H7>Step02!$B$3,Step02!H7-0.5,Step02!H7+0.5) -> 1460.4476 | I7: =IF(Step02!I7>Step02!$B$3,Step02!I7-0.5,Step02!I7+0.5) -> 1439.9966 | ... AY7: =IF(Step02!AY7>Step02!$B$3,Step02!AY7-0.5,Step02!AY7+0.5) -> 1554.4019
A8: Banca Lariana | B8: =IF(Step02!B8>Step02!$B$3,Step02!B8-0.5,Step02!B8+0.5) -> 1500.2607 | C8: =IF(Step02!C8>Step02!$B$3,Step02!C8-0.5,Step02!C8+0.5) -> 1469.7346 | D8: =IF(Step02!D8>Step02!$B$3,Step02!D8-0.5,Step02!D8+0.5) -> 1555.1075 | E8: =IF(Step02!E8>Step02!$B$3,Step02!E8-0.5,Step02!E8+0.5) -> 1542.0349 | F8: =IF(Step02!F8>Step02!$B$3,Step02!F8-0.5,Step02!F8+0.5) -> 1488.1436 | G8: =IF(Step02!G8>Step02!$B$3,Step02!G8-0.5,Step02!G8+0.5) -> 1545.7241 | H8: =IF(Step02!H8>Step02!$B$3,Step02!H8-0.5,Step02!H8+0.5) -> 1492.5615 | I8: =IF(Step02!I8>Step02!$B$3,Step02!I8-0.5,Step02!I8+0.5) -> 1560.3706 | ... AY8: =IF(Step02!AY8>Step02!$B$3,Step02!AY8-0.5,Step02!AY8+0.5) -> 1687.7783
A9: Banca Sabina | B9: =IF(Step02!B9>Step02!$B$3,Step02!B9-0.5,Step02!B9+0.5) -> 1665.3045 | C9: =IF(Step02!C9>Step02!$B$3,Step02!C9-0.5,Step02!C9+0.5) -> 1659.7206 | D9: =IF(Step02!D9>Step02!$B$3,Step02!D9-0.5,Step02!D9+0.5) -> 1608.6132 | E9: =IF(Step02!E9>Step02!$B$3,Step02!E9-0.5,Step02!E9+0.5) -> 1683.316 | F9: =IF(Step02!F9>Step02!$B$3,Step02!F9-0.5,Step02!F9+0.5) -> 1629.2246 | G9: =IF(Step02!G9>Step02!$B$3,Step02!G9-0.5,Step02!G9+0.5) -> 1686.8683 | H9: =IF(Step02!H9>Step02!$B$3,Step02!H9-0.5,Step02!H9+0.5) -> 1643.6004 | I9: =IF(Step02!I9>Step02!$B$3,Step02!I9-0.5,Step02!I9+0.5) -> 1711.0185 | ... AY9: =IF(Step02!AY9>Step02!$B$3,Step02!AY9-0.5,Step02!AY9+0.5) -> 1865.1629
A10: Banca Irpina | B10: =IF(Step02!B10>Step02!$B$3,Step02!B10-0.5,Step02!B10+0.5) -> 1702.1247 | C10: =IF(Step02!C10>Step02!$B$3,Step02!C10-0.5,Step02!C10+0.5) -> 1790.9462 | D10: =IF(Step02!D10>Step02!$B$3,Step02!D10-0.5,Step02!D10+0.5) -> 1809.2161 | E10: =IF(Step02!E10>Step02!$B$3,Step02!E10-0.5,Step02!E10+0.5) -> 1755.9189 | F10: =IF(Step02!F10>Step02!$B$3,Step02!F10-0.5,Step02!F10+0.5) -> 1783.7583 | G10: =IF(Step02!G10>Step02!$B$3,Step02!G10-0.5,Step02!G10+0.5) -> 1770.3749 | H10: =IF(Step02!H10>Step02!$B$3,Step02!H10-0.5,Step02!H10+0.5) -> 1764.1895 | I10: =IF(Step02!I10>Step02!$B$3,Step02!I10-0.5,Step02!I10+0.5) -> 1770.3649 | ... AY10: =IF(Step02!AY10>Step02!$B$3,Step02!AY10-0.5,Step02!AY10+0.5) -> 2020.7292
A11: Banca Sannita | B11: =IF(Step02!B11>Step02!$B$3,Step02!B11-0.5,Step02!B11+0.5) -> 1845.7846 | C11: =IF(Step02!C11>Step02!$B$3,Step02!C11-0.5,Step02!C11+0.5) -> 1899.8759 | D11: =IF(Step02!D11>Step02!$B$3,Step02!D11-0.5,Step02!D11+0.5) -> 1859.8898 | E11: =IF(Step02!E11>Step02!$B$3,Step02!E11-0.5,Step02!E11+0.5) -> 1873.3032 | F11: =IF(Step02!F11>Step02!$B$3,Step02!F11-0.5,Step02!F11+0.5) -> 1897.7943 | G11: =IF(Step02!G11>Step02!$B$3,Step02!G11-0.5,Step02!G11+0.5) -> 1936.2502 | H11: =IF(Step02!H11>Step02!$B$3,Step02!H11-0.5,Step02!H11+0.5) -> 1933.1825 | I11: =IF(Step02!I11>Step02!$B$3,Step02!I11-0.5,Step02!I11+0.5) -> 1879.8295 | ... AY11: =IF(Step02!AY11>Step02!$B$3,Step02!AY11-0.5,Step02!AY11+0.5) -> 2157.1912
A12: Banca Ligure | B12: =IF(Step02!B12>Step02!$B$3,Step02!B12-0.5,Step02!B12+0.5) -> 1945.9608 | C12: =IF(Step02!C12>Step02!$B$3,Step02!C12-0.5,Step02!C12+0.5) -> 2025.633 | D12: =IF(Step02!D12>Step02!$B$3,Step02!D12-0.5,Step02!D12+0.5) -> 2016.7308 | E12: =IF(Step02!E12>Step02!$B$3,Step02!E12-0.5,Step02!E12+0.5) -> 2043.6279 | F12: =IF(Step02!F12>Step02!$B$3,Step02!F12-0.5,Step02!F12+0.5) -> 1983.7887 | G12: =IF(Step02!G12>Step02!$B$3,Step02!G12-0.5,Step02!G12+0.5) -> 2067.337 | H12: =IF(Step02!H12>Step02!$B$3,Step02!H12-0.5,Step02!H12+0.5) -> 2055.4875 | I12: =IF(Step02!I12>Step02!$B$3,Step02!I12-0.5,Step02!I12+0.5) -> 2053.0839 | ... AY12: =IF(Step02!AY12>Step02!$B$3,Step02!AY12-0.5,Step02!AY12+0.5) -> 2241.572
A13: Banca Veneta | B13: =IF(Step02!B13>Step02!$B$3,Step02!B13-0.5,Step02!B13+0.5) -> 2120.0051 | C13: =IF(Step02!C13>Step02!$B$3,Step02!C13-0.5,Step02!C13+0.5) -> 2166.09 | D13: =IF(Step02!D13>Step02!$B$3,Step02!D13-0.5,Step02!D13+0.5) -> 2154.2906 | E13: =IF(Step02!E13>Step02!$B$3,Step02!E13-0.5,Step02!E13+0.5) -> 2123.7144 | F13: =IF(Step02!F13>Step02!$B$3,Step02!F13-0.5,Step02!F13+0.5) -> 2105.3586 | G13: =IF(Step02!G13>Step02!$B$3,Step02!G13-0.5,Step02!G13+0.5) -> 2124.7269 | H13: =IF(Step02!H13>Step02!$B$3,Step02!H13-0.5,Step02!H13+0.5) -> 2124.2741 | I13: =IF(Step02!I13>Step02!$B$3,Step02!I13-0.5,Step02!I13+0.5) -> 2168.2855 | ... AY13: =IF(Step02!AY13>Step02!$B$3,Step02!AY13-0.5,Step02!AY13+0.5) -> 2401.9683
A14: Banca Friulana | B14: =IF(Step02!B14>Step02!$B$3,Step02!B14-0.5,Step02!B14+0.5) -> 2212.8229 | C14: =IF(Step02!C14>Step02!$B$3,Step02!C14-0.5,Step02!C14+0.5) -> 2211.7602 | D14: =IF(Step02!D14>Step02!$B$3,Step02!D14-0.5,Step02!D14+0.5) -> 2254.1359 | E14: =IF(Step02!E14>Step02!$B$3,Step02!E14-0.5,Step02!E14+0.5) -> 2268.2812 | F14: =IF(Step02!F14>Step02!$B$3,Step02!F14-0.5,Step02!F14+0.5) -> 2212.4419 | G14: =IF(Step02!G14>Step02!$B$3,Step02!G14-0.5,Step02!G14+0.5) -> 2314.533 | H14: =IF(Step02!H14>Step02!$B$3,Step02!H14-0.5,Step02!H14+0.5) -> 2290.1657 | I14: =IF(Step02!I14>Step02!$B$3,Step02!I14-0.5,Step02!I14+0.5) -> 2283.4891 | ... AY14: =IF(Step02!AY14>Step02!$B$3,Step02!AY14-0.5,Step02!AY14+0.5) -> 2531.5377
... A32: Extra 10 | B32: =IF(Step02!B32>Step02!$B$3,Step02!B32-0.5,Step02!B32+0.5) -> 0.5 | C32: =IF(Step02!C32>Step02!$B$3,Step02!C32-0.5,Step02!C32+0.5) -> 2.83998 | D32: =IF(Step02!D32>Step02!$B$3,Step02!D32-0.5,Step02!D32+0.5) -> 0.5 | E32: =IF(Step02!E32>Step02!$B$3,Step02!E32-0.5,Step02!E32+0.5) -> 0.5 | F32: =IF(Step02!F32>Step02!$B$3,Step02!F32-0.5,Step02!F32+0.5) -> 0.5 | G32: =IF(Step02!G32>Step02!$B$3,Step02!G32-0.5,Step02!G32+0.5) -> 0.5 | H32: =IF(Step02!H32>Step02!$B$3,Step02!H32-0.5,Step02!H32+0.5) -> 0.5 | I32: =IF(Step02!I32>Step02!$B$3,Step02!I32-0.5,Step02!I32+0.5) -> 0.5 | ... AY32: =IF(Step02!AY32>Step02!$B$3,Step02!AY32-0.5,Step02!AY32+0.5) -> 0.5

Sheet Step04
A1: Sheet 4
A3: Banca Alpi | B3: =Step03!B3+SUM(Step03!$B3:$F3)/1000-AVERAGE(Step03!B$3:B$7)/1000 -> 893.4571 | C3: =Step03!C3+SUM(Step03!$B3:$F3)/1000-AVERAGE(Step03!C$3:C$7)/1000 -> 874.84362 | D3: =Step03!D3+SUM(Step03!$B3:$F3)/1000-AVERAGE(Step03!D$3:D$7)/1000 -> 867.56113 | E3: =Step03!E3+SUM(Step03!$B3:$F3)/1000-AVERAGE(Step03!E$3:E$7)/1000 -> 879.36861 | F3: =Step03!F3+SUM(Step03!$B3:$F3)/1000-AVERAGE(Step03!F$3:F$7)/1000 -> 876.00043 | G3: =Step03!G3+SUM(Step03!$B3:$F3)/1000-AVERAGE(Step03!G$3:G$7)/1000 -> 962.40051 | H3: =Step03!H3+SUM(Step03!$B3:$F3)/1000-AVERAGE(Step03!H$3:H$7)/1000 -> 963.59506 | I3: =Step03!I3+SUM(Step03!$B3:$F3)/1000-AVERAGE(Step03!I$3:I$7)/1000 -> 901.2057 | ... AY3: =Step03!AY3+SUM(Step03!$B3:$F3)/1000-AVERAGE(Step03!AY$3:AY$7)/1000 -> 1042.9278
A4: Banca Adriatica | B4: =Step03!B4+SUM(Step03!$B4:$F4)/1000-AVERAGE(Step03!B$3:B$7)/1000 -> 1044.0775 | C4: =Step03!C4+SUM(Step03!$B4:$F4)/1000-AVERAGE(Step03!C$3:C$7)/1000 -> 1078.7881 | D4: =Step03!D4+SUM(Step03!$B4:$F4)/1000-AVERAGE(Step03!D$3:D$7)/1000 -> 1059.8672 | E4: =Step03!E4+SUM(Step03!$B4:$F4)/1000-AVERAGE(Step03!E$3:E$7)/1000 -> 1065.7181 | F4: =Step03!F4+SUM(Step03!$B4:$F4)/1000-AVERAGE(Step03!F$3:F$7)/1000 -> 1016.4154 | G4: =Step03!G4+SUM(Step03!$B4:$F4)/1000-AVERAGE(Step03!G$3:G$7)/1000 -> 1055.6253 | H4: =Step03!H4+SUM(Step03!$B4:$F4)/1000-AVERAGE(Step03!H$3:H$7)/1000 -> 1088.5189 | I4: =Step03!I4+SUM(Step03!$B4:$F4)/1000-AVERAGE(Step03!I$3:I$7)/1000 -> 1059.8536 | ... AY4: =Step03!AY4+SUM(Step03!$B4:$F4)/1000-AVERAGE(Step03!AY$3:AY$7)/1000 -> 1182.7086
A5: Banca Tirrena | B5: =Step03!B5+SUM(Step03!$B5:$F5)/1000-AVERAGE(Step03!B$3:B$7)/1000 -> 1167.0054 | C5: =Step03!C5+SUM(Step03!$B5:$F5)/1000-AVERAGE(Step03!C$3:C$7)/1000 -> 1201.3168 | D5: =Step03!D5+SUM(Step03!$B5:$F5)/1000-AVERAGE(Step03!D$3:D$7)/1000 -> 1146.8283 | E5: =Step03!E5+SUM(Step03!$B5:$F5)/1000-AVERAGE(Step03!E$3:E$7)/1000 -> 1171.1352 | F5: =Step03!F5+SUM(Step03!$B5:$F5)/1000-AVERAGE(Step03!F$3:F$7)/1000 -> 1166.2031 | G5: =Step03!G5+SUM(Step03!$B5:$F5)/1000-AVERAGE(Step03!G$3:G$7)/1000 -> 1169.7441 | H5: =Step03!H5+SUM(Step03!$B5:$F5)/1000-AVERAGE(Step03!H$3:H$7)/1000 -> 1177.1241 | I5: =Step03!I5+SUM(Step03!$B5:$F5)/1000-AVERAGE(Step03!I$3:I$7)/1000 -> 1203.0911 | ... AY5: =Step03!AY5+SUM(Step03!$B5:$F5)/1000-AVERAGE(Step03!AY$3:AY$7)/1000 -> 1350.688
A6: Banca Padana | B6: =Step03!B6+SUM(Step03!$B6:$F6)/1000-AVERAGE(Step03!B$3:B$7)/1000 -> 1241.9244 | C6: =Step03!C6+SUM(Step03!$B6:$F6)/1000-AVERAGE(Step03!C$3:C$7)/1000 -> 1288.3231 | D6: =Step03!D6+SUM(Step03!$B6:$F6)/1000-AVERAGE(Step03!D$3:D$7)/1000 -> 1257.2029 | E6: =Step03!E6+SUM(Step03!$B6:$F6)/1000-AVERAGE(Step03!E$3:E$7)/1000 -> 1311.3642 | F6: =Step03!F6+SUM(Step03!$B6:$F6)/1000-AVERAGE(Step03!F$3:F$7)/1000 -> 1330.2415 | G6: =Step03!G6+SUM(Step03!$B6:$F6)/1000-AVERAGE(Step03!G$3:G$7)/1000 -> 1278.2139 | H6: =Step03!H6+SUM(Step03!$B6:$F6)/1000-AVERAGE(Step03!H$3:H$7)/1000 -> 1326.7558 | I6: =Step03!I6+SUM(Step03!$B6:$F6)/1000-AVERAGE(Step03!I$3:I$7)/1000 -> 1280.9686 | ... AY6: =Step03!AY6+SUM(Step03!$B6:$F6)/1000-AVERAGE(Step03!AY$3:AY$7)/1000 -> 1412.1945
A7: Banca Etrusca | B7: =Step03!B7+SUM(Step03!$B7:$F7)/1000-AVERAGE(Step03!B$3:B$7)/1000 -> 1377.9999 | C7: =Step03!C7+SUM(Step03!$B7:$F7)/1000-AVERAGE(Step03!C$3:C$7)/1000 -> 1366.6345 | D7: =Step03!D7+SUM(Step03!$B7:$F7)/1000-AVERAGE(Step03!D$3:D$7)/1000 -> 1391.3435 | E7: =Step03!E7+SUM(Step03!$B7:$F7)/1000-AVERAGE(Step03!E$3:E$7)/1000 -> 1363.761 | F7: =Step03!F7+SUM(Step03!$B7:$F7)/1000-AVERAGE(Step03!F$3:F$7)/1000 -> 1401.3751 | G7: =Step03!G7+SUM(Step03!$B7:$F7)/1000-AVERAGE(Step03!G$3:G$7)/1000 -> 1413.7693 | H7: =Step03!H7+SUM(Step03!$B7:$F7)/1000-AVERAGE(Step03!H$3:H$7)/1000 -> 1466.1202 | I7: =Step03!I7+SUM(Step03!$B7:$F7)/1000-AVERAGE(Step03!I$3:I$7)/1000 -> 1445.6955 | ... AY7: =Step03!AY7+SUM(Step03!$B7:$F7)/1000-AVERAGE(Step03!AY$3:AY$7)/1000 -> 1559.9691
A8: Banca Lariana | B8: =Step03!B8+SUM(Step03!$B8:$F8)/1000-AVERAGE(Step03!B$3:B$7)/1000 -> 1506.6757 | C8: =Step03!C8+SUM(Step03!$B8:$F8)/1000-AVERAGE(Step03!C$3:C$7)/1000 -> 1476.1324 | D8: =Step03!D8+SUM(Step03!$B8:$F8)/1000-AVERAGE(Step03!D$3:D$7)/1000 -> 1561.5228 | E8: =Step03!E8+SUM(Step03!$B8:$F8)/1000-AVERAGE(Step03!E$3:E$7)/1000 -> 1548.4365 | F8: =Step03!F8+SUM(Step03!$B8:$F8)/1000-AVERAGE(Step03!F$3:F$7)/1000 -> 1494.5454 | G8: =Step03!G8+SUM(Step03!$B8:$F8)/1000-AVERAGE(Step03!G$3:G$7)/1000 -> 1552.108 | H8: =Step03!H8+SUM(Step03!$B8:$F8)/1000-AVERAGE(Step03!H$3:H$7)/1000 -> 1498.9169 | I8: =Step03!I8+SUM(Step03!$B8:$F8)/1000-AVERAGE(Step03!I$3:I$7)/1000 -> 1566.7523 | ... AY8: =Step03!AY8+SUM(Step03!$B8:$F8)/1000-AVERAGE(Step03!AY$3:AY$7)/1000 -> 1694.0283
A9: Banca Sabina | B9: =Step03!B9+SUM(Step03!$B9:$F9)/1000-AVERAGE(Step03!B$3:B$7)/1000 -> 1672.4104 | C9: =Step03!C9+SUM(Step03!$B9:$F9)/1000-AVERAGE(Step03!C$3:C$7)/1000 -> 1666.8094 | D9: =Step03!D9+SUM(Step03!$B9:$F9)/1000-AVERAGE(Step03!D$3:D$7)/1000 -> 1615.7194 | E9: =Step03!E9+SUM(Step03!$B9:$F9)/1000-AVERAGE(Step03!E$3:E$7)/1000 -> 1690.4085 | F9: =Step03!F9+SUM(Step03!$B9:$F9)/1000-AVERAGE(Step03!F$3:F$7)/1000 -> 1636.3173 | G9: =Step03!G9+SUM(Step03!$B9:$F9)/1000-AVERAGE(Step03!G$3:G$7)/1000 -> 1693.9431 | H9: =Step03!H9+SUM(Step03!$B9:$F9)/1000-AVERAGE(Step03!H$3:H$7)/1000 -> 1650.6467 | I9: =Step03!I9+SUM(Step03!$B9:$F9)/1000-AVERAGE(Step03!I$3:I$7)/1000 -> 1718.0911 | ... AY9: =Step03!AY9+SUM(Step03!$B9:$F9)/1000-AVERAGE(Step03!AY$3:AY$7)/1000 -> 1872.1039
A10: Banca Irpina | B10: =Step03!B10+SUM(Step03!$B10:$F10)/1000-AVERAGE(Step03!B$3:B$7)/1000 -> 1709.8264 | C10: =Step03!C10+SUM(Step03!$B10:$F10)/1000-AVERAGE(Step03!C$3:C$7)/1000 -> 1798.6308 | D10: =Step03!D10+SUM(Step03!$B10:$F10)/1000-AVERAGE(Step03!D$3:D$7)/1000 -> 1816.9181 | E10: =Step03!E10+SUM(Step03!$B10:$F10)/1000-AVERAGE(Step03!E$3:E$7)/1000 -> 1763.6071 | F10: =Step03!F10+SUM(Step03!$B10:$F10)/1000-AVERAGE(Step03!F$3:F$7)/1000 -> 1791.4468 | G10: =Step03!G10+SUM(Step03!$B10:$F10)/1000-AVERAGE(Step03!G$3:G$7)/1000 -> 1778.0455 | H10: =Step03!H10+SUM(Step03!$B10:$F10)/1000-AVERAGE(Step03!H$3:H$7)/1000 -> 1771.8316 | I10: =Step03!I10+SUM(Step03!$B10:$F10)/1000-AVERAGE(Step03!I$3:I$7)/1000 -> 1778.0333 | ... AY10: =Step03!AY10+SUM(Step03!$B10:$F10)/1000-AVERAGE(Step03!AY$3:AY$7)/1000 -> 2028.2659
A11: Banca Sannita | B11: =Step03!B11+SUM(Step03!$B11:$F11)/1000-AVERAGE(Step03!B$3:B$7)/1000 -> 1854.0209 | C11: =Step03!C11+SUM(Step03!$B11:$F11)/1000-AVERAGE(Step03!C$3:C$7)/1000 -> 1908.0951 | D11: =Step03!D11+SUM(Step03!$B11:$F11)/1000-AVERAGE(Step03!D$3:D$7)/1000 -> 1868.1264 | E11: =Step03!E11+SUM(Step03!$B11:$F11)/1000-AVERAGE(Step03!E$3:E$7)/1000 -> 1881.5262 | F11: =Step03!F11+SUM(Step03!$B11:$F11)/1000-AVERAGE(Step03!F$3:F$7)/1000 -> 1906.0175 | G11: =Step03!G11+SUM(Step03!$B11:$F11)/1000-AVERAGE(Step03!G$3:G$7)/1000 -> 1944.4555 | H11: =Step03!H11+SUM(Step03!$B11:$F11)/1000-AVERAGE(Step03!H$3:H$7)/1000 -> 1941.3593 | I11: =Step03!I11+SUM(Step03!$B11:$F11)/1000-AVERAGE(Step03!I$3:I$7)/1000 -> 1888.0325 | ... AY11: =Step03!AY11+SUM(Step03!$B11:$F11)/1000-AVERAGE(Step03!AY$3:AY$7)/1000 -> 2165.2625
A12: Banca Ligure | B12: =Step03!B12+SUM(Step03!$B12:$F12)/1000-AVERAGE(Step03!B$3:B$7)/1000 -> 1954.8362 | C12: =Step03!C12+SUM(Step03!$B12:$F12)/1000-AVERAGE(Step03!C$3:C$7)/1000 -> 2034.4914 | D12: =Step03!D12+SUM(Step03!$B12:$F12)/1000-AVERAGE(Step03!D$3:D$7)/1000 -> 2025.6066 | E12: =Step03!E12+SUM(Step03!$B12:$F12)/1000-AVERAGE(Step03!E$3:E$7)/1000 -> 2052.49 | F12: =Step03!F12+SUM(Step03!$B12:$F12)/1000-AVERAGE(Step03!F$3:F$7)/1000 -> 1992.651 | G12: =Step03!G12+SUM(Step03!$B12:$F12)/1000-AVERAGE(Step03!G$3:G$7)/1000 -> 2076.1814 | H12: =Step03!H12+SUM(Step03!$B12:$F12)/1000-AVERAGE(Step03!H$3:H$7)/1000 -> 2064.3033 | I12: =Step03!I12+SUM(Step03!$B12:$F12)/1000-AVERAGE(Step03!I$3:I$7)/1000 -> 2061.926 | ... AY12: =Step03!AY12+SUM(Step03!$B12:$F12)/1000-AVERAGE(Step03!AY$3:AY$7)/1000 -> 2250.2825
A13: Banca Veneta | B13: =Step03!B13+SUM(Step03!$B13:$F13)/1000-AVERAGE(Step03!B$3:B$7)/1000 -> 2129.5343 | C13: =Step03!C13+SUM(Step03!$B13:$F13)/1000-AVERAGE(Step03!C$3:C$7)/1000 -> 2175.6021 | D13: =Step03!D13+SUM(Step03!$B13:$F13)/1000-AVERAGE(Step03!D$3:D$7)/1000 -> 2163.8201 | E13: =Step03!E13+SUM(Step03!$B13:$F13)/1000-AVERAGE(Step03!E$3:E$7)/1000 -> 2133.2302 | F13: =Step03!F13+SUM(Step03!$B13:$F13)/1000-AVERAGE(Step03!F$3:F$7)/1000 -> 2114.8746 | G13: =Step03!G13+SUM(Step03!$B13:$F13)/1000-AVERAGE(Step03!G$3:G$7)/1000 -> 2134.225 | H13: =Step03!H13+SUM(Step03!$B13:$F13)/1000-AVERAGE(Step03!H$3:H$7)/1000 -> 2133.7437 | I13: =Step03!I13+SUM(Step03!$B13:$F13)/1000-AVERAGE(Step03!I$3:I$7)/1000 -> 2177.7814 | ... AY13: =Step03!AY13+SUM(Step03!$B13:$F13)/1000-AVERAGE(Step03!AY$3:AY$7)/1000 -> 2411.3325
A14: Banca Friulana | B14: =Step03!B14+SUM(Step03!$B14:$F14)/1000-AVERAGE(Step03!B$3:B$7)/1000 -> 2222.842 | C14: =Step03!C14+SUM(Step03!$B14:$F14)/1000-AVERAGE(Step03!C$3:C$7)/1000 -> 2221.7623 | D14: =Step03!D14+SUM(Step03!$B14:$F14)/1000-AVERAGE(Step03!D$3:D$7)/1000 -> 2264.1554 | E14: =Step03!E14+SUM(Step03!$B14:$F14)/1000-AVERAGE(Step03!E$3:E$7)/1000 -> 2278.2869 | F14: =Step03!F14+SUM(Step03!$B14:$F14)/1000-AVERAGE(Step03!F$3:F$7)/1000 -> 2222.4479 | G14: =Step03!G14+SUM(Step03!$B14:$F14)/1000-AVERAGE(Step03!G$3:G$7)/1000 -> 2324.521 | H14: =Step03!H14+SUM(Step03!$B14:$F14)/1000-AVERAGE(Step03!H$3:H$7)/1000 -> 2300.1253 | I14: =Step03!I14+SUM(Step03!$B14:$F14)/1000-AVERAGE(Step03!I$3:I$7)/1000 -> 2293.4749 | ... AY14: =Step03!AY14+SUM(Step03!$B14:$F14)/1000-AVERAGE(Step03!AY$3:AY$7)/1000 -> 2541.3918
