Workbook

Sheet Control
A2: Bank | B2: Bank A
A3: Bank index | B3: =MATCH(B2,Data!H2:H11,0) -> 1
A4: Week | B4: 40
A5: FX | B5: 1.0847
A6: Unit | B6: mln
A7: Title | B7: =B2&" - week "&TEXT(B4,"00")&" ("&B6&" EUR)" -> Bank A - week 40 (mln EUR)
A8: Week date | B8: =INDEX(Data!G:G,MATCH(1,INDEX((Data!A:A=B2)*(Data!B:B=B4),0),0)) -> 46300.422
A9: Month end | B9: =EOMONTH(B8,0) -> 46326

Sheet Data
A1: Bank | B1: Week | C1: Loans | D1: Deposits | E1: Budget loans | F1: Budget deposits | G1: Date | H1: Banks
A2: Bank A | B2: 1 | C2: 1456.318 | D2: 1808.4 | E2: 1507 | F2: 1806 | G2: 46027.422 | H2: Bank A
A3: Bank A | B3: 2 | C3: 1541.67 | D3: 1794.8 | E3: 1513 | F3: 1813 | G3: 46034.422 | H3: Bank B
A4: Bank A | B4: 3 | C4: 1501.305 | D4: 1880.2 | E4: 1520 | F4: 1819 | G4: 46041.422 | H4: Bank C
A5: Bank A | B5: 4 | C5: 1479.122 | D5: 1803.6 | E5: 1527 | F5: 1825 | G5: 46048.422 | H5: Bank D
A6: Bank A | B6: 5 | C6: 1492.561 | D6: 1849 | E6: 1534 | F6: 1832 | G6: 46055.422 | H6: Bank E
A7: Bank A | B7: 6 | C7: 1573.565 | D7: 1875.4 | E7: 1540 | F7: 1838 | G7: 46062.422 | H7: Bank F
A8: Bank A | B8: 7 | C8: 1507.268 | D8: 1759.8 | E8: 1547 | F8: 1844 | G8: 46069.422 | H8: Bank G
A9: Bank A | B9: 8 | C9: 1587.048 | D9: 1889.2 | E9: 1554 | F9: 1850 | G9: 46076.422 | H9: Bank H
A10: Bank A | B10: 9 | C10: 1496.472 | D10: 1860.6 | E10: 1561 | F10: 1857 | G10: 46083.422 | H10: Bank I
A11: Bank A | B11: 10 | C11: 1539.649 | D11: 1877 | E11: 1568 | F11: 1863 | G11: 46090.422 | H11: Bank J
A12: Bank A | B12: 11 | C12: 1608.317 | D12: 1881.4 | E12: 1574 | F12: 1869 | G12: 46097.422
A13: Bank A | B13: 12 | C13: 1614.565 | D13: 1942.8 | E13: 1581 | F13: 1876 | G13: 46104.422
A14: Bank A | B14: 13 | C14: 1556.955 | D14: 1867.2 | E14: 1588 | F14: 1882 | G14: 46111.422
A15: Bank A | B15: 14 | C15: 1559.597 | D15: 1796.6 | E15: 1594 | F15: 1888 | G15: 46118.422
A16: Bank A | B16: 15 | C16: 1555.786 | D16: 1864 | E16: 1601 | F16: 1894 | G16: 46125.422
A17: Bank A | B17: 16 | C17: 1589.971 | D17: 1906.4 | E17: 1608 | F17: 1901 | G17: 46132.422
A18: Bank A | B18: 17 | C18: 1606.153 | D18: 1871.8 | E18: 1615 | F18: 1907 | G18: 46139.422
A19: Bank A | B19: 18 | C19: 1617.947 | D19: 1856.2 | E19: 1622 | F19: 1913 | G19: 46146.422
A20: Bank A | B20: 19 | C20: 1588.254 | D20: 1865.6 | E20: 1628 | F20: 1920 | G20: 46153.422
A21: Bank A | B21: 20 | C21: 1647.724 | D21: 1859 | E21: 1635 | F21: 1926 | G21: 46160.422
A22: Bank A | B22: 21 | C22: 1665.035 | D22: 1937.4 | E22: 1642 | F22: 1932 | G22: 46167.422
A23: Bank A | B23: 22 | C23: 1603.268 | D23: 1966.8 | E23: 1648 | F23: 1939 | G23: 46174.422
... A521: Bank J | B521: 52 | C521: 9407.757 | D521: 10788.2 | E521: 9625 | F521: 11064 | G521: 46384.422

Sheet SLIDE_1
B2: x
C3: ="Loans & deposits - "&Control!$B$2 -> Loans & deposits - Bank A
C4: Item | D4: ="Week "&TEXT(Control!$B$4-3,"00") -> Week 37 | E4: ="Week "&TEXT(Control!$B$4-2,"00") -> Week 38 | F4: ="Week "&TEXT(Control!$B$4-1,"00") -> Week 39 | G4: ="Week "&TEXT(Control!$B$4-0,"00") -> Week 40 | H4: Delta w/w | I4: Delta % | J4: Budget | K4: vs Budget
C5: Loans | D5: =ROUND(SUMIFS(Data!$C:$C,Data!$A:$A,Control!$B$2,Data!$B:$B,Control!$B$4-3)*Control!$B$5,1) -> 1877.9 | E5: =ROUND(SUMIFS(Data!$C:$C,Data!$A:$A,Control!$B$2,Data!$B:$B,Control!$B$4-2)*Control!$B$5,1) -> 1809.6 | F5: =ROUND(SUMIFS(Data!$C:$C,Data!$A:$A,Control!$B$2,Data!$B:$B,Control!$B$4-1)*Control!$B$5,1) -> 1906.8 | G5: =ROUND(SUMIFS(Data!$C:$C,Data!$A:$A,Control!$B$2,Data!$B:$B,Control!$B$4-0)*Control!$B$5,1) -> 1844 | H5: =G5-F5 -> -62.8 | I5: =IFERROR(H5/F5,0) -> -0.03293476 | J5: =ROUND(SUMIFS(Data!$E:$E,Data!$A:$A,Control!$B$2,Data!$B:$B,Control!$B$4-0)*Control!$B$5,1) -> 1919.9 | K5: =IF(ABS(G5-J5)<0.05,0,G5-J5) -> -75.9
C6: Deposits | D6: =ROUND(SUMIFS(Data!$D:$D,Data!$A:$A,Control!$B$2,Data!$B:$B,Control!$B$4-3)*Control!$B$5,1) -> 2190.9 | E6: =ROUND(SUMIFS(Data!$D:$D,Data!$A:$A,Control!$B$2,Data!$B:$B,Control!$B$4-2)*Control!$B$5,1) -> 2113.2 | F6: =ROUND(SUMIFS(Data!$D:$D,Data!$A:$A,Control!$B$2,Data!$B:$B,Control!$B$4-1)*Control!$B$5,1) -> 2135.3 | G6: =ROUND(SUMIFS(Data!$D:$D,Data!$A:$A,Control!$B$2,Data!$B:$B,Control!$B$4-0)*Control!$B$5,1) -> 2271.4 | H6: =G6-F6 -> 136.1 | I6: =IFERROR(H6/F6,0) -> 0.063738116 | J6: =ROUND(SUMIFS(Data!$F:$F,Data!$A:$A,Control!$B$2,Data!$B:$B,Control!$B$4-0)*Control!$B$5,1) -> 2225.8 | K6: =IF(ABS(G6-J6)<0.05,0,G6-J6) -> 45.6
C7: Total | D7: =SUM(D5:D6) -> 4068.8 | E7: =SUM(E5:E6) -> 3922.8 | F7: =SUM(F5:F6) -> 4042.1 | G7: =SUM(G5:G6) -> 4115.4 | H7: =SUM(H5:H6) -> 73.3 | I7: =IFERROR(H7/F7,0) -> 0.018134138 | J7: =SUM(J5:J6) -> 4145.7 | K7: =SUM(K5:K6) -> -30.3
C8: L/D ratio | D8: =IF(D6=0,"n/a",D5/D6) -> 0.85713634 | E8: =IF(E6=0,"n/a",E5/E6) -> 0.85633163 | F8: =IF(F6=0,"n/a",F5/F6) -> 0.89298928 | G8: =IF(G6=0,"n/a",G5/G6) -> 0.81183411
C9: Average 4w | D9: =AVERAGE(D7:G7) -> 4037.275 | E9: =MAX(D7:G7) -> 4115.4 | F9: =MIN(D7:G7) -> 3922.8 | G9: =COUNTIF(H5:H6,">0") -> 1
C11: Rank | D11: =RANK(G5,Data!$C$2:$C$521) -> #N/A | E11: =SUMPRODUCT((Data!$B$2:$B$521=Control!$B$4)*(Data!$C$2:$C$521>G5))+1 -> 10 | F11: =VLOOKUP(Control!$B$2,Data!$H$2:$H$11,1,FALSE) -> Bank A | G11: =LEFT(Control!$B$2,4)&MID(Control!$B$2,6,1)&LEN(Control!$B$2) -> BankA6
C12: Misc | D12: =CHOOSE(MOD(Control!$B$3,3)+1,"one","two","three") -> two | E12: =TEXT(Control!$B$8,"mmm yy") -> ott yy | F12: =OFFSET(D5,1,2) -> 2135.3 | G12: =INDIRECT("D7") -> 4068.8 | H12: =AVERAGEIF(Data!$A$2:$A$521,Control!$B$2,Data!$C$2:$C$521) -> 1655.3948 | I12: =DATE(2026,1,5)+7*(Control!$B$4-1) -> 46300 | J12: =CONCATENATE(Control!$B$6," EUR") -> mln EUR | K12: =ROUNDUP(G7/1000,0)*1000 -> 5000
C13: Today | D13: =TODAY() -> 46311 | E13: =IF(ISNUMBER(G5),"ok","missing") -> ok | F13: =LARGE(Data!$C$2:$C$521,3) -> 9376.065 | G13: =SMALL(D5:G6,2) -> 1844 | H13: =_xlfn.XLOOKUP(Control!$B$2,Data!$H$2:$H$11,Data!$H$2:$H$11,"none") -> Bank A | I13: {=_xlfn.IFS(G5>F5,"up",G5<F5,"down",TRUE,"flat")} -> down | J13: {=_xlfn.SWITCH(Control!$B$6,"mln",1000000,"k",1000,1)} -> 1000000 | K13: =_xlfn.LET(_xlpm.x,G7,_xlpm.y,J7,IF(_xlpm.y=0,0,_xlpm.x/_xlpm.y-1)) -> -0.0073087778 | L13: =SUM(_xlfn._xlws.FILTER(Data!$C$2:$C$521,Data!$A$2:$A$521=Control!$B$2)) -> 86080.528

Sheet SLIDE_2
B2: x
C3: ="Loans & deposits - "&Control!$B$2 -> Loans & deposits - Bank A
C4: Item | D4: ="Week "&TEXT(Control!$B$4-4,"00") -> Week 36 | E4: ="Week "&TEXT(Control!$B$4-3,"00") -> Week 37 | F4: ="Week "&TEXT(Control!$B$4-2,"00") -> Week 38 | G4: ="Week "&TEXT(Control!$B$4-1,"00") -> Week 39 | H4: Delta w/w | I4: Delta % | J4: Budget | K4: vs Budget
C5: Loans | D5: =ROUND(SUMIFS(Data!$C:$C,Data!$A:$A,Control!$B$2,Data!$B:$B,Control!$B$4-4)*Control!$B$5,1) -> 1896.4 | E5: =ROUND(SUMIFS(Data!$C:$C,Data!$A:$A,Control!$B$2,Data!$B:$B,Control!$B$4-3)*Control!$B$5,1) -> 1877.9 | F5: =ROUND(SUMIFS(Data!$C:$C,Data!$A:$A,Control!$B$2,Data!$B:$B,Control!$B$4-2)*Control!$B$5,1) -> 1809.6 | G5: =ROUND(SUMIFS(Data!$C:$C,Data!$A:$A,Control!$B$2,Data!$B:$B,Control!$B$4-1)*Control!$B$5,1) -> 1906.8 | H5: =G5-F5 -> 97.2 | I5: =IFERROR(H5/F5,0) -> 0.053713528 | J5: =ROUND(SUMIFS(Data!$E:$E,Data!$A:$A,Control!$B$2,Data!$B:$B,Control!$B$4-1)*Control!$B$5,1) -> 1912.3 | K5: =IF(ABS(G5-J5)<0.05,0,G5-J5) -> -5.5
C6: Deposits | D6: =ROUND(SUMIFS(Data!$D:$D,Data!$A:$A,Control!$B$2,Data!$B:$B,Control!$B$4-4)*Control!$B$5,1) -> 2083.1 | E6: =ROUND(SUMIFS(Data!$D:$D,Data!$A:$A,Control!$B$2,Data!$B:$B,Control!$B$4-3)*Control!$B$5,1) -> 2190.9 | F6: =ROUND(SUMIFS(Data!$D:$D,Data!$A:$A,Control!$B$2,Data!$B:$B,Control!$B$4-2)*Control!$B$5,1) -> 2113.2 | G6: =ROUND(SUMIFS(Data!$D:$D,Data!$A:$A,Control!$B$2,Data!$B:$B,Control!$B$4-1)*Control!$B$5,1) -> 2135.3 | H6: =G6-F6 -> 22.1 | I6: =IFERROR(H6/F6,0) -> 0.010458073 | J6: =ROUND(SUMIFS(Data!$F:$F,Data!$A:$A,Control!$B$2,Data!$B:$B,Control!$B$4-1)*Control!$B$5,1) -> 2219.3 | K6: =IF(ABS(G6-J6)<0.05,0,G6-J6) -> -84
C7: Total | D7: =SUM(D5:D6) -> 3979.5 | E7: =SUM(E5:E6) -> 4068.8 | F7: =SUM(F5:F6) -> 3922.8 | G7: =SUM(G5:G6) -> 4042.1 | H7: =SUM(H5:H6) -> 119.3 | I7: =IFERROR(H7/F7,0) -> 0.030411951 | J7: =SUM(J5:J6) -> 4131.6 | K7: =SUM(K5:K6) -> -89.5
C8: L/D ratio | D8: =IF(D6=0,"n/a",D5/D6) -> 0.91037396 | E8: =IF(E6=0,"n/a",E5/E6) -> 0.85713634 | F8: =IF(F6=0,"n/a",F5/F6) -> 0.85633163 | G8: =IF(G6=0,"n/a",G5/G6) -> 0.89298928
C9: Average 4w | D9: =AVERAGE(D7:G7) -> 4003.3 | E9: =MAX(D7:G7) -> 4068.8 | F9: =MIN(D7:G7) -> 3922.8 | G9: =COUNTIF(H5:H6,">0") -> 2
C10: ="vs SLIDE_1" -> vs SLIDE_1 | D10: =G7-SLIDE_1!G7 -> -73.3 | E10: =IFERROR(D10/SLIDE_1!G7,0) -> -0.017811148 | F10: =IF(AND(D10>0,SLIDE_1!H7>0),"up",IF(OR(D10<0,SLIDE_1!H7<0),"down","flat")) -> down | G10: =INDEX(SLIDE_1!D5:G6,2,MATCH(MAX(SLIDE_1!D6:G6),SLIDE_1!D6:G6,0)) -> 2271.4
C11: Rank | D11: =RANK(G5,Data!$C$2:$C$521) -> #N/A | E11: =SUMPRODUCT((Data!$B$2:$B$521=Control!$B$4)*(Data!$C$2:$C$521>G5))+1 -> 10 | F11: =VLOOKUP(Control!$B$2,Data!$H$2:$H$11,1,FALSE) -> Bank A | G11: =LEFT(Control!$B$2,4)&MID(Control!$B$2,6,1)&LEN(Control!$B$2) -> BankA6
C12: Misc | D12: =CHOOSE(MOD(Control!$B$3,3)+1,"one","two","three") -> two | E12: =TEXT(Control!$B$8,"mmm yy") -> ott yy | F12: =OFFSET(D5,1,2) -> 2113.2 | G12: =INDIRECT("D7") -> 3979.5 | H12: =AVERAGEIF(Data!$A$2:$A$521,Control!$B$2,Data!$C$2:$C$521) -> 1655.3948 | I12: =DATE(2026,1,5)+7*(Control!$B$4-1) -> 46300 | J12: =CONCATENATE(Control!$B$6," EUR") -> mln EUR | K12: =ROUNDUP(G7/1000,0)*1000 -> 5000
C13: Today | D13: =TODAY() -> 46311 | E13: =IF(ISNUMBER(G5),"ok","missing") -> ok | F13: =LARGE(Data!$C$2:$C$521,3) -> 9376.065 | G13: =SMALL(D5:G6,2) -> 1877.9 | H13: =_xlfn.XLOOKUP(Control!$B$2,Data!$H$2:$H$11,Data!$H$2:$H$11,"none") -> Bank A | I13: {=_xlfn.IFS(G5>F5,"up",G5<F5,"down",TRUE,"flat")} -> up | J13: {=_xlfn.SWITCH(Control!$B$6,"mln",1000000,"k",1000,1)} -> 1000000 | K13: =_xlfn.LET(_xlpm.x,G7,_xlpm.y,J7,IF(_xlpm.y=0,0,_xlpm.x/_xlpm.y-1)) -> -0.02166231 | L13: =SUM(_xlfn._xlws.FILTER(Data!$C$2:$C$521,Data!$A$2:$A$521=Control!$B$2)) -> 86080.528

Sheet SLIDE_3
B2: x
C3: ="Loans & deposits - "&Control!$B$2 -> Loans & deposits - Bank A
C4: Item | D4: ="Week "&TEXT(Control!$B$4-5,"00") -> Week 35 | E4: ="Week "&TEXT(Control!$B$4-4,"00") -> Week 36 | F4: ="Week "&TEXT(Control!$B$4-3,"00") -> Week 37 | G4: ="Week "&TEXT(Control!$B$4-2,"00") -> Week 38 | H4: Delta w/w | I4: Delta % | J4: Budget | K4: vs Budget
C5: Loans | D5: =ROUND(SUMIFS(Data!$C:$C,Data!$A:$A,Control!$B$2,Data!$B:$B,Control!$B$4-5)*Control!$B$5,1) -> 1873.2 | E5: =ROUND(SUMIFS(Data!$C:$C,Data!$A:$A,Control!$B$2,Data!$B:$B,Control!$B$4-4)*Control!$B$5,1) -> 1896.4 | F5: =ROUND(SUMIFS(Data!$C:$C,Data!$A:$A,Control!$B$2,Data!$B:$B,Control!$B$4-3)*Control!$B$5,1) -> 1877.9 | G5: =ROUND(SUMIFS(Data!$C:$C,Data!$A:$A,Control!$B$2,Data!$B:$B,Control!$B$4-2)*Control!$B$5,1) -> 1809.6 | H5: =G5-F5 -> -68.3 | I5: =IFERROR(H5/F5,0) -> -0.036370414 | J5: =ROUND(SUMIFS(Data!$E:$E,Data!$A:$A,Control!$B$2,Data!$B:$B,Control!$B$4-2)*Control!$B$5,1) -> 1904.7 | K5: =IF(ABS(G5-J5)<0.05,0,G5-J5) -> -95.1
C6: Deposits | D6: =ROUND(SUMIFS(Data!$D:$D,Data!$A:$A,Control!$B$2,Data!$B:$B,Control!$B$4-5)*Control!$B$5,1) -> 2185.7 | E6: =ROUND(SUMIFS(Data!$D:$D,Data!$A:$A,Control!$B$2,Data!$B:$B,Control!$B$4-4)*Control!$B$5,1) -> 2083.1 | F6: =ROUND(SUMIFS(Data!$D:$D,Data!$A:$A,Control!$B$2,Data!$B:$B,Control!$B$4-3)*Control!$B$5,1) -> 2190.9 | G6: =ROUND(SUMIFS(Data!$D:$D,Data!$A:$A,Control!$B$2,Data!$B:$B,Control!$B$4-2)*Control!$B$5,1) -> 2113.2 | H6: =G6-F6 -> -77.7 | I6: =IFERROR(H6/F6,0) -> -0.035464877 | J6: =ROUND(SUMIFS(Data!$F:$F,Data!$A:$A,Control!$B$2,Data!$B:$B,Control!$B$4-2)*Control!$B$5,1) -> 2211.7 | K6: =IF(ABS(G6-J6)<0.05,0,G6-J6) -> -98.5
C7: Total | D7: =SUM(D5:D6) -> 4058.9 | E7: =SUM(E5:E6) -> 3979.5 | F7: =SUM(F5:F6) -> 4068.8 | G7: =SUM(G5:G6) -> 3922.8 | H7: =SUM(H5:H6) -> -146 | I7: =IFERROR(H7/F7,0) -> -0.035882816 | J7: =SUM(J5:J6) -> 4116.4 | K7: =SUM(K5:K6) -> -193.6
C8: L/D ratio | D8: =IF(D6=0,"n/a",D5/D6) -> 0.85702521 | E8: =IF(E6=0,"n/a",E5/E6) -> 0.91037396 | F8: =IF(F6=0,"n/a",F5/F6) -> 0.85713634 | G8: =IF(G6=0,"n/a",G5/G6) -> 0.85633163
C9: Average 4w | D9: =AVERAGE(D7:G7) -> 4007.5 | E9: =MAX(D7:G7) -> 4068.8 | F9: =MIN(D7:G7) -> 3922.8 | G9: =COUNTIF(H5:H6,">0") -> 0
C10: ="vs SLIDE_2" -> vs SLIDE_2 | D10: =G7-SLIDE_2!G7 -> -119.3 | E10: =IFERROR(D10/SLIDE_2!G7,0) -> -0.029514361 | F10: =IF(AND(D10>0,SLIDE_2!H7>0),"up",IF(OR(D10<0,SLIDE_2!H7<0),"down","flat")) -> down | G10: =INDEX(SLIDE_2!D5:G6,2,MATCH(MAX(SLIDE_2!D6:G6),SLIDE_2!D6:G6,0)) -> 2190.9
C11: Rank | D11: =RANK(G5,Data!$C$2:$C$521) -> #N/A | E11: =SUMPRODUCT((Data!$B$2:$B$521=Control!$B$4)*(Data!$C$2:$C$521>G5))+1 -> 10 | F11: =VLOOKUP(Control!$B$2,Data!$H$2:$H$11,1,FALSE) -> Bank A | G11: =LEFT(Control!$B$2,4)&MID(Control!$B$2,6,1)&LEN(Control!$B$2) -> BankA6
C12: Misc | D12: =CHOOSE(MOD(Control!$B$3,3)+1,"one","two","three") -> two | E12: =TEXT(Control!$B$8,"mmm yy") -> ott yy | F12: =OFFSET(D5,1,2) -> 2190.9 | G12: =INDIRECT("D7") -> 4058.9 | H12: =AVERAGEIF(Data!$A$2:$A$521,Control!$B$2,Data!$C$2:$C$521) -> 1655.3948 | I12: =DATE(2026,1,5)+7*(Control!$B$4-1) -> 46300 | J12: =CONCATENATE(Control!$B$6," EUR") -> mln EUR | K12: =ROUNDUP(G7/1000,0)*1000 -> 4000
C13: Today | D13: =TODAY() -> 46311 | E13: =IF(ISNUMBER(G5),"ok","missing") -> ok | F13: =LARGE(Data!$C$2:$C$521,3) -> 9376.065 | G13: =SMALL(D5:G6,2) -> 1873.2 | H13: =_xlfn.XLOOKUP(Control!$B$2,Data!$H$2:$H$11,Data!$H$2:$H$11,"none") -> Bank A | I13: {=_xlfn.IFS(G5>F5,"up",G5<F5,"down",TRUE,"flat")} -> down | J13: {=_xlfn.SWITCH(Control!$B$6,"mln",1000000,"k",1000,1)} -> 1000000 | K13: =_xlfn.LET(_xlpm.x,G7,_xlpm.y,J7,IF(_xlpm.y=0,0,_xlpm.x/_xlpm.y-1)) -> -0.047031387 | L13: =SUM(_xlfn._xlws.FILTER(Data!$C$2:$C$521,Data!$A$2:$A$521=Control!$B$2)) -> 86080.528

Sheet SLIDE_4
B2: x
C3: ="Loans & deposits - "&Control!$B$2 -> Loans & deposits - Bank A
C4: Item | D4: ="Week "&TEXT(Control!$B$4-6,"00") -> Week 34 | E4: ="Week "&TEXT(Control!$B$4-5,"00") -> Week 35 | F4: ="Week "&TEXT(Control!$B$4-4,"00") -> Week 36 | G4: ="Week "&TEXT(Control!$B$4-3,"00") -> Week 37 | H4: Delta w/w | I4: Delta % | J4: Budget | K4: vs Budget
C5: Loans | D5: =ROUND(SUMIFS(Data!$C:$C,Data!$A:$A,Control!$B$2,Data!$B:$B,Control!$B$4-6)*Control!$B$5,1) -> 1859.9 | E5: =ROUND(SUMIFS(Data!$C:$C,Data!$A:$A,Control!$B$2,Data!$B:$B,Control!$B$4-5)*Control!$B$5,1) -> 1873.2 | F5: =ROUND(SUMIFS(Data!$C:$C,Data!$A:$A,Control!$B$2,Data!$B:$B,Control!$B$4-4)*Control!$B$5,1) -> 1896.4 | G5: =ROUND(SUMIFS(Data!$C:$C,Data!$A:$A,Control!$B$2,Data!$B:$B,Control!$B$4-3)*Control!$B$5,1) -> 1877.9 | H5: =G5-F5 -> -18.5 | I5: =IFERROR(H5/F5,0) -> -0.0097553259 | J5: =ROUND(SUMIFS(Data!$E:$E,Data!$A:$A,Control!$B$2,Data!$B:$B,Control!$B$4-3)*Control!$B$5,1) -> 1898.2 | K5: =IF(ABS(G5-J5)<0.05,0,G5-J5) -> -20.3
C6: Deposits | D6: =ROUND(SUMIFS(Data!$D:$D,Data!$A:$A,Control!$B$2,Data!$B:$B,Control!$B$4-6)*Control!$B$5,1) -> 2174.4 | E6: =ROUND(SUMIFS(Data!$D:$D,Data!$A:$A,Control!$B$2,Data!$B:$B,Control!$B$4-5)*Control!$B$5,1) -> 2185.7 | F6: =ROUND(SUMIFS(Data!$D:$D,Data!$A:$A,Control!$B$2,Data!$B:$B,Control!$B$4-4)*Control!$B$5,1) -> 2083.1 | G6: =ROUND(SUMIFS(Data!$D:$D,Data!$A:$A,Control!$B$2,Data!$B:$B,Control!$B$4-3)*Control!$B$5,1) -> 2190.9 | H6: =G6-F6 -> 107.8 | I6: =IFERROR(H6/F6,0) -> 0.051749796 | J6: =ROUND(SUMIFS(Data!$F:$F,Data!$A:$A,Control!$B$2,Data!$B:$B,Control!$B$4-3)*Control!$B$5,1) -> 2205.2 | K6: =IF(ABS(G6-J6)<0.05,0,G6-J6) -> -14.3
C7: Total | D7: =SUM(D5:D6) -> 4034.3 | E7: =SUM(E5:E6) -> 4058.9 | F7: =SUM(F5:F6) -> 3979.5 | G7: =SUM(G5:G6) -> 4068.8 | H7: =SUM(H5:H6) -> 89.3 | I7: =IFERROR(H7/F7,0) -> 0.022440005 | J7: =SUM(J5:J6) -> 4103.4 | K7: =SUM(K5:K6) -> -34.6
C8: L/D ratio | D8: =IF(D6=0,"n/a",D5/D6) -> 0.8553624 | E8: =IF(E6=0,"n/a",E5/E6) -> 0.85702521 | F8: =IF(F6=0,"n/a",F5/F6) -> 0.91037396 | G8: =IF(G6=0,"n/a",G5/G6) -> 0.85713634
C9: Average 4w | D9: =AVERAGE(D7:G7) -> 4035.375 | E9: =MAX(D7:G7) -> 4068.8 | F9: =MIN(D7:G7) -> 3979.5 | G9: =COUNTIF(H5:H6,">0") -> 1
C10: ="vs SLIDE_3" -> vs SLIDE_3 | D10: =G7-SLIDE_3!G7 -> 146 | E10: =IFERROR(D10/SLIDE_3!G7,0) -> 0.037218313 | F10: =IF(AND(D10>0,SLIDE_3!H7>0),"up",IF(OR(D10<0,SLIDE_3!H7<0),"down","flat")) -> down | G10: =INDEX(SLIDE_3!D5:G6,2,MATCH(MAX(SLIDE_3!D6:G6),SLIDE_3!D6:G6,0)) -> 2190.9
C11: Rank | D11: =RANK(G5,Data!$C$2:$C$521) -> #N/A | E11: =SUMPRODUCT((Data!$B$2:$B$521=Control!$B$4)*(Data!$C$2:$C$521>G5))+1 -> 10 | F11: =VLOOKUP(Control!$B$2,Data!$H$2:$H$11,1,FALSE) -> Bank A | G11: =LEFT(Control!$B$2,4)&MID(Control!$B$2,6,1)&LEN(Control!$B$2) -> BankA6
C12: Misc | D12: =CHOOSE(MOD(Control!$B$3,3)+1,"one","two","three") -> two | E12: =TEXT(Control!$B$8,"mmm yy") -> ott yy | F12: =OFFSET(D5,1,2) -> 2083.1 | G12: =INDIRECT("D7") -> 4034.3 | H12: =AVERAGEIF(Data!$A$2:$A$521,Control!$B$2,Data!$C$2:$C$521) -> 1655.3948 | I12: =DATE(2026,1,5)+7*(Control!$B$4-1) -> 46300 | J12: =CONCATENATE(Control!$B$6," EUR") -> mln EUR | K12: =ROUNDUP(G7/1000,0)*1000 -> 5000
C13: Today | D13: =TODAY() -> 46311 | E13: =IF(ISNUMBER(G5),"ok","missing") -> ok | F13: =LARGE(Data!$C$2:$C$521,3) -> 9376.065 | G13: =SMALL(D5:G6,2) -> 1873.2 | H13: =_xlfn.XLOOKUP(Control!$B$2,Data!$H$2:$H$11,Data!$H$2:$H$11,"none") -> Bank A | I13: {=_xlfn.IFS(G5>F5,"up",G5<F5,"down",TRUE,"flat")} -> down | J13: {=_xlfn.SWITCH(Control!$B$6,"mln",1000000,"k",1000,1)} -> 1000000 | K13: =_xlfn.LET(_xlpm.x,G7,_xlpm.y,J7,IF(_xlpm.y=0,0,_xlpm.x/_xlpm.y-1)) -> -0.008432032 | L13: =SUM(_xlfn._xlws.FILTER(Data!$C$2:$C$521,Data!$A$2:$A$521=Control!$B$2)) -> 86080.528

Sheet SLIDE_5
B2: x
C3: ="Loans & deposits - "&Control!$B$2 -> Loans & deposits - Bank A
C4: Item | D4: ="Week "&TEXT(Control!$B$4-7,"00") -> Week 33 | E4: ="Week "&TEXT(Control!$B$4-6,"00") -> Week 34 | F4: ="Week "&TEXT(Control!$B$4-5,"00") -> Week 35 | G4: ="Week "&TEXT(Control!$B$4-4,"00") -> Week 36 | H4: Delta w/w | I4: Delta % | J4: Budget | K4: vs Budget
C5: Loans | D5: =ROUND(SUMIFS(Data!$C:$C,Data!$A:$A,Control!$B$2,Data!$B:$B,Control!$B$4-7)*Control!$B$5,1) -> 1823.3 | E5: =ROUND(SUMIFS(Data!$C:$C,Data!$A:$A,Control!$B$2,Data!$B:$B,Control!$B$4-6)*Control!$B$5,1) -> 1859.9 | F5: =ROUND(SUMIFS(Data!$C:$C,Data!$A:$A,Control!$B$2,Data!$B:$B,Control!$B$4-5)*Control!$B$5,1) -> 1873.2 | G5: =ROUND(SUMIFS(Data!$C:$C,Data!$A:$A,Control!$B$2,Data!$B:$B,Control!$B$4-4)*Control!$B$5,1) -> 1896.4 | H5: =G5-F5 -> 23.2 | I5: =IFERROR(H5/F5,0) -> 0.012385223 | J5: =ROUND(SUMIFS(Data!$E:$E,Data!$A:$A,Control!$B$2,Data!$B:$B,Control!$B$4-4)*Control!$B$5,1) -> 1890.6 | K5: =IF(ABS(G5-J5)<0.05,0,G5-J5) -> 5.8
C6: Deposits | D6: =ROUND(SUMIFS(Data!$D:$D,Data!$A:$A,Control!$B$2,Data!$B:$B,Control!$B$4-7)*Control!$B$5,1) -> 2147.9 | E6: =ROUND(SUMIFS(Data!$D:$D,Data!$A:$A,Control!$B$2,Data!$B:$B,Control!$B$4-6)*Control!$B$5,1) -> 2174.4 | F6: =ROUND(SUMIFS(Data!$D:$D,Data!$A:$A,Control!$B$2,Data!$B:$B,Control!$B$4-5)*Control!$B$5,1) -> 2185.7 | G6: =ROUND(SUMIFS(Data!$D:$D,Data!$A:$A,Control!$B$2,Data!$B:$B,Control!$B$4-4)*Control!$B$5,1) -> 2083.1 | H6: =G6-F6 -> -102.6 | I6: =IFERROR(H6/F6,0) -> -0.046941483 | J6: =ROUND(SUMIFS(Data!$F:$F,Data!$A:$A,Control!$B$2,Data!$B:$B,Control!$B$4-4)*Control!$B$5,1) -> 2198.7 | K6: =IF(ABS(G6-J6)<0.05,0,G6-J6) -> -115.6
C7: Total | D7: =SUM(D5:D6) -> 3971.2 | E7: =SUM(E5:E6) -> 4034.3 | F7: =SUM(F5:F6) -> 4058.9 | G7: =SUM(G5:G6) -> 3979.5 | H7: =SUM(H5:H6) -> -79.4 | I7: =IFERROR(H7/F7,0) -> -0.01956195 | J7: =SUM(J5:J6) -> 4089.3 | K7: =SUM(K5:K6) -> -109.8
C8: L/D ratio | D8: =IF(D6=0,"n/a",D5/D6) -> 0.84887565 | E8: =IF(E6=0,"n/a",E5/E6) -> 0.8553624 | F8: =IF(F6=0,"n/a",F5/F6) -> 0.85702521 | G8: =IF(G6=0,"n/a",G5/G6) -> 0.91037396
C9: Average 4w | D9: =AVERAGE(D7:G7) -> 4010.975 | E9: =MAX(D7:G7) -> 4058.9 | F9: =MIN(D7:G7) -> 3971.2 | G9: =COUNTIF(H5:H6,">0") -> 1
C10: ="vs SLIDE_4" -> vs SLIDE_4 | D10: =G7-SLIDE_4!G7 -> -89.3 | E10: =IFERROR(D10/SLIDE_4!G7,0) -> -0.021947503 | F10: =IF(AND(D10>0,SLIDE_4!H7>0),"up",IF(OR(D10<0,SLIDE_4!H7<0),"down","flat")) -> down | G10: =INDEX(SLIDE_4!D5:G6,2,MATCH(MAX(SLIDE_4!D6:G6),SLIDE_4!D6:G6,0)) -> 2190.9
C11: Rank | D11: =RANK(G5,Data!$C$2:$C$521) -> #N/A | E11: =SUMPRODUCT((Data!$B$2:$B$521=Control!$B$4)*(Data!$C$2:$C$521>G5))+1 -> 10 | F11: =VLOOKUP(Control!$B$2,Data!$H$2:$H$11,1,FALSE) -> Bank A | G11: =LEFT(Control!$B$2,4)&MID(Control!$B$2,6,1)&LEN(Control!$B$2) -> BankA6
C12: Misc | D12: =CHOOSE(MOD(Control!$B$3,3)+1,"one","two","three") -> two | E12: =TEXT(Control!$B$8,"mmm yy") -> ott yy | F12: =OFFSET(D5,1,2) -> 2185.7 | G12: =INDIRECT("D7") -> 3971.2 | H12: =AVERAGEIF(Data!$A$2:$A$521,Control!$B$2,Data!$C$2:$C$521) -> 1655.3948 | I12: =DATE(2026,1,5)+7*(Control!$B$4-1) -> 46300 | J12: =CONCATENATE(Control!$B$6," EUR") -> mln EUR | K12: =ROUNDUP(G7/1000,0)*1000 -> 4000
C13: Today | D13: =TODAY() -> 46311 | E13: =IF(ISNUMBER(G5),"ok","missing") -> ok | F13: =LARGE(Data!$C$2:$C$521,3) -> 9376.065 | G13: =SMALL(D5:G6,2) -> 1859.9 | H13: =_xlfn.XLOOKUP(Control!$B$2,Data!$H$2:$H$11,Data!$H$2:$H$11,"none") -> Bank A | I13: {=_xlfn.IFS(G5>F5,"up",G5<F5,"down",TRUE,"flat")} -> up | J13: {=_xlfn.SWITCH(Control!$B$6,"mln",1000000,"k",1000,1)} -> 1000000 | K13: =_xlfn.LET(_xlpm.x,G7,_xlpm.y,J7,IF(_xlpm.y=0,0,_xlpm.x/_xlpm.y-1)) -> -0.026850561 | L13: =SUM(_xlfn._xlws.FILTER(Data!$C$2:$C$521,Data!$A$2:$A$521=Control!$B$2)) -> 86080.528

Sheet SLIDE_6
B2: x
C3: ="Loans & deposits - "&Control!$B$2 -> Loans & deposits - Bank A
C4: Item | D4: ="Week "&TEXT(Control!$B$4-8,"00") -> Week 32 | E4: ="Week "&TEXT(Control!$B$4-7,"00") -> Week 33 | F4: ="Week "&TEXT(Control!$B$4-6,"00") -> Week 34 | G4: ="Week "&TEXT(Control!$B$4-5,"00") -> Week 35 | H4: Delta w/w | I4: Delta % | J4: Budget | K4: vs Budget
C5: Loans | D5: =ROUND(SUMIFS(Data!$C:$C,Data!$A:$A,Control!$B$2,Data!$B:$B,Control!$B$4-8)*Control!$B$5,1) -> 1807.6 | E5: =ROUND(SUMIFS(Data!$C:$C,Data!$A:$A,Control!$B$2,Data!$B:$B,Control!$B$4-7)*Control!$B$5,1) -> 1823.3 | F5: =ROUND(SUMIFS(Data!$C:$C,Data!$A:$A,Control!$B$2,Data!$B:$B,Control!$B$4-6)*Control!$B$5,1) -> 1859.9 | G5: =ROUND(SUMIFS(Data!$C:$C,Data!$A:$A,Control!$B$2,Data!$B:$B,Control!$B$4-5)*Control!$B$5,1) -> 1873.2 | H5: =G5-F5 -> 13.3 | I5: =IFERROR(H5/F5,0) -> 0.0071509221 | J5: =ROUND(SUMIFS(Data!$E:$E,Data!$A:$A,Control!$B$2,Data!$B:$B,Control!$B$4-5)*Control!$B$5,1) -> 1883 | K5: =IF(ABS(G5-J5)<0.05,0,G5-J5) -> -9.8
C6: Deposits | D6: =ROUND(SUMIFS(Data!$D:$D,Data!$A:$A,Control!$B$2,Data!$B:$B,Control!$B$4-8)*Control!$B$5,1) -> 2149.7 | E6: =ROUND(SUMIFS(Data!$D:$D,Data!$A:$A,Control!$B$2,Data!$B:$B,Control!$B$4-7)*Control!$B$5,1) -> 2147.9 | F6: =ROUND(SUMIFS(Data!$D:$D,Data!$A:$A,Control!$B$2,Data!$B:$B,Control!$B$4-6)*Control!$B$5,1) -> 2174.4 | G6: =ROUND(SUMIFS(Data!$D:$D,Data!$A:$A,Control!$B$2,Data!$B:$B,Control!$B$4-5)*Control!$B$5,1) -> 2185.7 | H6: =G6-F6 -> 11.3 | I6: =IFERROR(H6/F6,0) -> 0.0051968359 | J6: =ROUND(SUMIFS(Data!$F:$F,Data!$A:$A,Control!$B$2,Data!$B:$B,Control!$B$4-5)*Control!$B$5,1) -> 2191.1 | K6: =IF(ABS(G6-J6)<0.05,0,G6-J6) -> -5.4
C7: Total | D7: =SUM(D5:D6) -> 3957.3 | E7: =SUM(E5:E6) -> 3971.2 | F7: =SUM(F5:F6) -> 4034.3 | G7: =SUM(G5:G6) -> 4058.9 | H7: =SUM(H5:H6) -> 24.6 | I7: =IFERROR(H7/F7,0) -> 0.0060977121 | J7: =SUM(J5:J6) -> 4074.1 | K7: =SUM(K5:K6) -> -15.2
C8: L/D ratio | D8: =IF(D6=0,"n/a",D5/D6) -> 0.84086152 | E8: =IF(E6=0,"n/a",E5/E6) -> 0.84887565 | F8: =IF(F6=0,"n/a",F5/F6) -> 0.8553624 | G8: =IF(G6=0,"n/a",G5/G6) -> 0.85702521
C9: Average 4w | D9: =AVERAGE(D7:G7) -> 4005.425 | E9: =MAX(D7:G7) -> 4058.9 | F9: =MIN(D7:G7) -> 3957.3 | G9: =COUNTIF(H5:H6,">0") -> 2
C10: ="vs SLIDE_5" -> vs SLIDE_5 | D10: =G7-SLIDE_5!G7 -> 79.4 | E10: =IFERROR(D10/SLIDE_5!G7,0) -> 0.019952255 | F10: =IF(AND(D10>0,SLIDE_5!H7>0),"up",IF(OR(D10<0,SLIDE_5!H7<0),"down","flat")) -> down | G10: =INDEX(SLIDE_5!D5:G6,2,MATCH(MAX(SLIDE_5!D6:G6),SLIDE_5!D6:G6,0)) -> 2185.7
C11: Rank | D11: =RANK(G5,Data!$C$2:$C$521) -> #N/A | E11: =SUMPRODUCT((Data!$B$2:$B$521=Control!$B$4)*(Data!$C$2:$C$521>G5))+1 -> 10 | F11: =VLOOKUP(Control!$B$2,Data!$H$2:$H$11,1,FALSE) -> Bank A | G11: =LEFT(Control!$B$2,4)&MID(Control!$B$2,6,1)&LEN(Control!$B$2) -> BankA6
C12: Misc | D12: =CHOOSE(MOD(Control!$B$3,3)+1,"one","two","three") -> two | E12: =TEXT(Control!$B$8,"mmm yy") -> ott yy | F12: =OFFSET(D5,1,2) -> 2174.4 | G12: =INDIRECT("D7") -> 3957.3 | H12: =AVERAGEIF(Data!$A$2:$A$521,Control!$B$2,Data!$C$2:$C$521) -> 1655.3948 | I12: =DATE(2026,1,5)+7*(Control!$B$4-1) -> 46300 | J12: =CONCATENATE(Control!$B$6," EUR") -> mln EUR | K12: =ROUNDUP(G7/1000,0)*1000 -> 5000
C13: Today | D13: =TODAY() -> 46311 | E13: =IF(ISNUMBER(G5),"ok","missing") -> ok | F13: =LARGE(Data!$C$2:$C$521,3) -> 9376.065 | G13: =SMALL(D5:G6,2) -> 1823.3 | H13: =_xlfn.XLOOKUP(Control!$B$2,Data!$H$2:$H$11,Data!$H$2:$H$11,"none") -> Bank A | I13: {=_xlfn.IFS(G5>F5,"up",G5<F5,"down",TRUE,"flat")} -> up | J13: {=_xlfn.SWITCH(Control!$B$6,"mln",1000000,"k",1000,1)} -> 1000000 | K13: =_xlfn.LET(_xlpm.x,G7,_xlpm.y,J7,IF(_xlpm.y=0,0,_xlpm.x/_xlpm.y-1)) -> -0.0037308853 | L13: =SUM(_xlfn._xlws.FILTER(Data!$C$2:$C$521,Data!$A$2:$A$521=Control!$B$2)) -> 86080.528

Sheet SLIDE_7
B2: x
C3: ="Loans & deposits - "&Control!$B$2 -> Loans & deposits - Bank A
C4: Item | D4: ="Week "&TEXT(Control!$B$4-9,"00") -> Week 31 | E4: ="Week "&TEXT(Control!$B$4-8,"00") -> Week 32 | F4: ="Week "&TEXT(Control!$B$4-7,"00") -> Week 33 | G4: ="Week "&TEXT(Control!$B$4-6,"00") -> Week 34 | H4: Delta w/w | I4: Delta % | J4: Budget | K4: vs Budget
C5: Loans | D5: =ROUND(SUMIFS(Data!$C:$C,Data!$A:$A,Control!$B$2,Data!$B:$B,Control!$B$4-9)*Control!$B$5,1) -> 1857.7 | E5: =ROUND(SUMIFS(Data!$C:$C,Data!$A:$A,Control!$B$2,Data!$B:$B,Control!$B$4-8)*Control!$B$5,1) -> 1807.6 | F5: =ROUND(SUMIFS(Data!$C:$C,Data!$A:$A,Control!$B$2,Data!$B:$B,Control!$B$4-7)*Control!$B$5,1) -> 1823.3 | G5: =ROUND(SUMIFS(Data!$C:$C,Data!$A:$A,Control!$B$2,Data!$B:$B,Control!$B$4-6)*Control!$B$5,1) -> 1859.9 | H5: =G5-F5 -> 36.6 | I5: =IFERROR(H5/F5,0) -> 0.020073493 | J5: =ROUND(SUMIFS(Data!$E:$E,Data!$A:$A,Control!$B$2,Data!$B:$B,Control!$B$4-6)*Control!$B$5,1) -> 1876.5 | K5: =IF(ABS(G5-J5)<0.05,0,G5-J5) -> -16.6
C6: Deposits | D6: =ROUND(SUMIFS(Data!$D:$D,Data!$A:$A,Control!$B$2,Data!$B:$B,Control!$B$4-9)*Control!$B$5,1) -> 2086.3 | E6: =ROUND(SUMIFS(Data!$D:$D,Data!$A:$A,Control!$B$2,Data!$B:$B,Control!$B$4-8)*Control!$B$5,1) -> 2149.7 | F6: =ROUND(SUMIFS(Data!$D:$D,Data!$A:$A,Control!$B$2,Data!$B:$B,Control!$B$4-7)*Control!$B$5,1) -> 2147.9 | G6: =ROUND(SUMIFS(Data!$D:$D,Data!$A:$A,Control!$B$2,Data!$B:$B,Control!$B$4-6)*Control!$B$5,1) -> 2174.4 | H6: =G6-F6 -> 26.5 | I6: =IFERROR(H6/F6,0) -> 0.012337632 | J6: =ROUND(SUMIFS(Data!$F:$F,Data!$A:$A,Control!$B$2,Data!$B:$B,Control!$B$4-6)*Control!$B$5,1) -> 2184.6 | K6: =IF(ABS(G6-J6)<0.05,0,G6-J6) -> -10.2
C7: Total | D7: =SUM(D5:D6) -> 3944 | E7: =SUM(E5:E6) -> 3957.3 | F7: =SUM(F5:F6) -> 3971.2 | G7: =SUM(G5:G6) -> 4034.3 | H7: =SUM(H5:H6) -> 63.1 | I7: =IFERROR(H7/F7,0) -> 0.015889404 | J7: =SUM(J5:J6) -> 4061.1 | K7: =SUM(K5:K6) -> -26.8
C8: L/D ratio | D8: =IF(D6=0,"n/a",D5/D6) -> 0.89042803 | E8: =IF(E6=0,"n/a",E5/E6) -> 0.84086152 | F8: =IF(F6=0,"n/a",F5/F6) -> 0.84887565 | G8: =IF(G6=0,"n/a",G5/G6) -> 0.8553624
C9: Average 4w | D9: =AVERAGE(D7:G7) -> 3976.7 | E9: =MAX(D7:G7) -> 4034.3 | F9: =MIN(D7:G7) -> 3944 | G9: =COUNTIF(H5:H6,">0") -> 2
C10: ="vs SLIDE_6" -> vs SLIDE_6 | D10: =G7-SLIDE_6!G7 -> -24.6 | E10: =IFERROR(D10/SLIDE_6!G7,0) -> -0.0060607554 | F10: =IF(AND(D10>0,SLIDE_6!H7>0),"up",IF(OR(D10<0,SLIDE_6!H7<0),"down","flat")) -> down | G10: =INDEX(SLIDE_6!D5:G6,2,MATCH(MAX(SLIDE_6!D6:G6),SLIDE_6!D6:G6,0)) -> 2185.7
C11: Rank | D11: =RANK(G5,Data!$C$2:$C$521) -> #N/A | E11: =SUMPRODUCT((Data!$B$2:$B$521=Control!$B$4)*(Data!$C$2:$C$521>G5))+1 -> 10 | F11: =VLOOKUP(Control!$B$2,Data!$H$2:$H$11,1,FALSE) -> Bank A | G11: =LEFT(Control!$B$2,4)&MID(Control!$B$2,6,1)&LEN(Control!$B$2) -> BankA6
C12: Misc | D12: =CHOOSE(MOD(Control!$B$3,3)+1,"one","two","three") -> two | E12: =TEXT(Control!$B$8,"mmm yy") -> ott yy | F12: =OFFSET(D5,1,2) -> 2147.9 | G12: =INDIRECT("D7") -> 3944 | H12: =AVERAGEIF(Data!$A$2:$A$521,Control!$B$2,Data!$C$2:$C$521) -> 1655.3948 | I12: =DATE(2026,1,5)+7*(Control!$B$4-1) -> 46300 | J12: =CONCATENATE(Control!$B$6," EUR") -> mln EUR | K12: =ROUNDUP(G7/1000,0)*1000 -> 5000
C13: Today | D13: =TODAY() -> 46311 | E13: =IF(ISNUMBER(G5),"ok","missing") -> ok | F13: =LARGE(Data!$C$2:$C$521,3) -> 9376.065 | G13: =SMALL(D5:G6,2) -> 1823.3 | H13: =_xlfn.XLOOKUP(Control!$B$2,Data!$H$2:$H$11,Data!$H$2:$H$11,"none") -> Bank A | I13: {=_xlfn.IFS(G5>F5,"up",G5<F5,"down",TRUE,"flat")} -> up | J13: {=_xlfn.SWITCH(Control!$B$6,"mln",1000000,"k",1000,1)} -> 1000000 | K13: =_xlfn.LET(_xlpm.x,G7,_xlpm.y,J7,IF(_xlpm.y=0,0,_xlpm.x/_xlpm.y-1)) -> -0.0065991973 | L13: =SUM(_xlfn._xlws.FILTER(Data!$C$2:$C$521,Data!$A$2:$A$521=Control!$B$2)) -> 86080.528

Sheet SLIDE_8
B2: x
C3: ="Loans & deposits - "&Control!$B$2 -> Loans & deposits - Bank A
C4: Item | D4: ="Week "&TEXT(Control!$B$4-10,"00") -> Week 30 | E4: ="Week "&TEXT(Control!$B$4-9,"00") -> Week 31 | F4: ="Week "&TEXT(Control!$B$4-8,"00") -> Week 32 | G4: ="Week "&TEXT(Control!$B$4-7,"00") -> Week 33 | H4: Delta w/w | I4: Delta % | J4: Budget | K4: vs Budget
C5: Loans | D5: =ROUND(SUMIFS(Data!$C:$C,Data!$A:$A,Control!$B$2,Data!$B:$B,Control!$B$4-10)*Control!$B$5,1) -> 1808.8 | E5: =ROUND(SUMIFS(Data!$C:$C,Data!$A:$A,Control!$B$2,Data!$B:$B,Control!$B$4-9)*Control!$B$5,1) -> 1857.7 | F5: =ROUND(SUMIFS(Data!$C:$C,Data!$A:$A,Control!$B$2,Data!$B:$B,Control!$B$4-8)*Control!$B$5,1) -> 1807.6 | G5: =ROUND(SUMIFS(Data!$C:$C,Data!$A:$A,Control!$B$2,Data!$B:$B,Control!$B$4-7)*Control!$B$5,1) -> 1823.3 | H5: =G5-F5 -> 15.7 | I5: =IFERROR(H5/F5,0) -> 0.0086855499 | J5: =ROUND(SUMIFS(Data!$E:$E,Data!$A:$A,Control!$B$2,Data!$B:$B,Control!$B$4-7)*Control!$B$5,1) -> 1868.9 | K5: =IF(ABS(G5-J5)<0.05,0,G5-J5) -> -45.6
C6: Deposits | D6: =ROUND(SUMIFS(Data!$D:$D,Data!$A:$A,Control!$B$2,Data!$B:$B,Control!$B$4-10)*Control!$B$5,1) -> 2094.6 | E6: =ROUND(SUMIFS(Data!$D:$D,Data!$A:$A,Control!$B$2,Data!$B:$B,Control!$B$4-9)*Control!$B$5,1) -> 2086.3 | F6: =ROUND(SUMIFS(Data!$D:$D,Data!$A:$A,Control!$B$2,Data!$B:$B,Control!$B$4-8)*Control!$B$5,1) -> 2149.7 | G6: =ROUND(SUMIFS(Data!$D:$D,Data!$A:$A,Control!$B$2,Data!$B:$B,Control!$B$4-7)*Control!$B$5,1) -> 2147.9 | H6: =G6-F6 -> -1.8 | I6: =IFERROR(H6/F6,0) -> -0.00083732614 | J6: =ROUND(SUMIFS(Data!$F:$F,Data!$A:$A,Control!$B$2,Data!$B:$B,Control!$B$4-7)*Control!$B$5,1) -> 2178.1 | K6: =IF(ABS(G6-J6)<0.05,0,G6-J6) -> -30.2
C7: Total | D7: =SUM(D5:D6) -> 3903.4 | E7: =SUM(E5:E6) -> 3944 | F7: =SUM(F5:F6) -> 3957.3 | G7: =SUM(G5:G6) -> 3971.2 | H7: =SUM(H5:H6) -> 13.9 | I7: =IFERROR(H7/F7,0) -> 0.0035124959 | J7: =SUM(J5:J6) -> 4047 | K7: =SUM(K5:K6) -> -75.8
C8: L/D ratio | D8: =IF(D6=0,"n/a",D5/D6) -> 0.8635539 | E8: =IF(E6=0,"n/a",E5/E6) -> 0.89042803 | F8: =IF(F6=0,"n/a",F5/F6) -> 0.84086152 | G8: =IF(G6=0,"n/a",G5/G6) -> 0.84887565
C9: Average 4w | D9: =AVERAGE(D7:G7) -> 3943.975 | E9: =MAX(D7:G7) -> 3971.2 | F9: =MIN(D7:G7) -> 3903.4 | G9: =COUNTIF(H5:H6,">0") -> 1
C10: ="vs SLIDE_7" -> vs SLIDE_7 | D10: =G7-SLIDE_7!G7 -> -63.1 | E10: =IFERROR(D10/SLIDE_7!G7,0) -> -0.015640879 | F10: =IF(AND(D10>0,SLIDE_7!H7>0),"up",IF(OR(D10<0,SLIDE_7!H7<0),"down","flat")) -> down | G10: =INDEX(SLIDE_7!D5:G6,2,MATCH(MAX(SLIDE_7!D6:G6),SLIDE_7!D6:G6,0)) -> 2174.4
C11: Rank | D11: =RANK(G5,Data!$C$2:$C$521) -> #N/A | E11: =SUMPRODUCT((Data!$B$2:$B$521=Control!$B$4)*(Data!$C$2:$C$521>G5))+1 -> 10 | F11: =VLOOKUP(Control!$B$2,Data!$H$2:$H$11,1,FALSE) -> Bank A | G11: =LEFT(Control!$B$2,4)&MID(Control!$B$2,6,1)&LEN(Control!$B$2) -> BankA6
C12: Misc | D12: =CHOOSE(MOD(Control!$B$3,3)+1,"one","two","three") -> two | E12: =TEXT(Control!$B$8,"mmm yy") -> ott yy | F12: =OFFSET(D5,1,2) -> 2149.7 | G12: =INDIRECT("D7") -> 3903.4 | H12: =AVERAGEIF(Data!$A$2:$A$521,Control!$B$2,Data!$C$2:$C$521) -> 1655.3948 | I12: =DATE(2026,1,5)+7*(Control!$B$4-1) -> 46300 | J12: =CONCATENATE(Control!$B$6," EUR") -> mln EUR | K12: =ROUNDUP(G7/1000,0)*1000 -> 4000
C13: Today | D13: =TODAY() -> 46311 | E13: =IF(ISNUMBER(G5),"ok","missing") -> ok | F13: =LARGE(Data!$C$2:$C$521,3) -> 9376.065 | G13: =SMALL(D5:G6,2) -> 1808.8 | H13: =_xlfn.XLOOKUP(Control!$B$2,Data!$H$2:$H$11,Data!$H$2:$H$11,"none") -> Bank A | I13: {=_xlfn.IFS(G5>F5,"up",G5<F5,"down",TRUE,"flat")} -> up | J13: {=_xlfn.SWITCH(Control!$B$6,"mln",1000000,"k",1000,1)} -> 1000000 | K13: =_xlfn.LET(_xlpm.x,G7,_xlpm.y,J7,IF(_xlpm.y=0,0,_xlpm.x/_xlpm.y-1)) -> -0.018729923 | L13: =SUM(_xlfn._xlws.FILTER(Data!$C$2:$C$521,Data!$A$2:$A$521=Control!$B$2)) -> 86080.528

Sheet SLIDE_9
B2: x
C3: ="Loans & deposits - "&Control!$B$2 -> Loans & deposits - Bank A
C4: Item | D4: ="Week "&TEXT(Control!$B$4-11,"00") -> Week 29 | E4: ="Week "&TEXT(Control!$B$4-10,"00") -> Week 30 | F4: ="Week "&TEXT(Control!$B$4-9,"00") -> Week 31 | G4: ="Week "&TEXT(Control!$B$4-8,"00") -> Week 32 | H4: Delta w/w | I4: Delta % | J4: Budget | K4: vs Budget
C5: Loans | D5: =ROUND(SUMIFS(Data!$C:$C,Data!$A:$A,Control!$B$2,Data!$B:$B,Control!$B$4-11)*Control!$B$5,1) -> 1784.6 | E5: =ROUND(SUMIFS(Data!$C:$C,Data!$A:$A,Control!$B$2,Data!$B:$B,Control!$B$4-10)*Control!$B$5,1) -> 1808.8 | F5: =ROUND(SUMIFS(Data!$C:$C,Data!$A:$A,Control!$B$2,Data!$B:$B,Control!$B$4-9)*Control!$B$5,1) -> 1857.7 | G5: =ROUND(SUMIFS(Data!$C:$C,Data!$A:$A,Control!$B$2,Data!$B:$B,Control!$B$4-8)*Control!$B$5,1) -> 1807.6 | H5: =G5-F5 -> -50.1 | I5: =IFERROR(H5/F5,0) -> -0.026968832 | J5: =ROUND(SUMIFS(Data!$E:$E,Data!$A:$A,Control!$B$2,Data!$B:$B,Control!$B$4-8)*Control!$B$5,1) -> 1861.3 | K5: =IF(ABS(G5-J5)<0.05,0,G5-J5) -> -53.7
C6: Deposits | D6: =ROUND(SUMIFS(Data!$D:$D,Data!$A:$A,Control!$B$2,Data!$B:$B,Control!$B$4-11)*Control!$B$5,1) -> 2099.5 | E6: =ROUND(SUMIFS(Data!$D:$D,Data!$A:$A,Control!$B$2,Data!$B:$B,Control!$B$4-10)*Control!$B$5,1) -> 2094.6 | F6: =ROUND(SUMIFS(Data!$D:$D,Data!$A:$A,Control!$B$2,Data!$B:$B,Control!$B$4-9)*Control!$B$5,1) -> 2086.3 | G6: =ROUND(SUMIFS(Data!$D:$D,Data!$A:$A,Control!$B$2,Data!$B:$B,Control!$B$4-8)*Control!$B$5,1) -> 2149.7 | H6: =G6-F6 -> 63.4 | I6: =IFERROR(H6/F6,0) -> 0.030388726 | J6: =ROUND(SUMIFS(Data!$F:$F,Data!$A:$A,Control!$B$2,Data!$B:$B,Control!$B$4-8)*Control!$B$5,1) -> 2171.6 | K6: =IF(ABS(G6-J6)<0.05,0,G6-J6) -> -21.9
C7: Total | D7: =SUM(D5:D6) -> 3884.1 | E7: =SUM(E5:E6) -> 3903.4 | F7: =SUM(F5:F6) -> 3944 | G7: =SUM(G5:G6) -> 3957.3 | H7: =SUM(H5:H6) -> 13.3 | I7: =IFERROR(H7/F7,0) -> 0.003372211 | J7: =SUM(J5:J6) -> 4032.9 | K7: =SUM(K5:K6) -> -75.6
C8: L/D ratio | D8: =IF(D6=0,"n/a",D5/D6) -> 0.85001191 | E8: =IF(E6=0,"n/a",E5/E6) -> 0.8635539 | F8: =IF(F6=0,"n/a",F5/F6) -> 0.89042803 | G8: =IF(G6=0,"n/a",G5/G6) -> 0.84086152
C9: Average 4w | D9: =AVERAGE(D7:G7) -> 3922.2 | E9: =MAX(D7:G7) -> 3957.3 | F9: =MIN(D7:G7) -> 3884.1 | G9: =COUNTIF(H5:H6,">0") -> 1
C10: ="vs SLIDE_8" -> vs SLIDE_8 | D10: =G7-SLIDE_8!G7 -> -13.9 | E10: =IFERROR(D10/SLIDE_8!G7,0) -> -0.0035002015 | F10: =IF(AND(D10>0,SLIDE_8!H7>0),"up",IF(OR(D10<0,SLIDE_8!H7<0),"down","flat")) -> down | G10: =INDEX(SLIDE_8!D5:G6,2,MATCH(MAX(SLIDE_8!D6:G6),SLIDE_8!D6:G6,0)) -> 2149.7
C11: Rank | D11: =RANK(G5,Data!$C$2:$C$521) -> #N/A | E11: =SUMPRODUCT((Data!$B$2:$B$521=Control!$B$4)*(Data!$C$2:$C$521>G5))+1 -> 10 | F11: =VLOOKUP(Control!$B$2,Data!$H$2:$H$11,1,FALSE) -> Bank A | G11: =LEFT(Control!$B$2,4)&MID(Control!$B$2,6,1)&LEN(Control!$B$2) -> BankA6
C12: Misc | D12: =CHOOSE(MOD(Control!$B$3,3)+1,"one","two","three") -> two | E12: =TEXT(Control!$B$8,"mmm yy") -> ott yy | F12: =OFFSET(D5,1,2) -> 2086.3 | G12: =INDIRECT("D7") -> 3884.1 | H12: =AVERAGEIF(Data!$A$2:$A$521,Control!$B$2,Data!$C$2:$C$521) -> 1655.3948 | I12: =DATE(2026,1,5)+7*(Control!$B$4-1) -> 46300 | J12: =CONCATENATE(Control!$B$6," EUR") -> mln EUR | K12: =ROUNDUP(G7/1000,0)*1000 -> 4000
C13: Today | D13: =TODAY() -> 46311 | E13: =IF(ISNUMBER(G5),"ok","missing") -> ok | F13: =LARGE(Data!$C$2:$C$521,3) -> 9376.065 | G13: =SMALL(D5:G6,2) -> 1807.6 | H13: =_xlfn.XLOOKUP(Control!$B$2,Data!$H$2:$H$11,Data!$H$2:$H$11,"none") -> Bank A | I13: {=_xlfn.IFS(G5>F5,"up",G5<F5,"down",TRUE,"flat")} -> down | J13: {=_xlfn.SWITCH(Control!$B$6,"mln",1000000,"k",1000,1)} -> 1000000 | K13: =_xlfn.LET(_xlpm.x,G7,_xlpm.y,J7,IF(_xlpm.y=0,0,_xlpm.x/_xlpm.y-1)) -> -0.018745816 | L13: =SUM(_xlfn._xlws.FILTER(Data!$C$2:$C$521,Data!$A$2:$A$521=Control!$B$2)) -> 86080.528

Sheet SLIDE_10
B2: x
C3: ="Loans & deposits - "&Control!$B$2 -> Loans & deposits - Bank A
C4: Item | D4: ="Week "&TEXT(Control!$B$4-12,"00") -> Week 28 | E4: ="Week "&TEXT(Control!$B$4-11,"00") -> Week 29 | F4: ="Week "&TEXT(Control!$B$4-10,"00") -> Week 30 | G4: ="Week "&TEXT(Control!$B$4-9,"00") -> Week 31 | H4: Delta w/w | I4: Delta % | J4: Budget | K4: vs Budget
C5: Loans | D5: =ROUND(SUMIFS(Data!$C:$C,Data!$A:$A,Control!$B$2,Data!$B:$B,Control!$B$4-12)*Control!$B$5,1) -> 1867.6 | E5: =ROUND(SUMIFS(Data!$C:$C,Data!$A:$A,Control!$B$2,Data!$B:$B,Control!$B$4-11)*Control!$B$5,1) -> 1784.6 | F5: =ROUND(SUMIFS(Data!$C:$C,Data!$A:$A,Control!$B$2,Data!$B:$B,Control!$B$4-10)*Control!$B$5,1) -> 1808.8 | G5: =ROUND(SUMIFS(Data!$C:$C,Data!$A:$A,Control!$B$2,Data!$B:$B,Control!$B$4-9)*Control!$B$5,1) -> 1857.7 | H5: =G5-F5 -> 48.9 | I5: =IFERROR(H5/F5,0) -> 0.027034498 | J5: =ROUND(SUMIFS(Data!$E:$E,Data!$A:$A,Control!$B$2,Data!$B:$B,Control!$B$4-9)*Control!$B$5,1) -> 1853.8 | K5: =IF(ABS(G5-J5)<0.05,0,G5-J5) -> 3.9
C6: Deposits | D6: =ROUND(SUMIFS(Data!$D:$D,Data!$A:$A,Control!$B$2,Data!$B:$B,Control!$B$4-12)*Control!$B$5,1) -> 2115.4 | E6: =ROUND(SUMIFS(Data!$D:$D,Data!$A:$A,Control!$B$2,Data!$B:$B,Control!$B$4-11)*Control!$B$5,1) -> 2099.5 | F6: =ROUND(SUMIFS(Data!$D:$D,Data!$A:$A,Control!$B$2,Data!$B:$B,Control!$B$4-10)*Control!$B$5,1) -> 2094.6 | G6: =ROUND(SUMIFS(Data!$D:$D,Data!$A:$A,Control!$B$2,Data!$B:$B,Control!$B$4-9)*Control!$B$5,1) -> 2086.3 | H6: =G6-F6 -> -8.3 | I6: =IFERROR(H6/F6,0) -> -0.0039625704 | J6: =ROUND(SUMIFS(Data!$F:$F,Data!$A:$A,Control!$B$2,Data!$B:$B,Control!$B$4-9)*Control!$B$5,1) -> 2164 | K6: =IF(ABS(G6-J6)<0.05,0,G6-J6) -> -77.7
C7: Total | D7: =SUM(D5:D6) -> 3983 | E7: =SUM(E5:E6) -> 3884.1 | F7: =SUM(F5:F6) -> 3903.4 | G7: =SUM(G5:G6) -> 3944 | H7: =SUM(H5:H6) -> 40.6 | I7: =IFERROR(H7/F7,0) -> 0.010401189 | J7: =SUM(J5:J6) -> 4017.8 | K7: =SUM(K5:K6) -> -73.8
C8: L/D ratio | D8: =IF(D6=0,"n/a",D5/D6) -> 0.88285903 | E8: =IF(E6=0,"n/a",E5/E6) -> 0.85001191 | F8: =IF(F6=0,"n/a",F5/F6) -> 0.8635539 | G8: =IF(G6=0,"n/a",G5/G6) -> 0.89042803
C9: Average 4w | D9: =AVERAGE(D7:G7) -> 3928.625 | E9: =MAX(D7:G7) -> 3983 | F9: =MIN(D7:G7) -> 3884.1 | G9: =COUNTIF(H5:H6,">0") -> 1
C10: ="vs SLIDE_9" -> vs SLIDE_9 | D10: =G7-SLIDE_9!G7 -> -13.3 | E10: =IFERROR(D10/SLIDE_9!G7,0) -> -0.0033608774 | F10: =IF(AND(D10>0,SLIDE_9!H7>0),"up",IF(OR(D10<0,SLIDE_9!H7<0),"down","flat")) -> down | G10: =INDEX(SLIDE_9!D5:G6,2,MATCH(MAX(SLIDE_9!D6:G6),SLIDE_9!D6:G6,0)) -> 2149.7
C11: Rank | D11: =RANK(G5,Data!$C$2:$C$521) -> #N/A | E11: =SUMPRODUCT((Data!$B$2:$B$521=Control!$B$4)*(Data!$C$2:$C$521>G5))+1 -> 10 | F11: =VLOOKUP(Control!$B$2,Data!$H$2:$H$11,1,FALSE) -> Bank A | G11: =LEFT(Control!$B$2,4)&MID(Control!$B$2,6,1)&LEN(Control!$B$2) -> BankA6
C12: Misc | D12: =CHOOSE(MOD(Control!$B$3,3)+1,"one","two","three") -> two | E12: =TEXT(Control!$B$8,"mmm yy") -> ott yy | F12: =OFFSET(D5,1,2) -> 2094.6 | G12: =INDIRECT("D7") -> 3983 | H12: =AVERAGEIF(Data!$A$2:$A$521,Control!$B$2,Data!$C$2:$C$521) -> 1655.3948 | I12: =DATE(2026,1,5)+7*(Control!$B$4-1) -> 46300 | J12: =CONCATENATE(Control!$B$6," EUR") -> mln EUR | K12: =ROUNDUP(G7/1000,0)*1000 -> 4000
C13: Today | D13: =TODAY() -> 46311 | E13: =IF(ISNUMBER(G5),"ok","missing") -> ok | F13: =LARGE(Data!$C$2:$C$521,3) -> 9376.065 | G13: =SMALL(D5:G6,2) -> 1808.8 | H13: =_xlfn.XLOOKUP(Control!$B$2,Data!$H$2:$H$11,Data!$H$2:$H$11,"none") -> Bank A | I13: {=_xlfn.IFS(G5>F5,"up",G5<F5,"down",TRUE,"flat")} -> up | J13: {=_xlfn.SWITCH(Control!$B$6,"mln",1000000,"k",1000,1)} -> 1000000 | K13: =_xlfn.LET(_xlpm.x,G7,_xlpm.y,J7,IF(_xlpm.y=0,0,_xlpm.x/_xlpm.y-1)) -> -0.018368261 | L13: =SUM(_xlfn._xlws.FILTER(Data!$C$2:$C$521,Data!$A$2:$A$521=Control!$B$2)) -> 86080.528

Sheet SLIDE_11
B2: x
C3: ="Loans & deposits - "&Control!$B$2 -> Loans & deposits - Bank A
C4: Item | D4: ="Week "&TEXT(Control!$B$4-13,"00") -> Week 27 | E4: ="Week "&TEXT(Control!$B$4-12,"00") -> Week 28 | F4: ="Week "&TEXT(Control!$B$4-11,"00") -> Week 29 | G4: ="Week "&TEXT(Control!$B$4-10,"00") -> Week 30 | H4: Delta w/w | I4: Delta % | J4: Budget | K4: vs Budget
C5: Loans | D5: =ROUND(SUMIFS(Data!$C:$C,Data!$A:$A,Control!$B$2,Data!$B:$B,Control!$B$4-13)*Control!$B$5,1) -> 1789.3 | E5: =ROUND(SUMIFS(Data!$C:$C,Data!$A:$A,Control!$B$2,Data!$B:$B,Control!$B$4-12)*Control!$B$5,1) -> 1867.6 | F5: =ROUND(SUMIFS(Data!$C:$C,Data!$A:$A,Control!$B$2,Data!$B:$B,Control!$B$4-11)*Control!$B$5,1) -> 1784.6 | G5: =ROUND(SUMIFS(Data!$C:$C,Data!$A:$A,Control!$B$2,Data!$B:$B,Control!$B$4-10)*Control!$B$5,1) -> 1808.8 | H5: =G5-F5 -> 24.2 | I5: =IFERROR(H5/F5,0) -> 0.013560462 | J5: =ROUND(SUMIFS(Data!$E:$E,Data!$A:$A,Control!$B$2,Data!$B:$B,Control!$B$4-10)*Control!$B$5,1) -> 1846.2 | K5: =IF(ABS(G5-J5)<0.05,0,G5-J5) -> -37.4
C6: Deposits | D6: =ROUND(SUMIFS(Data!$D:$D,Data!$A:$A,Control!$B$2,Data!$B:$B,Control!$B$4-13)*Control!$B$5,1) -> 2110.6 | E6: =ROUND(SUMIFS(Data!$D:$D,Data!$A:$A,Control!$B$2,Data!$B:$B,Control!$B$4-12)*Control!$B$5,1) -> 2115.4 | F6: =ROUND(SUMIFS(Data!$D:$D,Data!$A:$A,Control!$B$2,Data!$B:$B,Control!$B$4-11)*Control!$B$5,1) -> 2099.5 | G6: =ROUND(SUMIFS(Data!$D:$D,Data!$A:$A,Control!$B$2,Data!$B:$B,Control!$B$4-10)*Control!$B$5,1) -> 2094.6 | H6: =G6-F6 -> -4.9 | I6: =IFERROR(H6/F6,0) -> -0.002333889 | J6: =ROUND(SUMIFS(Data!$F:$F,Data!$A:$A,Control!$B$2,Data!$B:$B,Control!$B$4-10)*Control!$B$5,1) -> 2157.5 | K6: =IF(ABS(G6-J6)<0.05,0,G6-J6) -> -62.9
C7: Total | D7: =SUM(D5:D6) -> 3899.9 | E7: =SUM(E5:E6) -> 3983 | F7: =SUM(F5:F6) -> 3884.1 | G7: =SUM(G5:G6) -> 3903.4 | H7: =SUM(H5:H6) -> 19.3 | I7: =IFERROR(H7/F7,0) -> 0.0049689761 | J7: =SUM(J5:J6) -> 4003.7 | K7: =SUM(K5:K6) -> -100.3
C8: L/D ratio | D8: =IF(D6=0,"n/a",D5/D6) -> 0.84776841 | E8: =IF(E6=0,"n/a",E5/E6) -> 0.88285903 | F8: =IF(F6=0,"n/a",F5/F6) -> 0.85001191 | G8: =IF(G6=0,"n/a",G5/G6) -> 0.8635539
C9: Average 4w | D9: =AVERAGE(D7:G7) -> 3917.6 | E9: =MAX(D7:G7) -> 3983 | F9: =MIN(D7:G7) -> 3884.1 | G9: =COUNTIF(H5:H6,">0") -> 1
C10: ="vs SLIDE_10" -> vs SLIDE_10 | D10: =G7-SLIDE_10!G7 -> -40.6 | E10: =IFERROR(D10/SLIDE_10!G7,0) -> -0.010294118 | F10: =IF(AND(D10>0,SLIDE_10!H7>0),"up",IF(OR(D10<0,SLIDE_10!H7<0),"down","flat")) -> down | G10: =INDEX(SLIDE_10!D5:G6,2,MATCH(MAX(SLIDE_10!D6:G6),SLIDE_10!D6:G6,0)) -> 2115.4
C11: Rank | D11: =RANK(G5,Data!$C$2:$C$521) -> #N/A | E11: =SUMPRODUCT((Data!$B$2:$B$521=Control!$B$4)*(Data!$C$2:$C$521>G5))+1 -> 10 | F11: =VLOOKUP(Control!$B$2,Data!$H$2:$H$11,1,FALSE) -> Bank A | G11: =LEFT(Control!$B$2,4)&MID(Control!$B$2,6,1)&LEN(Control!$B$2) -> BankA6
C12: Misc | D12: =CHOOSE(MOD(Control!$B$3,3)+1,"one","two","three") -> two | E12: =TEXT(Control!$B$8,"mmm yy") -> ott yy | F12: =OFFSET(D5,1,2) -> 2099.5 | G12: =INDIRECT("D7") -> 3899.9 | H12: =AVERAGEIF(Data!$A$2:$A$521,Control!$B$2,Data!$C$2:$C$521) -> 1655.3948 | I12: =DATE(2026,1,5)+7*(Control!$B$4-1) -> 46300 | J12: =CONCATENATE(Control!$B$6," EUR") -> mln EUR | K12: =ROUNDUP(G7/1000,0)*1000 -> 4000
C13: Today | D13: =TODAY() -> 46311 | E13: =IF(ISNUMBER(G5),"ok","missing") -> ok | F13: =LARGE(Data!$C$2:$C$521,3) -> 9376.065 | G13: =SMALL(D5:G6,2) -> 1789.3 | H13: =_xlfn.XLOOKUP(Control!$B$2,Data!$H$2:$H$11,Data!$H$2:$H$11,"none") -> Bank A | I13: {=_xlfn.IFS(G5>F5,"up",G5<F5,"down",TRUE,"flat")} -> up | J13: {=_xlfn.SWITCH(Control!$B$6,"mln",1000000,"k",1000,1)} -> 1000000 | K13: =_xlfn.LET(_xlpm.x,G7,_xlpm.y,J7,IF(_xlpm.y=0,0,_xlpm.x/_xlpm.y-1)) -> -0.025051827 | L13: =SUM(_xlfn._xlws.FILTER(Data!$C$2:$C$521,Data!$A$2:$A$521=Control!$B$2)) -> 86080.528

Sheet SLIDE_12
B2: x
C3: ="Loans & deposits - "&Control!$B$2 -> Loans & deposits - Bank A
C4: Item | D4: ="Week "&TEXT(Control!$B$4-14,"00") -> Week 26 | E4: ="Week "&TEXT(Control!$B$4-13,"00") -> Week 27 | F4: ="Week "&TEXT(Control!$B$4-12,"00") -> Week 28 | G4: ="Week "&TEXT(Control!$B$4-11,"00") -> Week 29 | H4: Delta w/w | I4: Delta % | J4: Budget | K4: vs Budget
C5: Loans | D5: =ROUND(SUMIFS(Data!$C:$C,Data!$A:$A,Control!$B$2,Data!$B:$B,Control!$B$4-14)*Control!$B$5,1) -> 1731.9 | E5: =ROUND(SUMIFS(Data!$C:$C,Data!$A:$A,Control!$B$2,Data!$B:$B,Control!$B$4-13)*Control!$B$5,1) -> 1789.3 | F5: =ROUND(SUMIFS(Data!$C:$C,Data!$A:$A,Control!$B$2,Data!$B:$B,Control!$B$4-12)*Control!$B$5,1) -> 1867.6 | G5: =ROUND(SUMIFS(Data!$C:$C,Data!$A:$A,Control!$B$2,Data!$B:$B,Control!$B$4-11)*Control!$B$5,1) -> 1784.6 | H5: =G5-F5 -> -83 | I5: =IFERROR(H5/F5,0) -> -0.044442065 | J5: =ROUND(SUMIFS(Data!$E:$E,Data!$A:$A,Control!$B$2,Data!$B:$B,Control!$B$4-11)*Control!$B$5,1) -> 1839.7 | K5: =IF(ABS(G5-J5)<0.05,0,G5-J5) -> -55.1
C6: Deposits | D6: =ROUND(SUMIFS(Data!$D:$D,Data!$A:$A,Control!$B$2,Data!$B:$B,Control!$B$4-14)*Control!$B$5,1) -> 2062.4 | E6: =ROUND(SUMIFS(Data!$D:$D,Data!$A:$A,Control!$B$2,Data!$B:$B,Control!$B$4-13)*Control!$B$5,1) -> 2110.6 | F6: =ROUND(SUMIFS(Data!$D:$D,Data!$A:$A,Control!$B$2,Data!$B:$B,Control!$B$4-12)*Control!$B$5,1) -> 2115.4 | G6: =ROUND(SUMIFS(Data!$D:$D,Data!$A:$A,Control!$B$2,Data!$B:$B,Control!$B$4-11)*Control!$B$5,1) -> 2099.5 | H6: =G6-F6 -> -15.9 | I6: =IFERROR(H6/F6,0) -> -0.007516309 | J6: =ROUND(SUMIFS(Data!$F:$F,Data!$A:$A,Control!$B$2,Data!$B:$B,Control!$B$4-11)*Control!$B$5,1) -> 2151 | K6: =IF(ABS(G6-J6)<0.05,0,G6-J6) -> -51.5
C7: Total | D7: =SUM(D5:D6) -> 3794.3 | E7: =SUM(E5:E6) -> 3899.9 | F7: =SUM(F5:F6) -> 3983 | G7: =SUM(G5:G6) -> 3884.1 | H7: =SUM(H5:H6) -> -98.9 | I7: =IFERROR(H7/F7,0) -> -0.02483053 | J7: =SUM(J5:J6) -> 3990.7 | K7: =SUM(K5:K6) -> -106.6
C8: L/D ratio | D8: =IF(D6=0,"n/a",D5/D6) -> 0.83974981 | E8: =IF(E6=0,"n/a",E5/E6) -> 0.84776841 | F8: =IF(F6=0,"n/a",F5/F6) -> 0.88285903 | G8: =IF(G6=0,"n/a",G5/G6) -> 0.85001191
C9: Average 4w | D9: =AVERAGE(D7:G7) -> 3890.325 | E9: =MAX(D7:G7) -> 3983 | F9: =MIN(D7:G7) -> 3794.3 | G9: =COUNTIF(H5:H6,">0") -> 0
C10: ="vs SLIDE_11" -> vs SLIDE_11 | D10: =G7-SLIDE_11!G7 -> -19.3 | E10: =IFERROR(D10/SLIDE_11!G7,0) -> -0.0049444074 | F10: =IF(AND(D10>0,SLIDE_11!H7>0),"up",IF(OR(D10<0,SLIDE_11!H7<0),"down","flat")) -> down | G10: =INDEX(SLIDE_11!D5:G6,2,MATCH(MAX(SLIDE_11!D6:G6),SLIDE_11!D6:G6,0)) -> 2115.4
C11: Rank | D11: =RANK(G5,Data!$C$2:$C$521) -> #N/A | E11: =SUMPRODUCT((Data!$B$2:$B$521=Control!$B$4)*(Data!$C$2:$C$521>G5))+1 -> 10 | F11: =VLOOKUP(Control!$B$2,Data!$H$2:$H$11,1,FALSE) -> Bank A | G11: =LEFT(Control!$B$2,4)&MID(Control!$B$2,6,1)&LEN(Control!$B$2) -> BankA6
C12: Misc | D12: =CHOOSE(MOD(Control!$B$3,3)+1,"one","two","three") -> two | E12: =TEXT(Control!$B$8,"mmm yy") -> ott yy | F12: =OFFSET(D5,1,2) -> 2115.4 | G12: =INDIRECT("D7") -> 3794.3 | H12: =AVERAGEIF(Data!$A$2:$A$521,Control!$B$2,Data!$C$2:$C$521) -> 1655.3948 | I12: =DATE(2026,1,5)+7*(Control!$B$4-1) -> 46300 | J12: =CONCATENATE(Control!$B$6," EUR") -> mln EUR | K12: =ROUNDUP(G7/1000,0)*1000 -> 4000
C13: Today | D13: =TODAY() -> 46311 | E13: =IF(ISNUMBER(G5),"ok","missing") -> ok | F13: =LARGE(Data!$C$2:$C$521,3) -> 9376.065 | G13: =SMALL(D5:G6,2) -> 1784.6 | H13: =_xlfn.XLOOKUP(Control!$B$2,Data!$H$2:$H$11,Data!$H$2:$H$11,"none") -> Bank A | I13: {=_xlfn.IFS(G5>F5,"up",G5<F5,"down",TRUE,"flat")} -> down | J13: {=_xlfn.SWITCH(Control!$B$6,"mln",1000000,"k",1000,1)} -> 1000000 | K13: =_xlfn.LET(_xlpm.x,G7,_xlpm.y,J7,IF(_xlpm.y=0,0,_xlpm.x/_xlpm.y-1)) -> -0.026712106 | L13: =SUM(_xlfn._xlws.FILTER(Data!$C$2:$C$521,Data!$A$2:$A$521=Control!$B$2)) -> 86080.528

Sheet SLIDE_13
B2: x
C3: ="Loans & deposits - "&Control!$B$2 -> Loans & deposits - Bank A
C4: Item | D4: ="Week "&TEXT(Control!$B$4-15,"00") -> Week 25 | E4: ="Week "&TEXT(Control!$B$4-14,"00") -> Week 26 | F4: ="Week "&TEXT(Control!$B$4-13,"00") -> Week 27 | G4: ="Week "&TEXT(Control!$B$4-12,"00") -> Week 28 | H4: Delta w/w | I4: Delta % | J4: Budget | K4: vs Budget
C5: Loans | D5: =ROUND(SUMIFS(Data!$C:$C,Data!$A:$A,Control!$B$2,Data!$B:$B,Control!$B$4-15)*Control!$B$5,1) -> 1762.5 | E5: =ROUND(SUMIFS(Data!$C:$C,Data!$A:$A,Control!$B$2,Data!$B:$B,Control!$B$4-14)*Control!$B$5,1) -> 1731.9 | F5: =ROUND(SUMIFS(Data!$C:$C,Data!$A:$A,Control!$B$2,Data!$B:$B,Control!$B$4-13)*Control!$B$5,1) -> 1789.3 | G5: =ROUND(SUMIFS(Data!$C:$C,Data!$A:$A,Control!$B$2,Data!$B:$B,Control!$B$4-12)*Control!$B$5,1) -> 1867.6 | H5: =G5-F5 -> 78.3 | I5: =IFERROR(H5/F5,0) -> 0.04376013 | J5: =ROUND(SUMIFS(Data!$E:$E,Data!$A:$A,Control!$B$2,Data!$B:$B,Control!$B$4-12)*Control!$B$5,1) -> 1832.1 | K5: =IF(ABS(G5-J5)<0.05,0,G5-J5) -> 35.5
C6: Deposits | D6: =ROUND(SUMIFS(Data!$D:$D,Data!$A:$A,Control!$B$2,Data!$B:$B,Control!$B$4-15)*Control!$B$5,1) -> 2128.2 | E6: =ROUND(SUMIFS(Data!$D:$D,Data!$A:$A,Control!$B$2,Data!$B:$B,Control!$B$4-14)*Control!$B$5,1) -> 2062.4 | F6: =ROUND(SUMIFS(Data!$D:$D,Data!$A:$A,Control!$B$2,Data!$B:$B,Control!$B$4-13)*Control!$B$5,1) -> 2110.6 | G6: =ROUND(SUMIFS(Data!$D:$D,Data!$A:$A,Control!$B$2,Data!$B:$B,Control!$B$4-12)*Control!$B$5,1) -> 2115.4 | H6: =G6-F6 -> 4.8 | I6: =IFERROR(H6/F6,0) -> 0.0022742348 | J6: =ROUND(SUMIFS(Data!$F:$F,Data!$A:$A,Control!$B$2,Data!$B:$B,Control!$B$4-12)*Control!$B$5,1) -> 2143.4 | K6: =IF(ABS(G6-J6)<0.05,0,G6-J6) -> -28
C7: Total | D7: =SUM(D5:D6) -> 3890.7 | E7: =SUM(E5:E6) -> 3794.3 | F7: =SUM(F5:F6) -> 3899.9 | G7: =SUM(G5:G6) -> 3983 | H7: =SUM(H5:H6) -> 83.1 | I7: =IFERROR(H7/F7,0) -> 0.021308239 | J7: =SUM(J5:J6) -> 3975.5 | K7: =SUM(K5:K6) -> 7.5
C8: L/D ratio | D8: =IF(D6=0,"n/a",D5/D6) -> 0.82816465 | E8: =IF(E6=0,"n/a",E5/E6) -> 0.83974981 | F8: =IF(F6=0,"n/a",F5/F6) -> 0.84776841 | G8: =IF(G6=0,"n/a",G5/G6) -> 0.88285903
C9: Average 4w | D9: =AVERAGE(D7:G7) -> 3891.975 | E9: =MAX(D7:G7) -> 3983 | F9: =MIN(D7:G7) -> 3794.3 | G9: =COUNTIF(H5:H6,">0") -> 2
C10: ="vs SLIDE_12" -> vs SLIDE_12 | D10: =G7-SLIDE_12!G7 -> 98.9 | E10: =IFERROR(D10/SLIDE_12!G7,0) -> 0.025462784 | F10: =IF(AND(D10>0,SLIDE_12!H7>0),"up",IF(OR(D10<0,SLIDE_12!H7<0),"down","flat")) -> down | G10: =INDEX(SLIDE_12!D5:G6,2,MATCH(MAX(SLIDE_12!D6:G6),SLIDE_12!D6:G6,0)) -> 2115.4
C11: Rank | D11: =RANK(G5,Data!$C$2:$C$521) -> #N/A | E11: =SUMPRODUCT((Data!$B$2:$B$521=Control!$B$4)*(Data!$C$2:$C$521>G5))+1 -> 10 | F11: =VLOOKUP(Control!$B$2,Data!$H$2:$H$11,1,FALSE) -> Bank A | G11: =LEFT(Control!$B$2,4)&MID(Control!$B$2,6,1)&LEN(Control!$B$2) -> BankA6
C12: Misc | D12: =CHOOSE(MOD(Control!$B$3,3)+1,"one","two","three") -> two | E12: =TEXT(Control!$B$8,"mmm yy") -> ott yy | F12: =OFFSET(D5,1,2) -> 2110.6 | G12: =INDIRECT("D7") -> 3890.7 | H12: =AVERAGEIF(Data!$A$2:$A$521,Control!$B$2,Data!$C$2:$C$521) -> 1655.3948 | I12: =DATE(2026,1,5)+7*(Control!$B$4-1) -> 46300 | J12: =CONCATENATE(Control!$B$6," EUR") -> mln EUR | K12: =ROUNDUP(G7/1000,0)*1000 -> 4000
C13: Today | D13: =TODAY() -> 46311 | E13: =IF(ISNUMBER(G5),"ok","missing") -> ok | F13: =LARGE(Data!$C$2:$C$521,3) -> 9376.065 | G13: =SMALL(D5:G6,2) -> 1762.5 | H13: =_xlfn.XLOOKUP(Control!$B$2,Data!$H$2:$H$11,Data!$H$2:$H$11,"none") -> Bank A | I13: {=_xlfn.IFS(G5>F5,"up",G5<F5,"down",TRUE,"flat")} -> up | J13: {=_xlfn.SWITCH(Control!$B$6,"mln",1000000,"k",1000,1)} -> 1000000 | K13: =_xlfn.LET(_xlpm.x,G7,_xlpm.y,J7,IF(_xlpm.y=0,0,_xlpm.x/_xlpm.y-1)) -> 0.0018865552 | L13: =SUM(_xlfn._xlws.FILTER(Data!$C$2:$C$521,Data!$A$2:$A$521=Control!$B$2)) -> 86080.528

Sheet SLIDE_14
B2: x
C3: ="Loans & deposits - "&Control!$B$2 -> Loans & deposits - Bank A
C4: Item | D4: ="Week "&TEXT(Control!$B$4-16,"00") -> Week 24 | E4: ="Week "&TEXT(Control!$B$4-15,"00") -> Week 25 | F4: ="Week "&TEXT(Control!$B$4-14,"00") -> Week 26 | G4: ="Week "&TEXT(Control!$B$4-13,"00") -> Week 27 | H4: Delta w/w | I4: Delta % | J4: Budget | K4: vs Budget
C5: Loans | D5: =ROUND(SUMIFS(Data!$C:$C,Data!$A:$A,Control!$B$2,Data!$B:$B,Control!$B$4-16)*Control!$B$5,1) -> 1803.3 | E5: =ROUND(SUMIFS(Data!$C:$C,Data!$A:$A,Control!$B$2,Data!$B:$B,Control!$B$4-15)*Control!$B$5,1) -> 1762.5 | F5: =ROUND(SUMIFS(Data!$C:$C,Data!$A:$A,Control!$B$2,Data!$B:$B,Control!$B$4-14)*Control!$B$5,1) -> 1731.9 | G5: =ROUND(SUMIFS(Data!$C:$C,Data!$A:$A,Control!$B$2,Data!$B:$B,Control!$B$4-13)*Control!$B$5,1) -> 1789.3 | H5: =G5-F5 -> 57.4 | I5: =IFERROR(H5/F5,0) -> 0.033142791 | J5: =ROUND(SUMIFS(Data!$E:$E,Data!$A:$A,Control!$B$2,Data!$B:$B,Control!$B$4-13)*Control!$B$5,1) -> 1824.5 | K5: =IF(ABS(G5-J5)<0.05,0,G5-J5) -> -35.2
C6: Deposits | D6: =ROUND(SUMIFS(Data!$D:$D,Data!$A:$A,Control!$B$2,Data!$B:$B,Control!$B$4-16)*Control!$B$5,1) -> 2111.5 | E6: =ROUND(SUMIFS(Data!$D:$D,Data!$A:$A,Control!$B$2,Data!$B:$B,Control!$B$4-15)*Control!$B$5,1) -> 2128.2 | F6: =ROUND(SUMIFS(Data!$D:$D,Data!$A:$A,Control!$B$2,Data!$B:$B,Control!$B$4-14)*Control!$B$5,1) -> 2062.4 | G6: =ROUND(SUMIFS(Data!$D:$D,Data!$A:$A,Control!$B$2,Data!$B:$B,Control!$B$4-13)*Control!$B$5,1) -> 2110.6 | H6: =G6-F6 -> 48.2 | I6: =IFERROR(H6/F6,0) -> 0.02337083 | J6: =ROUND(SUMIFS(Data!$F:$F,Data!$A:$A,Control!$B$2,Data!$B:$B,Control!$B$4-13)*Control!$B$5,1) -> 2136.9 | K6: =IF(ABS(G6-J6)<0.05,0,G6-J6) -> -26.3
C7: Total | D7: =SUM(D5:D6) -> 3914.8 | E7: =SUM(E5:E6) -> 3890.7 | F7: =SUM(F5:F6) -> 3794.3 | G7: =SUM(G5:G6) -> 3899.9 | H7: =SUM(H5:H6) -> 105.6 | I7: =IFERROR(H7/F7,0) -> 0.027831221 | J7: =SUM(J5:J6) -> 3961.4 | K7: =SUM(K5:K6) -> -61.5
C8: L/D ratio | D8: =IF(D6=0,"n/a",D5/D6) -> 0.85403741 | E8: =IF(E6=0,"n/a",E5/E6) -> 0.82816465 | F8: =IF(F6=0,"n/a",F5/F6) -> 0.83974981 | G8: =IF(G6=0,"n/a",G5/G6) -> 0.84776841
C9: Average 4w | D9: =AVERAGE(D7:G7) -> 3874.925 | E9: =MAX(D7:G7) -> 3914.8 | F9: =MIN(D7:G7) -> 3794.3 | G9: =COUNTIF(H5:H6,">0") -> 2
C10: ="vs SLIDE_13" -> vs SLIDE_13 | D10: =G7-SLIDE_13!G7 -> -83.1 | E10: =IFERROR(D10/SLIDE_13!G7,0) -> -0.020863671 | F10: =IF(AND(D10>0,SLIDE_13!H7>0),"up",IF(OR(D10<0,SLIDE_13!H7<0),"down","flat")) -> down | G10: =INDEX(SLIDE_13!D5:G6,2,MATCH(MAX(SLIDE_13!D6:G6),SLIDE_13!D6:G6,0)) -> 2128.2
C11: Rank | D11: =RANK(G5,Data!$C$2:$C$521) -> #N/A | E11: =SUMPRODUCT((Data!$B$2:$B$521=Control!$B$4)*(Data!$C$2:$C$521>G5))+1 -> 10 | F11: =VLOOKUP(Control!$B$2,Data!$H$2:$H$11,1,FALSE) -> Bank A | G11: =LEFT(Control!$B$2,4)&MID(Control!$B$2,6,1)&LEN(Control!$B$2) -> BankA6
C12: Misc | D12: =CHOOSE(MOD(Control!$B$3,3)+1,"one","two","three") -> two | E12: =TEXT(Control!$B$8,"mmm yy") -> ott yy | F12: =OFFSET(D5,1,2) -> 2062.4 | G12: =INDIRECT("D7") -> 3914.8 | H12: =AVERAGEIF(Data!$A$2:$A$521,Control!$B$2,Data!$C$2:$C$521) -> 1655.3948 | I12: =DATE(2026,1,5)+7*(Control!$B$4-1) -> 46300 | J12: =CONCATENATE(Control!$B$6," EUR") -> mln EUR | K12: =ROUNDUP(G7/1000,0)*1000 -> 4000
C13: Today | D13: =TODAY() -> 46311 | E13: =IF(ISNUMBER(G5),"ok","missing") -> ok | F13: =LARGE(Data!$C$2:$C$521,3) -> 9376.065 | G13: =SMALL(D5:G6,2) -> 1762.5 | H13: =_xlfn.XLOOKUP(Control!$B$2,Data!$H$2:$H$11,Data!$H$2:$H$11,"none") -> Bank A | I13: {=_xlfn.IFS(G5>F5,"up",G5<F5,"down",TRUE,"flat")} -> up | J13: {=_xlfn.SWITCH(Control!$B$6,"mln",1000000,"k",1000,1)} -> 1000000 | K13: =_xlfn.LET(_xlpm.x,G7,_xlpm.y,J7,IF(_xlpm.y=0,0,_xlpm.x/_xlpm.y-1)) -> -0.015524814 | L13: =SUM(_xlfn._xlws.FILTER(Data!$C$2:$C$521,Data!$A$2:$A$521=Control!$B$2)) -> 86080.528

Sheet SLIDE_15
B2: x
C3: ="Loans & deposits - "&Control!$B$2 -> Loans & deposits - Bank A
C4: Item | D4: ="Week "&TEXT(Control!$B$4-17,"00") -> Week 23 | E4: ="Week "&TEXT(Control!$B$4-16,"00") -> Week 24 | F4: ="Week "&TEXT(Control!$B$4-15,"00") -> Week 25 | G4: ="Week "&TEXT(Control!$B$4-14,"00") -> Week 26 | H4: Delta w/w | I4: Delta % | J4: Budget | K4: vs Budget
C5: Loans | D5: =ROUND(SUMIFS(Data!$C:$C,Data!$A:$A,Control!$B$2,Data!$B:$B,Control!$B$4-17)*Control!$B$5,1) -> 1808.6 | E5: =ROUND(SUMIFS(Data!$C:$C,Data!$A:$A,Control!$B$2,Data!$B:$B,Control!$B$4-16)*Control!$B$5,1) -> 1803.3 | F5: =ROUND(SUMIFS(Data!$C:$C,Data!$A:$A,Control!$B$2,Data!$B:$B,Control!$B$4-15)*Control!$B$5,1) -> 1762.5 | G5: =ROUND(SUMIFS(Data!$C:$C,Data!$A:$A,Control!$B$2,Data!$B:$B,Control!$B$4-14)*Control!$B$5,1) -> 1731.9 | H5: =G5-F5 -> -30.6 | I5: =IFERROR(H5/F5,0) -> -0.017361702 | J5: =ROUND(SUMIFS(Data!$E:$E,Data!$A:$A,Control!$B$2,Data!$B:$B,Control!$B$4-14)*Control!$B$5,1) -> 1818 | K5: =IF(ABS(G5-J5)<0.05,0,G5-J5) -> -86.1
C6: Deposits | D6: =ROUND(SUMIFS(Data!$D:$D,Data!$A:$A,Control!$B$2,Data!$B:$B,Control!$B$4-17)*Control!$B$5,1) -> 2172.9 | E6: =ROUND(SUMIFS(Data!$D:$D,Data!$A:$A,Control!$B$2,Data!$B:$B,Control!$B$4-16)*Control!$B$5,1) -> 2111.5 | F6: =ROUND(SUMIFS(Data!$D:$D,Data!$A:$A,Control!$B$2,Data!$B:$B,Control!$B$4-15)*Control!$B$5,1) -> 2128.2 | G6: =ROUND(SUMIFS(Data!$D:$D,Data!$A:$A,Control!$B$2,Data!$B:$B,Control!$B$4-14)*Control!$B$5,1) -> 2062.4 | H6: =G6-F6 -> -65.8 | I6: =IFERROR(H6/F6,0) -> -0.030918147 | J6: =ROUND(SUMIFS(Data!$F:$F,Data!$A:$A,Control!$B$2,Data!$B:$B,Control!$B$4-14)*Control!$B$5,1) -> 2130.4 | K6: =IF(ABS(G6-J6)<0.05,0,G6-J6) -> -68
C7: Total | D7: =SUM(D5:D6) -> 3981.5 | E7: =SUM(E5:E6) -> 3914.8 | F7: =SUM(F5:F6) -> 3890.7 | G7: =SUM(G5:G6) -> 3794.3 | H7: =SUM(H5:H6) -> -96.4 | I7: =IFERROR(H7/F7,0) -> -0.024777032 | J7: =SUM(J5:J6) -> 3948.4 | K7: =SUM(K5:K6) -> -154.1
C8: L/D ratio | D8: =IF(D6=0,"n/a",D5/D6) -> 0.83234387 | E8: =IF(E6=0,"n/a",E5/E6) -> 0.85403741 | F8: =IF(F6=0,"n/a",F5/F6) -> 0.82816465 | G8: =IF(G6=0,"n/a",G5/G6) -> 0.83974981
C9: Average 4w | D9: =AVERAGE(D7:G7) -> 3895.325 | E9: =MAX(D7:G7) -> 3981.5 | F9: =MIN(D7:G7) -> 3794.3 | G9: =COUNTIF(H5:H6,">0") -> 0
C10: ="vs SLIDE_14" -> vs SLIDE_14 | D10: =G7-SLIDE_14!G7 -> -105.6 | E10: =IFERROR(D10/SLIDE_14!G7,0) -> -0.027077617 | F10: =IF(AND(D10>0,SLIDE_14!H7>0),"up",IF(OR(D10<0,SLIDE_14!H7<0),"down","flat")) -> down | G10: =INDEX(SLIDE_14!D5:G6,2,MATCH(MAX(SLIDE_14!D6:G6),SLIDE_14!D6:G6,0)) -> 2128.2
C11: Rank | D11: =RANK(G5,Data!$C$2:$C$521) -> #N/A | E11: =SUMPRODUCT((Data!$B$2:$B$521=Control!$B$4)*(Data!$C$2:$C$521>G5))+1 -> 10 | F11: =VLOOKUP(Control!$B$2,Data!$H$2:$H$11,1,FALSE) -> Bank A | G11: =LEFT(Control!$B$2,4)&MID(Control!$B$2,6,1)&LEN(Control!$B$2) -> BankA6
C12: Misc | D12: =CHOOSE(MOD(Control!$B$3,3)+1,"one","two","three") -> two | E12: =TEXT(Control!$B$8,"mmm yy") -> ott yy | F12: =OFFSET(D5,1,2) -> 2128.2 | G12: =INDIRECT("D7") -> 3981.5 | H12: =AVERAGEIF(Data!$A$2:$A$521,Control!$B$2,Data!$C$2:$C$521) -> 1655.3948 | I12: =DATE(2026,1,5)+7*(Control!$B$4-1) -> 46300 | J12: =CONCATENATE(Control!$B$6," EUR") -> mln EUR | K12: =ROUNDUP(G7/1000,0)*1000 -> 4000
C13: Today | D13: =TODAY() -> 46311 | E13: =IF(ISNUMBER(G5),"ok","missing") -> ok | F13: =LARGE(Data!$C$2:$C$521,3) -> 9376.065 | G13: =SMALL(D5:G6,2) -> 1762.5 | H13: =_xlfn.XLOOKUP(Control!$B$2,Data!$H$2:$H$11,Data!$H$2:$H$11,"none") -> Bank A | I13: {=_xlfn.IFS(G5>F5,"up",G5<F5,"down",TRUE,"flat")} -> down | J13: {=_xlfn.SWITCH(Control!$B$6,"mln",1000000,"k",1000,1)} -> 1000000 | K13: =_xlfn.LET(_xlpm.x,G7,_xlpm.y,J7,IF(_xlpm.y=0,0,_xlpm.x/_xlpm.y-1)) -> -0.039028467 | L13: =SUM(_xlfn._xlws.FILTER(Data!$C$2:$C$521,Data!$A$2:$A$521=Control!$B$2)) -> 86080.528

Sheet SLIDE_16
B2: x
C3: ="Loans & deposits - "&Control!$B$2 -> Loans & deposits - Bank A
C4: Item | D4: ="Week "&TEXT(Control!$B$4-18,"00") -> Week 22 | E4: ="Week "&TEXT(Control!$B$4-17,"00") -> Week 23 | F4: ="Week "&TEXT(Control!$B$4-16,"00") -> Week 24 | G4: ="Week "&TEXT(Control!$B$4-15,"00") -> Week 25 | H4: Delta w/w | I4: Delta % | J4: Budget | K4: vs Budget
