Workbook
Name BankList: Banks!$A$2:$A$21
Name BankRegion: Banks!$C$2:$C$21
Name D_Bank: Data!$A$2:$A$5761
Name D_Month: Data!$B$2:$B$5761
Name D_Vol: Data!$E$2:$E$5761
Name Rate: Control!$B$4
Name SelBank: Control!$B$2
Name SelMonth: Control!$B$3
Name SelRegion: Control!$B$5
Name TaxRate: 0.24
Name VolSel: SUMIFS(D_Vol,D_Bank,SelBank,D_Month,SelMonth)

Sheet Control
A1: Parametro
A2: Banca | B2: Banca Tirrena
A3: Mese (indice) | B3: 13
A4: Tasso scenario | B4: 0.03
A5: Regione | B5: Centro
A6: Indice banca | B6: =MATCH(B2,Banks!$A$2:$A$21,0) -> 3
A7: Codice | B7: =VLOOKUP(B2,Banks!$A$2:$H$21,2,FALSE) -> B103
A8: Regione banca | B8: =_xlfn.XLOOKUP(B2,Banks!$A$2:$A$21,Banks!$C$2:$C$21,"n.d.",0) -> Centro
A9: Data rif. | B9: =EOMONTH(DATE(2024,B3,1),0) -> 45688
A10: Etichetta | B10: =TEXT(B9,"mmmm aaaa") -> gennaio 2025
A11: Anno | B11: =YEAR(B9) -> 2025
A12: Mese anno | B12: =MONTH(B9) -> 1
A13: Mese prec. | B13: =MAX(1,B3-1) -> 12
A14: Anno prec. | B14: =MAX(1,B3-12) -> 1
A15: Cambio USD | B15: =_xlfn.XLOOKUP(B3,FX!$A$2:$A$37,FX!$C$2:$C$37) -> 1.0719
A16: Titolo | B16: =B2&" ("&B7&") - "&B10 -> Banca Tirrena (B103) - gennaio 2025
A17: Oggi | B17: =TODAY() -> 46312
A18: Gap peer | B18: =[1]Summary!$B$2 -> 0.057912768
A19: Totale regioni | B19: =[2]Summary!$B$2 -> 343560.2
A20: Trimestre | B20: =ROUNDUP(B12/3,0) -> 1
A21: Inizio trimestre | B21: =B3-MOD(B12-1,3) -> 13
A22: Primo mese anno | B22: =B3-B12+1 -> 13
A23: Responsabile | B23: {=TRIM(INDEX(Banks!$D$2:$D$21,B6))} -> Verdi
A24: Segmento | B24: {=INDEX(Banks!$E$2:$E$21,B6)} -> Grande
A25: Tasso mensile | B25: =(1+B4)^(1/12)-1 -> 0.0024662698

Sheet Data
A1: Banca | B1: Mese | C1: Prodotto | D1: Data | E1: Volumi | F1: Ricavi | G1: Costi | H1: Clienti | I1: Regione | J1: Anno | K1: Margine | L1: Chiave
A2: Banca Alpi | B2: 1 | C2: Mutui | D2: 45322 | E2: 346 | F2: 15.89 | G2: 10.09 | H2: 50 | I2: Nord-Ovest | J2: 2024 | K2: =F2-G2 -> 5.8 | L2: =A2&"|"&B2&"|"&C2 -> Banca Alpi|1|Mutui
A3: Banca Alpi | B3: 1 | C3: Prestiti | D3: 45322 | E3: 465.8 | F3: 22.55 | G3: 13.66 | H3: 65 | I3: Nord-Ovest | J3: 2024 | K3: =F3-G3 -> 8.89 | L3: =A3&"|"&B3&"|"&C3 -> Banca Alpi|1|Prestiti
A4: Banca Alpi | B4: 1 | C4: Conti | D4: 45322 | E4: 536.6 | F4: 26.52 | G4: 16.42 | H4: 90 | I4: Nord-Ovest | J4: 2024 | K4: =F4-G4 -> 10.1 | L4: =A4&"|"&B4&"|"&C4 -> Banca Alpi|1|Conti
A5: Banca Alpi | B5: 1 | C5: Carte | D5: 45322 | E5: 686.6 | F5: 35.92 | G5: 21.52 | H5: 68 | I5: Nord-Ovest | J5: 2024 | K5: =F5-G5 -> 14.4 | L5: =A5&"|"&B5&"|"&C5 -> Banca Alpi|1|Carte
A6: Banca Alpi | B6: 1 | C6: Leasing | D6: 45322 | E6: 780.2 | F6: 41.73 | G6: 25.8 | H6: 85 | I6: Nord-Ovest | J6: 2024 | K6: =F6-G6 -> 15.93 | L6: =A6&"|"&B6&"|"&C6 -> Banca Alpi|1|Leasing
A7: Banca Alpi | B7: 1 | C7: Factoring | D7: 45322 | E7: 923.8 | F7: 50.9 | G7: 31.24 | H7: 109 | I7: Nord-Ovest | J7: 2024 | K7: =F7-G7 -> 19.66 | L7: =A7&"|"&B7&"|"&C7 -> Banca Alpi|1|Factoring
A8: Banca Alpi | B8: 1 | C8: Risparmio | D8: 45322 | E8: 1059.9 | F8: 61.23 | G8: 36.35 | H8: 130 | I8: Nord-Ovest | J8: 2024 | K8: =F8-G8 -> 24.88 | L8: =A8&"|"&B8&"|"&C8 -> Banca Alpi|1|Risparmio
A9: Banca Alpi | B9: 1 | C9: Assicurazioni | D9: 45322 | E9: 1142.7 | F9: 67.94 | G9: 40.18 | H9: 147 | I9: Nord-Ovest | J9: 2024 | K9: =F9-G9 -> 27.76 | L9: =A9&"|"&B9&"|"&C9 -> Banca Alpi|1|Assicurazioni
A10: Banca Alpi | B10: 2 | C10: Mutui | D10: 45351 | E10: 301.3 | F10: 13.67 | G10: 8.45 | H10: 32 | I10: Nord-Ovest | J10: 2024 | K10: =F10-G10 -> 5.22 | L10: =A10&"|"&B10&"|"&C10 -> Banca Alpi|2|Mutui
A11: Banca Alpi | B11: 2 | C11: Prestiti | D11: 45351 | E11: 447.6 | F11: 21.46 | G11: 13.03 | H11: 47 | I11: Nord-Ovest | J11: 2024 | K11: =F11-G11 -> 8.43 | L11: =A11&"|"&B11&"|"&C11 -> Banca Alpi|2|Prestiti
A12: Banca Alpi | B12: 2 | C12: Conti | D12: 45351 | E12: 570.2 | F12: 28.2 | G12: 18.02 | H12: 88 | I12: Nord-Ovest | J12: 2024 | K12: =F12-G12 -> 10.18 | L12: =A12&"|"&B12&"|"&C12 -> Banca Alpi|2|Conti
A13: Banca Alpi | B13: 2 | C13: Carte | D13: 45351 | E13: 663.9 | F13: 34.35 | G13: 20.86 | H13: 68 | I13: Nord-Ovest | J13: 2024 | K13: =F13-G13 -> 13.49 | L13: =A13&"|"&B13&"|"&C13 -> Banca Alpi|2|Carte
... A5761: Banca Città | B5761: 36 | C5761: Assicurazioni | D5761: 46387 | E5761: 6339.9 | F5761: 374.28 | G5761: 222.35 | H5761: 493 | I5761: Centro | J5761: 2026 | K5761: =F5761-G5761 -> 151.93 | L5761: =A5761&"|"&B5761&"|"&C5761 -> Banca Città|36|Assicurazioni

Sheet Banks
A1: Banca | B1: Codice | C1: Regione | D1: Responsabile | E1: Segmento | F1: Fondazione | G1: Obiettivo | H1: Peso
A2: Banca Alpi | B2: B101 | C2: Nord-Ovest | D2: Rossi | E2: Grande | F2: 1850 | G2: 4480 | H2: 0.02
A3: Banca Adriatica | B3: B102 | C3: Nord-Est | D3: Bianchi Anna | E3: Media | F3: 1857 | G3: 5247 | H3: 0.023
A4: Banca Tirrena | B4: B103 | C4: Centro | D4: Verdi | E4: Grande | F4: 1864 | G4: 6014 | H4: 0.026
A5: Banca Padana | B5: B104 | C5: Nord-Ovest | D5: Ferrari | E5: Grande | F5: 1871 | G5: 6782 | H5: 0.029
A6: Banca Etrusca | B6: B105 | C6: Centro | D6: Russo | E6: Media | F6: 1878 | G6: 7549 | H6: 0.032
A7: Banca Lariana | B7: B106 | C7: Nord-Ovest | D7: Colombo Luca | E7: Piccola | F7: 1885 | G7: 8316 | H7: 0.035
A8: Banca Sabina | B8: B107 | C8: Centro | D8: Ricci | E8: Piccola | F8: 1892 | G8: 9083 | H8: 0.038
A9: Banca Irpina | B9: B108 | C9: Sud | D9: Marino | E9: Piccola | F9: 1899 | G9: 9850 | H9: 0.041
A10: Banca Sannita | B10: B109 | C10: Sud | D10: Greco | E10: Media | F10: 1906 | G10: 10618 | H10: 0.044
A11: Banca Ligure | B11: B110 | C11: Nord-Ovest | D11: Bruno | E11: Media | F11: 1913 | G11: 11385 | H11: 0.047
A12: Banca Veneta | B12: B111 | C12: Nord-Est | D12: Gallo | E12: Grande | F12: 1920 | G12: 12152 | H12: 0.05
A13: Banca Friulana | B13: B112 | C13: Nord-Est | D13: Conti | E13: Media | F13: 1927 | G13: 12919 | H13: 0.053
... A21: Banca Città | B21: B120 | C21: Centro | D21: Barbieri | E21: Grande | F21: 1983 | G21: 19057 | H21: 0.077

Sheet FX
A1: Mese | B1: Data | C1: USD | D1: GBP | E1: CHF
A2: 1 | B2: 45322 | C2: 1.058 | D2: 0.8597 | E2: 0.948
A3: 2 | B3: 45351 | C3: 1.0658 | D3: 0.8588 | E3: 0.946
A4: 3 | B4: 45382 | C4: 1.0729 | D4: 0.8573 | E4: 0.944
A5: 4 | B5: 45412 | C5: 1.0791 | D5: 0.8554 | E5: 0.942
A6: 5 | B6: 45443 | C6: 1.0842 | D6: 0.8532 | E6: 0.94
A7: 6 | B7: 45473 | C7: 1.0879 | D7: 0.8507 | E7: 0.938
A8: 7 | B8: 45504 | C8: 1.0901 | D8: 0.8482 | E8: 0.936
A9: 8 | B9: 45535 | C9: 1.0908 | D9: 0.8458 | E9: 0.934
A10: 9 | B10: 45565 | C10: 1.0899 | D10: 0.8437 | E10: 0.932
A11: 10 | B11: 45596 | C11: 1.0874 | D11: 0.842 | E11: 0.93
A12: 11 | B12: 45626 | C12: 1.0834 | D12: 0.8408 | E12: 0.928
A13: 12 | B13: 45657 | C13: 1.0782 | D13: 0.8401 | E13: 0.926
... A37: 36 | B37: 46387 | C37: 1.0853 | D37: 0.8409 | E37: 0.878
A40: Mese | B40: 1 | C40: 2 | D40: 3 | E40: 4 | F40: 5 | G40: 6 | H40: 7 | I40: 8 | J40: 9 | K40: 10 | L40: 11 | M40: 12 | N40: 13 | O40: 14 | P40: 15 | Q40: 16 | R40: 17 | S40: 18 | T40: 19 | U40: 20 | V40: 21 | W40: 22 | X40: 23 | Y40: 24 | Z40: 25 | AA40: 26 | AB40: 27 | AC40: 28 | AD40: 29 | AE40: 30 | AF40: 31 | AG40: 32 | AH40: 33 | AI40: 34 | AJ40: 35 | AK40: 36
A41: USD | B41: 1.058 | C41: 1.0658 | D41: 1.0729 | E41: 1.0791 | F41: 1.0842 | G41: 1.0879 | H41: 1.0901 | I41: 1.0908 | J41: 1.0899 | K41: 1.0874 | L41: 1.0834 | M41: 1.0782 | N41: 1.0719 | O41: 1.0648 | P41: 1.0571 | Q41: 1.0493 | R41: 1.0415 | S41: 1.0341 | T41: 1.0274 | U41: 1.0217 | V41: 1.0172 | W41: 1.0141 | X41: 1.0126 | Y41: 1.0126 | Z41: 1.0141 | AA41: 1.0173 | AB41: 1.0218 | AC41: 1.0275 | AD41: 1.0343 | AE41: 1.0418 | AF41: 1.0498 | AG41: 1.0579 | AH41: 1.0658 | AI41: 1.0732 | AJ41: 1.0798 | AK41: 1.0853
A42: GBP | B42: 0.8597 | C42: 0.8588 | D42: 0.8573 | E42: 0.8554 | F42: 0.8532 | G42: 0.8507 | H42: 0.8482 | I42: 0.8458 | J42: 0.8437 | K42: 0.842 | L42: 0.8408 | M42: 0.8401 | N42: 0.8401 | O42: 0.8406 | P42: 0.8418 | Q42: 0.8435 | R42: 0.8455 | S42: 0.8479 | T42: 0.8504 | U42: 0.8528 | V42: 0.8551 | W42: 0.8571 | X42: 0.8586 | Y42: 0.8596 | Z42: 0.86 | AA42: 0.8598 | AB42: 0.8589 | AC42: 0.8575 | AD42: 0.8557 | AE42: 0.8535 | AF42: 0.851 | AG42: 0.8485 | AH42: 0.8461 | AI42: 0.844 | AJ42: 0.8422 | AK42: 0.8409
A43: CHF | B43: 0.948 | C43: 0.946 | D43: 0.944 | E43: 0.942 | F43: 0.94 | G43: 0.938 | H43: 0.936 | I43: 0.934 | J43: 0.932 | K43: 0.93 | L43: 0.928 | M43: 0.926 | N43: 0.924 | O43: 0.922 | P43: 0.92 | Q43: 0.918 | R43: 0.916 | S43: 0.914 | T43: 0.912 | U43: 0.91 | V43: 0.908 | W43: 0.906 | X43: 0.904 | Y43: 0.902 | Z43: 0.9 | AA43: 0.898 | AB43: 0.896 | AC43: 0.894 | AD43: 0.892 | AE43: 0.89 | AF43: 0.888 | AG43: 0.886 | AH43: 0.884 | AI43: 0.882 | AJ43: 0.88 | AK43: 0.878

Sheet Budget
A1: Budget volumi | B1: 1 | C1: 2 | D1: 3 | E1: 4 | F1: 5 | G1: 6 | H1: 7 | I1: 8 | J1: 9 | K1: 10 | L1: 11 | M1: 12 | N1: 13 | O1: 14 | P1: 15 | Q1: 16 | R1: 17 | S1: 18 | T1: 19 | U1: 20 | V1: 21 | W1: 22 | X1: 23 | Y1: 24 | Z1: 25 | AA1: 26 | AB1: 27 | AC1: 28 | AD1: 29 | AE1: 30 | AF1: 31 | AG1: 32 | AH1: 33 | AI1: 34 | AJ1: 35 | AK1: 36
A2: Banca Alpi | B2: 5973 | C2: 6027 | D2: 6080 | E2: 6133 | F2: 6186 | G2: 6240 | H2: 6293 | I2: 6346 | J2: 6400 | K2: 6453 | L2: 6506 | M2: 6559 | N2: 6613 | O2: 6666 | P2: 6719 | Q2: 6772 | R2: 6826 | S2: 6879 | T2: 6932 | U2: 6986 | V2: 7039 | W2: 7092 | X2: 7145 | Y2: 7199 | Z2: 7252 | AA2: 7305 | AB2: 7359 | AC2: 7412 | AD2: 7465 | AE2: 7518 | AF2: 7572 | AG2: 7625 | AH2: 7678 | AI2: 7732 | AJ2: 7785 | AK2: 7838
A3: Banca Adriatica | B3: 6996 | C3: 7059 | D3: 7121 | E3: 7183 | F3: 7246 | G3: 7308 | H3: 7371 | I3: 7433 | J3: 7495 | K3: 7558 | L3: 7620 | M3: 7683 | N3: 7745 | O3: 7807 | P3: 7870 | Q3: 7932 | R3: 7995 | S3: 8057 | T3: 8119 | U3: 8182 | V3: 8244 | W3: 8307 | X3: 8369 | Y3: 8432 | Z3: 8494 | AA3: 8556 | AB3: 8619 | AC3: 8681 | AD3: 8744 | AE3: 8806 | AF3: 8868 | AG3: 8931 | AH3: 8993 | AI3: 9056 | AJ3: 9118 | AK3: 9180
A4: Banca Tirrena | B4: 8019 | C4: 8091 | D4: 8162 | E4: 8234 | F4: 8305 | G4: 8377 | H4: 8448 | I4: 8520 | J4: 8591 | K4: 8663 | L4: 8734 | M4: 8806 | N4: 8877 | O4: 8949 | P4: 9021 | Q4: 9092 | R4: 9164 | S4: 9235 | T4: 9307 | U4: 9378 | V4: 9450 | W4: 9521 | X4: 9593 | Y4: 9664 | Z4: 9736 | AA4: 9807 | AB4: 9879 | AC4: 9950 | AD4: 10022 | AE4: 10093 | AF4: 10165 | AG4: 10237 | AH4: 10308 | AI4: 10380 | AJ4: 10451 | AK4: 10523
A5: Banca Padana | B5: 9042 | C5: 9123 | D5: 9203 | E5: 9284 | F5: 9365 | G5: 9445 | H5: 9526 | I5: 9607 | J5: 9687 | K5: 9768 | L5: 9849 | M5: 9929 | N5: 10010 | O5: 10091 | P5: 10171 | Q5: 10252 | R5: 10332 | S5: 10413 | T5: 10494 | U5: 10574 | V5: 10655 | W5: 10736 | X5: 10816 | Y5: 10897 | Z5: 10978 | AA5: 11058 | AB5: 11139 | AC5: 11220 | AD5: 11300 | AE5: 11381 | AF5: 11462 | AG5: 11542 | AH5: 11623 | AI5: 11704 | AJ5: 11784 | AK5: 11865
A6: Banca Etrusca | B6: 10065 | C6: 10155 | D6: 10245 | E6: 10334 | F6: 10424 | G6: 10514 | H6: 10604 | I6: 10693 | J6: 10783 | K6: 10873 | L6: 10963 | M6: 11053 | N6: 11142 | O6: 11232 | P6: 11322 | Q6: 11412 | R6: 11501 | S6: 11591 | T6: 11681 | U6: 11771 | V6: 11861 | W6: 11950 | X6: 12040 | Y6: 12130 | Z6: 12220 | AA6: 12309 | AB6: 12399 | AC6: 12489 | AD6: 12579 | AE6: 12669 | AF6: 12758 | AG6: 12848 | AH6: 12938 | AI6: 13028 | AJ6: 13117 | AK6: 13207
A7: Banca Lariana | B7: 11088 | C7: 11187 | D7: 11286 | E7: 11385 | F7: 11484 | G7: 11582 | H7: 11681 | I7: 11780 | J7: 11879 | K7: 11978 | L7: 12077 | M7: 12176 | N7: 12275 | O7: 12374 | P7: 12473 | Q7: 12571 | R7: 12670 | S7: 12769 | T7: 12868 | U7: 12967 | V7: 13066 | W7: 13165 | X7: 13264 | Y7: 13363 | Z7: 13462 | AA7: 13560 | AB7: 13659 | AC7: 13758 | AD7: 13857 | AE7: 13956 | AF7: 14055 | AG7: 14154 | AH7: 14253 | AI7: 14352 | AJ7: 14451 | AK7: 14549
A8: Banca Sabina | B8: 12111 | C8: 12219 | D8: 12327 | E8: 12435 | F8: 12543 | G8: 12651 | H8: 12759 | I8: 12867 | J8: 12975 | K8: 13083 | L8: 13191 | M8: 13299 | N8: 13407 | O8: 13515 | P8: 13623 | Q8: 13731 | R8: 13839 | S8: 13947 | T8: 14055 | U8: 14163 | V8: 14271 | W8: 14379 | X8: 14487 | Y8: 14595 | Z8: 14703 | AA8: 14811 | AB8: 14919 | AC8: 15028 | AD8: 15136 | AE8: 15244 | AF8: 15352 | AG8: 15460 | AH8: 15568 | AI8: 15676 | AJ8: 15784 | AK8: 15892
A9: Banca Irpina | B9: 13134 | C9: 13251 | D9: 13368 | E9: 13485 | F9: 13602 | G9: 13719 | H9: 13837 | I9: 13954 | J9: 14071 | K9: 14188 | L9: 14305 | M9: 14422 | N9: 14540 | O9: 14657 | P9: 14774 | Q9: 14891 | R9: 15008 | S9: 15125 | T9: 15242 | U9: 15360 | V9: 15477 | W9: 15594 | X9: 15711 | Y9: 15828 | Z9: 15945 | AA9: 16062 | AB9: 16180 | AC9: 16297 | AD9: 16414 | AE9: 16531 | AF9: 16648 | AG9: 16765 | AH9: 16883 | AI9: 17000 | AJ9: 17117 | AK9: 17234
A10: Banca Sannita | B10: 14157 | C10: 14283 | D10: 14409 | E10: 14535 | F10: 14662 | G10: 14788 | H10: 14914 | I10: 15041 | J10: 15167 | K10: 15293 | L10: 15419 | M10: 15546 | N10: 15672 | O10: 15798 | P10: 15925 | Q10: 16051 | R10: 16177 | S10: 16303 | T10: 16430 | U10: 16556 | V10: 16682 | W10: 16808 | X10: 16935 | Y10: 17061 | Z10: 17187 | AA10: 17314 | AB10: 17440 | AC10: 17566 | AD10: 17692 | AE10: 17819 | AF10: 17945 | AG10: 18071 | AH10: 18197 | AI10: 18324 | AJ10: 18450 | AK10: 18576
A11: Banca Ligure | B11: 15180 | C11: 15315 | D11: 15450 | E11: 15586 | F11: 15721 | G11: 15857 | H11: 15992 | I11: 16127 | J11: 16263 | K11: 16398 | L11: 16534 | M11: 16669 | N11: 16804 | O11: 16940 | P11: 17075 | Q11: 17211 | R11: 17346 | S11: 17481 | T11: 17617 | U11: 17752 | V11: 17888 | W11: 18023 | X11: 18158 | Y11: 18294 | Z11: 18429 | AA11: 18565 | AB11: 18700 | AC11: 18835 | AD11: 18971 | AE11: 19106 | AF11: 19242 | AG11: 19377 | AH11: 19512 | AI11: 19648 | AJ11: 19783 | AK11: 19919
A12: Banca Veneta | B12: 16203 | C12: 16347 | D12: 16492 | E12: 16636 | F12: 16781 | G12: 16925 | H12: 17070 | I12: 17214 | J12: 17359 | K12: 17503 | L12: 17648 | M12: 17792 | N12: 17937 | O12: 18081 | P12: 18226 | Q12: 18370 | R12: 18515 | S12: 18659 | T12: 18804 | U12: 18948 | V12: 19093 | W12: 19237 | X12: 19382 | Y12: 19527 | Z12: 19671 | AA12: 19816 | AB12: 19960 | AC12: 20105 | AD12: 20249 | AE12: 20394 | AF12: 20538 | AG12: 20683 | AH12: 20827 | AI12: 20972 | AJ12: 21116 | AK12: 21261
... A44: Banca Città | B44: 1321.3 | C44: 1333 | D44: 1344.8 | E44: 1356.6 | F44: 1368.4 | G44: 1380.2 | H44: 1392 | I44: 1403.8 | J44: 1415.5 | K44: 1427.3 | L44: 1439.1 | M44: 1450.9 | N44: 1462.7 | O44: 1474.5 | P44: 1486.3 | Q44: 1498 | R44: 1509.8 | S44: 1521.6 | T44: 1533.4 | U44: 1545.2 | V44: 1557 | W44: 1568.8 | X44: 1580.5 | Y44: 1592.3 | Z44: 1604.1 | AA44: 1615.9 | AB44: 1627.7 | AC44: 1639.5 | AD44: 1651.2 | AE44: 1663 | AF44: 1674.8 | AG44: 1686.6 | AH44: 1698.4 | AI44: 1710.2 | AJ44: 1722 | AK44: 1733.7

Sheet Products
A1: Prodotto | B1: Categoria | C1: Peso margine | D1: Codice
A2: Mutui | B2: Credito | C2: 0.6 | D2: P1
A3: Prestiti | B3: Credito | C3: 0.65 | D3: P2
A4: Conti | B4: Raccolta | C4: 0.7 | D4: P3
A5: Carte | B5: Servizi | C5: 0.75 | D5: P4
A6: Leasing | B6: Credito | C6: 0.8 | D6: P5
A7: Factoring | B7: Credito | C7: 0.85 | D7: P6
A8: Risparmio | B8: Raccolta | C8: 0.9 | D8: P7
A9: Assicurazioni | B9: Servizi | C9: 0.95 | D9: P8

Sheet Aree
A1: Regione | B1: Responsabile | C1: Obiettivo
A2: Nord-Ovest | B2: Galli | C2: 42000
A3: Nord-Est | B3: Fontana | C3: 30000
A4: Centro | B4: Santoro | C4: 47000
A5: Sud | B5: Marini | C5: 26000
A6: Isole | B6: Caruso | C6: 16000

Sheet Calc_Month
A1: Mese | B1: Data | C1: Volumi | D1: Ricavi | E1: Costi | F1: Clienti | G1: Margine | H1: Budget | I1: Scost. % | J1: YTD volumi | K1: Anno | L1: Media mobile 3m | M1: Volumi USD | N1: Scenario | O1: Rango | P1: Var. m/m | Q1: Cost/income | R1: Ricavo/cliente | S1: Esito | T1: Trimestre | U1: Media 12m
A2: =ROW()-1 -> 1 | B2: =EOMONTH(DATE(2024,A2,1),0) -> 45322 | C2: =SUMIFS(Data!$E$2:$E$5761,Data!$A$2:$A$5761,Control!$B$2,Data!$B$2:$B$5761,A2) -> 8012.1 | D2: =SUMIFS(Data!$F$2:$F$5761,Data!$A$2:$A$5761,Control!$B$2,Data!$B$2:$B$5761,A2) -> 433.36 | E2: =SUMIFS(Data!$G$2:$G$5761,Data!$A$2:$A$5761,Control!$B$2,Data!$B$2:$B$5761,A2) -> 263.59 | F2: =SUMIFS(Data!$H$2:$H$5761,Data!$A$2:$A$5761,Control!$B$2,Data!$B$2:$B$5761,A2) -> 980 | G2: =D2-E2 -> 169.77 | H2: {=INDEX(Budget!$B$2:$AK$21,Control!$B$6,MATCH(A2,Budget!$B$1:$AK$1,0))} -> 8019 | I2: =IFERROR(C2/H2-1,0) -> -0.00086045642 | J2: =SUMIFS($C$2:$C$37,$K$2:$K$37,K2,$A$2:$A$37,"<="&A2) -> 8012.1 | K2: =YEAR(B2) -> 2024 | L2: =AVERAGE(OFFSET(C2,-MIN(2,A2-1),0,MIN(3,A2),1)) -> 8012.1 | M2: =C2*_xlfn.XLOOKUP(A2,FX!$A$2:$A$37,FX!$C$2:$C$37) -> 8476.8018 | N2: =C2*(1+Control!$B$4)^(A2/12) -> 8031.86 | O2: =RANK(C2,$C$2:$C$37,0) -> 36 | P2: =IFERROR(C2-C1,0) -> 0 | Q2: =IFERROR(E2/D2,0) -> 0.60824718 | R2: =ROUND(IFERROR(D2/F2,0),2) -> 0.44 | S2: =IF(AND(I2>0,G2>0),"sopra",IF(OR(I2<-0.05,G2<0),"sotto","in linea")) -> in linea | T2: ="T"&ROUNDUP(MONTH(B2)/3,0)&"-"&YEAR(B2) -> T1-2024 | U2: =AVERAGEIFS($C$2:$C$37,$A$2:$A$37,">"&(A2-12),$A$2:$A$37,"<="&A2) -> 8012.1
A3: =ROW()-1 -> 2 | B3: =EOMONTH(DATE(2024,A3,1),0) -> 45351 | C3: =SUMIFS(Data!$E$2:$E$5761,Data!$A$2:$A$5761,Control!$B$2,Data!$B$2:$B$5761,A3) -> 8126.5 | D3: =SUMIFS(Data!$F$2:$F$5761,Data!$A$2:$A$5761,Control!$B$2,Data!$B$2:$B$5761,A3) -> 440.86 | E3: =SUMIFS(Data!$G$2:$G$5761,Data!$A$2:$A$5761,Control!$B$2,Data!$B$2:$B$5761,A3) -> 266.66 | F3: =SUMIFS(Data!$H$2:$H$5761,Data!$A$2:$A$5761,Control!$B$2,Data!$B$2:$B$5761,A3) -> 951 | G3: =D3-E3 -> 174.2 | H3: {=INDEX(Budget!$B$2:$AK$21,Control!$B$6,MATCH(A3,Budget!$B$1:$AK$1,0))} -> 8091 | I3: =IFERROR(C3/H3-1,0) -> 0.0043875912 | J3: =SUMIFS($C$2:$C$37,$K$2:$K$37,K3,$A$2:$A$37,"<="&A3) -> 16138.6 | K3: =YEAR(B3) -> 2024 | L3: =AVERAGE(OFFSET(C3,-MIN(2,A3-1),0,MIN(3,A3),1)) -> 8069.3 | M3: =C3*_xlfn.XLOOKUP(A3,FX!$A$2:$A$37,FX!$C$2:$C$37) -> 8661.2237 | N3: =C3*(1+Control!$B$4)^(A3/12) -> 8166.6337 | O3: =RANK(C3,$C$2:$C$37,0) -> 35 | P3: =IFERROR(C3-C2,0) -> 114.4 | Q3: =IFERROR(E3/D3,0) -> 0.60486322 | R3: =ROUND(IFERROR(D3/F3,0),2) -> 0.46 | S3: =IF(AND(I3>0,G3>0),"sopra",IF(OR(I3<-0.05,G3<0),"sotto","in linea")) -> sopra | T3: ="T"&ROUNDUP(MONTH(B3)/3,0)&"-"&YEAR(B3) -> T1-2024 | U3: =AVERAGEIFS($C$2:$C$37,$A$2:$A$37,">"&(A3-12),$A$2:$A$37,"<="&A3) -> 8069.3
A4: =ROW()-1 -> 3 | B4: =EOMONTH(DATE(2024,A4,1),0) -> 45382 | C4: =SUMIFS(Data!$E$2:$E$5761,Data!$A$2:$A$5761,Control!$B$2,Data!$B$2:$B$5761,A4) -> 8163.5 | D4: =SUMIFS(Data!$F$2:$F$5761,Data!$A$2:$A$5761,Control!$B$2,Data!$B$2:$B$5761,A4) -> 443.09 | E4: =SUMIFS(Data!$G$2:$G$5761,Data!$A$2:$A$5761,Control!$B$2,Data!$B$2:$B$5761,A4) -> 268.36 | F4: =SUMIFS(Data!$H$2:$H$5761,Data!$A$2:$A$5761,Control!$B$2,Data!$B$2:$B$5761,A4) -> 906 | G4: =D4-E4 -> 174.73 | H4: {=INDEX(Budget!$B$2:$AK$21,Control!$B$6,MATCH(A4,Budget!$B$1:$AK$1,0))} -> 8162 | I4: =IFERROR(C4/H4-1,0) -> 0.00018377849 | J4: =SUMIFS($C$2:$C$37,$K$2:$K$37,K4,$A$2:$A$37,"<="&A4) -> 24302.1 | K4: =YEAR(B4) -> 2024 | L4: =AVERAGE(OFFSET(C4,-MIN(2,A4-1),0,MIN(3,A4),1)) -> 8100.7 | M4: =C4*_xlfn.XLOOKUP(A4,FX!$A$2:$A$37,FX!$C$2:$C$37) -> 8758.6192 | N4: =C4*(1+Control!$B$4)^(A4/12) -> 8224.0493 | O4: =RANK(C4,$C$2:$C$37,0) -> 34 | P4: =IFERROR(C4-C3,0) -> 37 | Q4: =IFERROR(E4/D4,0) -> 0.60565574 | R4: =ROUND(IFERROR(D4/F4,0),2) -> 0.49 | S4: =IF(AND(I4>0,G4>0),"sopra",IF(OR(I4<-0.05,G4<0),"sotto","in linea")) -> sopra | T4: ="T"&ROUNDUP(MONTH(B4)/3,0)&"-"&YEAR(B4) -> T1-2024 | U4: =AVERAGEIFS($C$2:$C$37,$A$2:$A$37,">"&(A4-12),$A$2:$A$37,"<="&A4) -> 8100.7
A5: =ROW()-1 -> 4 | B5: =EOMONTH(DATE(2024,A5,1),0) -> 45412 | C5: =SUMIFS(Data!$E$2:$E$5761,Data!$A$2:$A$5761,Control!$B$2,Data!$B$2:$B$5761,A5) -> 8209.7 | D5: =SUMIFS(Data!$F$2:$F$5761,Data!$A$2:$A$5761,Control!$B$2,Data!$B$2:$B$5761,A5) -> 444.15 | E5: =SUMIFS(Data!$G$2:$G$5761,Data!$A$2:$A$5761,Control!$B$2,Data!$B$2:$B$5761,A5) -> 268.62 | F5: =SUMIFS(Data!$H$2:$H$5761,Data!$A$2:$A$5761,Control!$B$2,Data!$B$2:$B$5761,A5) -> 925 | G5: =D5-E5 -> 175.53 | H5: {=INDEX(Budget!$B$2:$AK$21,Control!$B$6,MATCH(A5,Budget!$B$1:$AK$1,0))} -> 8234 | I5: =IFERROR(C5/H5-1,0) -> -0.002951178 | J5: =SUMIFS($C$2:$C$37,$K$2:$K$37,K5,$A$2:$A$37,"<="&A5) -> 32511.8 | K5: =YEAR(B5) -> 2024 | L5: =AVERAGE(OFFSET(C5,-MIN(2,A5-1),0,MIN(3,A5),1)) -> 8166.5667 | M5: =C5*_xlfn.XLOOKUP(A5,FX!$A$2:$A$37,FX!$C$2:$C$37) -> 8859.0873 | N5: =C5*(1+Control!$B$4)^(A5/12) -> 8290.9894 | O5: =RANK(C5,$C$2:$C$37,0) -> 33 | P5: =IFERROR(C5-C4,0) -> 46.2 | Q5: =IFERROR(E5/D5,0) -> 0.60479568 | R5: =ROUND(IFERROR(D5/F5,0),2) -> 0.48 | S5: =IF(AND(I5>0,G5>0),"sopra",IF(OR(I5<-0.05,G5<0),"sotto","in linea")) -> in linea | T5: ="T"&ROUNDUP(MONTH(B5)/3,0)&"-"&YEAR(B5) -> T2-2024 | U5: =AVERAGEIFS($C$2:$C$37,$A$2:$A$37,">"&(A5-12),$A$2:$A$37,"<="&A5) -> 8127.95
A6: =ROW()-1 -> 5 | B6: =EOMONTH(DATE(2024,A6,1),0) -> 45443 | C6: =SUMIFS(Data!$E$2:$E$5761,Data!$A$2:$A$5761,Control!$B$2,Data!$B$2:$B$5761,A6) -> 8325.2 | D6: =SUMIFS(Data!$F$2:$F$5761,Data!$A$2:$A$5761,Control!$B$2,Data!$B$2:$B$5761,A6) -> 451.45 | E6: =SUMIFS(Data!$G$2:$G$5761,Data!$A$2:$A$5761,Control!$B$2,Data!$B$2:$B$5761,A6) -> 271.5 | F6: =SUMIFS(Data!$H$2:$H$5761,Data!$A$2:$A$5761,Control!$B$2,Data!$B$2:$B$5761,A6) -> 901 | G6: =D6-E6 -> 179.95 | H6: {=INDEX(Budget!$B$2:$AK$21,Control!$B$6,MATCH(A6,Budget!$B$1:$AK$1,0))} -> 8305 | I6: =IFERROR(C6/H6-1,0) -> 0.0024322697 | J6: =SUMIFS($C$2:$C$37,$K$2:$K$37,K6,$A$2:$A$37,"<="&A6) -> 40837 | K6: =YEAR(B6) -> 2024 | L6: =AVERAGE(OFFSET(C6,-MIN(2,A6-1),0,MIN(3,A6),1)) -> 8232.8 | M6: =C6*_xlfn.XLOOKUP(A6,FX!$A$2:$A$37,FX!$C$2:$C$37) -> 9026.1818 | N6: =C6*(1+Control!$B$4)^(A6/12) -> 8428.3686 | O6: =RANK(C6,$C$2:$C$37,0) -> 32 | P6: =IFERROR(C6-C5,0) -> 115.5 | Q6: =IFERROR(E6/D6,0) -> 0.6013955 | R6: =ROUND(IFERROR(D6/F6,0),2) -> 0.5 | S6: =IF(AND(I6>0,G6>0),"sopra",IF(OR(I6<-0.05,G6<0),"sotto","in linea")) -> sopra | T6: ="T"&ROUNDUP(MONTH(B6)/3,0)&"-"&YEAR(B6) -> T2-2024 | U6: =AVERAGEIFS($C$2:$C$37,$A$2:$A$37,">"&(A6-12),$A$2:$A$37,"<="&A6) -> 8167.4
A7: =ROW()-1 -> 6 | B7: =EOMONTH(DATE(2024,A7,1),0) -> 45473 | C7: =SUMIFS(Data!$E$2:$E$5761,Data!$A$2:$A$5761,Control!$B$2,Data!$B$2:$B$5761,A7) -> 8343.3 | D7: =SUMIFS(Data!$F$2:$F$5761,Data!$A$2:$A$5761,Control!$B$2,Data!$B$2:$B$5761,A7) -> 451.67 | E7: =SUMIFS(Data!$G$2:$G$5761,Data!$A$2:$A$5761,Control!$B$2,Data!$B$2:$B$5761,A7) -> 275.01 | F7: =SUMIFS(Data!$H$2:$H$5761,Data!$A$2:$A$5761,Control!$B$2,Data!$B$2:$B$5761,A7) -> 974 | G7: =D7-E7 -> 176.66 | H7: {=INDEX(Budget!$B$2:$AK$21,Control!$B$6,MATCH(A7,Budget!$B$1:$AK$1,0))} -> 8377 | I7: =IFERROR(C7/H7-1,0) -> -0.0040229199 | J7: =SUMIFS($C$2:$C$37,$K$2:$K$37,K7,$A$2:$A$37,"<="&A7) -> 49180.3 | K7: =YEAR(B7) -> 2024 | L7: =AVERAGE(OFFSET(C7,-MIN(2,A7-1),0,MIN(3,A7),1)) -> 8292.7333 | M7: =C7*_xlfn.XLOOKUP(A7,FX!$A$2:$A$37,FX!$C$2:$C$37) -> 9076.6761 | N7: =C7*(1+Control!$B$4)^(A7/12) -> 8467.5247 | O7: =RANK(C7,$C$2:$C$37,0) -> 31 | P7: =IFERROR(C7-C6,0) -> 18.1 | Q7: =IFERROR(E7/D7,0) -> 0.60887374 | R7: =ROUND(IFERROR(D7/F7,0),2) -> 0.46 | S7: =IF(AND(I7>0,G7>0),"sopra",IF(OR(I7<-0.05,G7<0),"sotto","in linea")) -> in linea | T7: ="T"&ROUNDUP(MONTH(B7)/3,0)&"-"&YEAR(B7) -> T2-2024 | U7: =AVERAGEIFS($C$2:$C$37,$A$2:$A$37,">"&(A7-12),$A$2:$A$37,"<="&A7) -> 8196.7167
A8: =ROW()-1 -> 7 | B8: =EOMONTH(DATE(2024,A8,1),0) -> 45504 | C8: =SUMIFS(Data!$E$2:$E$5761,Data!$A$2:$A$5761,Control!$B$2,Data!$B$2:$B$5761,A8) -> 8405 | D8: =SUMIFS(Data!$F$2:$F$5761,Data!$A$2:$A$5761,Control!$B$2,Data!$B$2:$B$5761,A8) -> 455.92 | E8: =SUMIFS(Data!$G$2:$G$5761,Data!$A$2:$A$5761,Control!$B$2,Data!$B$2:$B$5761,A8) -> 276.09 | F8: =SUMIFS(Data!$H$2:$H$5761,Data!$A$2:$A$5761,Control!$B$2,Data!$B$2:$B$5761,A8) -> 935 | G8: =D8-E8 -> 179.83 | H8: {=INDEX(Budget!$B$2:$AK$21,Control!$B$6,MATCH(A8,Budget!$B$1:$AK$1,0))} -> 8448 | I8: =IFERROR(C8/H8-1,0) -> -0.0050899621 | J8: =SUMIFS($C$2:$C$37,$K$2:$K$37,K8,$A$2:$A$37,"<="&A8) -> 57585.3 | K8: =YEAR(B8) -> 2024 | L8: =AVERAGE(OFFSET(C8,-MIN(2,A8-1),0,MIN(3,A8),1)) -> 8357.8333 | M8: =C8*_xlfn.XLOOKUP(A8,FX!$A$2:$A$37,FX!$C$2:$C$37) -> 9162.2905 | N8: =C8*(1+Control!$B$4)^(A8/12) -> 8551.181 | O8: =RANK(C8,$C$2:$C$37,0) -> 30 | P8: =IFERROR(C8-C7,0) -> 61.7 | Q8: =IFERROR(E8/D8,0) -> 0.60556677 | R8: =ROUND(IFERROR(D8/F8,0),2) -> 0.49 | S8: =IF(AND(I8>0,G8>0),"sopra",IF(OR(I8<-0.05,G8<0),"sotto","in linea")) -> in linea | T8: ="T"&ROUNDUP(MONTH(B8)/3,0)&"-"&YEAR(B8) -> T3-2024 | U8: =AVERAGEIFS($C$2:$C$37,$A$2:$A$37,">"&(A8-12),$A$2:$A$37,"<="&A8) -> 8226.4714
A9: =ROW()-1 -> 8 | B9: =EOMONTH(DATE(2024,A9,1),0) -> 45535 | C9: =SUMIFS(Data!$E$2:$E$5761,Data!$A$2:$A$5761,Control!$B$2,Data!$B$2:$B$5761,A9) -> 8440.6 | D9: =SUMIFS(Data!$F$2:$F$5761,Data!$A$2:$A$5761,Control!$B$2,Data!$B$2:$B$5761,A9) -> 457.53 | E9: =SUMIFS(Data!$G$2:$G$5761,Data!$A$2:$A$5761,Control!$B$2,Data!$B$2:$B$5761,A9) -> 276.42 | F9: =SUMIFS(Data!$H$2:$H$5761,Data!$A$2:$A$5761,Control!$B$2,Data!$B$2:$B$5761,A9) -> 937 | G9: =D9-E9 -> 181.11 | H9: {=INDEX(Budget!$B$2:$AK$21,Control!$B$6,MATCH(A9,Budget!$B$1:$AK$1,0))} -> 8520 | I9: =IFERROR(C9/H9-1,0) -> -0.0093192488 | J9: =SUMIFS($C$2:$C$37,$K$2:$K$37,K9,$A$2:$A$37,"<="&A9) -> 66025.9 | K9: =YEAR(B9) -> 2024 | L9: =AVERAGE(OFFSET(C9,-MIN(2,A9-1),0,MIN(3,A9),1)) -> 8396.3 | M9: =C9*_xlfn.XLOOKUP(A9,FX!$A$2:$A$37,FX!$C$2:$C$37) -> 9207.0065 | N9: =C9*(1+Control!$B$4)^(A9/12) -> 8608.579 | O9: =RANK(C9,$C$2:$C$37,0) -> 29 | P9: =IFERROR(C9-C8,0) -> 35.6 | Q9: =IFERROR(E9/D9,0) -> 0.6041571 | R9: =ROUND(IFERROR(D9/F9,0),2) -> 0.49 | S9: =IF(AND(I9>0,G9>0),"sopra",IF(OR(I9<-0.05,G9<0),"sotto","in linea")) -> in linea | T9: ="T"&ROUNDUP(MONTH(B9)/3,0)&"-"&YEAR(B9) -> T3-2024 | U9: =AVERAGEIFS($C$2:$C$37,$A$2:$A$37,">"&(A9-12),$A$2:$A$37,"<="&A9) -> 8253.2375
A10: =ROW()-1 -> 9 | B10: =EOMONTH(DATE(2024,A10,1),0) -> 45565 | C10: =SUMIFS(Data!$E$2:$E$5761,Data!$A$2:$A$5761,Control!$B$2,Data!$B$2:$B$5761,A10) -> 8499.6 | D10: =SUMIFS(Data!$F$2:$F$5761,Data!$A$2:$A$5761,Control!$B$2,Data!$B$2:$B$5761,A10) -> 458.84 | E10: =SUMIFS(Data!$G$2:$G$5761,Data!$A$2:$A$5761,Control!$B$2,Data!$B$2:$B$5761,A10) -> 279.94 | F10: =SUMIFS(Data!$H$2:$H$5761,Data!$A$2:$A$5761,Control!$B$2,Data!$B$2:$B$5761,A10) -> 994 | G10: =D10-E10 -> 178.9 | H10: {=INDEX(Budget!$B$2:$AK$21,Control!$B$6,MATCH(A10,Budget!$B$1:$AK$1,0))} -> 8591 | I10: =IFERROR(C10/H10-1,0) -> -0.010639041 | J10: =SUMIFS($C$2:$C$37,$K$2:$K$37,K10,$A$2:$A$37,"<="&A10) -> 74525.5 | K10: =YEAR(B10) -> 2024 | L10: =AVERAGE(OFFSET(C10,-MIN(2,A10-1),0,MIN(3,A10),1)) -> 8448.4 | M10: =C10*_xlfn.XLOOKUP(A10,FX!$A$2:$A$37,FX!$C$2:$C$37) -> 9263.714 | N10: =C10*(1+Control!$B$4)^(A10/12) -> 8690.1327 | O10: =RANK(C10,$C$2:$C$37,0) -> 28 | P10: =IFERROR(C10-C9,0) -> 59 | Q10: =IFERROR(E10/D10,0) -> 0.61010374 | R10: =ROUND(IFERROR(D10/F10,0),2) -> 0.46 | S10: =IF(AND(I10>0,G10>0),"sopra",IF(OR(I10<-0.05,G10<0),"sotto","in linea")) -> in linea | T10: ="T"&ROUNDUP(MONTH(B10)/3,0)&"-"&YEAR(B10) -> T3-2024 | U10: =AVERAGEIFS($C$2:$C$37,$A$2:$A$37,">"&(A10-12),$A$2:$A$37,"<="&A10) -> 8280.6111
A11: =ROW()-1 -> 10 | B11: =EOMONTH(DATE(2024,A11,1),0) -> 45596 | C11: =SUMIFS(Data!$E$2:$E$5761,Data!$A$2:$A$5761,Control!$B$2,Data!$B$2:$B$5761,A11) -> 8590.6 | D11: =SUMIFS(Data!$F$2:$F$5761,Data!$A$2:$A$5761,Control!$B$2,Data!$B$2:$B$5761,A11) -> 465 | E11: =SUMIFS(Data!$G$2:$G$5761,Data!$A$2:$A$5761,Control!$B$2,Data!$B$2:$B$5761,A11) -> 281.33 | F11: =SUMIFS(Data!$H$2:$H$5761,Data!$A$2:$A$5761,Control!$B$2,Data!$B$2:$B$5761,A11) -> 965 | G11: =D11-E11 -> 183.67 | H11: {=INDEX(Budget!$B$2:$AK$21,Control!$B$6,MATCH(A11,Budget!$B$1:$AK$1,0))} -> 8663 | I11: =IFERROR(C11/H11-1,0) -> -0.008357382 | J11: =SUMIFS($C$2:$C$37,$K$2:$K$37,K11,$A$2:$A$37,"<="&A11) -> 83116.1 | K11: =YEAR(B11) -> 2024 | L11: =AVERAGE(OFFSET(C11,-MIN(2,A11-1),0,MIN(3,A11),1)) -> 8510.2667 | M11: =C11*_xlfn.XLOOKUP(A11,FX!$A$2:$A$37,FX!$C$2:$C$37) -> 9341.4184 | N11: =C11*(1+Control!$B$4)^(A11/12) -> 8804.8343 | O11: =RANK(C11,$C$2:$C$37,0) -> 27 | P11: =IFERROR(C11-C10,0) -> 91 | Q11: =IFERROR(E11/D11,0) -> 0.60501075 | R11: =ROUND(IFERROR(D11/F11,0),2) -> 0.48 | S11: =IF(AND(I11>0,G11>0),"sopra",IF(OR(I11<-0.05,G11<0),"sotto","in linea")) -> in linea | T11: ="T"&ROUNDUP(MONTH(B11)/3,0)&"-"&YEAR(B11) -> T4-2024 | U11: =AVERAGEIFS($C$2:$C$37,$A$2:$A$37,">"&(A11-12),$A$2:$A$37,"<="&A11) -> 8311.61
A12: =ROW()-1 -> 11 | B12: =EOMONTH(DATE(2024,A12,1),0) -> 45626 | C12: =SUMIFS(Data!$E$2:$E$5761,Data!$A$2:$A$5761,Control!$B$2,Data!$B$2:$B$5761,A12) -> 8644.9 | D12: =SUMIFS(Data!$F$2:$F$5761,Data!$A$2:$A$5761,Control!$B$2,Data!$B$2:$B$5761,A12) -> 468.26 | E12: =SUMIFS(Data!$G$2:$G$5761,Data!$A$2:$A$5761,Control!$B$2,Data!$B$2:$B$5761,A12) -> 284.77 | F12: =SUMIFS(Data!$H$2:$H$5761,Data!$A$2:$A$5761,Control!$B$2,Data!$B$2:$B$5761,A12) -> 927 | G12: =D12-E12 -> 183.49 | H12: {=INDEX(Budget!$B$2:$AK$21,Control!$B$6,MATCH(A12,Budget!$B$1:$AK$1,0))} -> 8734 | I12: =IFERROR(C12/H12-1,0) -> -0.010201511 | J12: =SUMIFS($C$2:$C$37,$K$2:$K$37,K12,$A$2:$A$37,"<="&A12) -> 91761 | K12: =YEAR(B12) -> 2024 | L12: =AVERAGE(OFFSET(C12,-MIN(2,A12-1),0,MIN(3,A12),1)) -> 8578.3667 | M12: =C12*_xlfn.XLOOKUP(A12,FX!$A$2:$A$37,FX!$C$2:$C$37) -> 9365.8847 | N12: =C12*(1+Control!$B$4)^(A12/12) -> 8882.3408 | O12: =RANK(C12,$C$2:$C$37,0) -> 26 | P12: =IFERROR(C12-C11,0) -> 54.3 | Q12: =IFERROR(E12/D12,0) -> 0.60814505 | R12: =ROUND(IFERROR(D12/F12,0),2) -> 0.51 | S12: =IF(AND(I12>0,G12>0),"sopra",IF(OR(I12<-0.05,G12<0),"sotto","in linea")) -> in linea | T12: ="T"&ROUNDUP(MONTH(B12)/3,0)&"-"&YEAR(B12) -> T4-2024 | U12: =AVERAGEIFS($C$2:$C$37,$A$2:$A$37,">"&(A12-12),$A$2:$A$37,"<="&A12) -> 8341.9091
A13: =ROW()-1 -> 12 | B13: =EOMONTH(DATE(2024,A13,1),0) -> 45657 | C13: =SUMIFS(Data!$E$2:$E$5761,Data!$A$2:$A$5761,Control!$B$2,Data!$B$2:$B$5761,A13) -> 8718.7 | D13: =SUMIFS(Data!$F$2:$F$5761,Data!$A$2:$A$5761,Control!$B$2,Data!$B$2:$B$5761,A13) -> 472.51 | E13: =SUMIFS(Data!$G$2:$G$5761,Data!$A$2:$A$5761,Control!$B$2,Data!$B$2:$B$5761,A13) -> 285.29 | F13: =SUMIFS(Data!$H$2:$H$5761,Data!$A$2:$A$5761,Control!$B$2,Data!$B$2:$B$5761,A13) -> 972 | G13: =D13-E13 -> 187.22 | H13: {=INDEX(Budget!$B$2:$AK$21,Control!$B$6,MATCH(A13,Budget!$B$1:$AK$1,0))} -> 8806 | I13: =IFERROR(C13/H13-1,0) -> -0.0099136952 | J13: =SUMIFS($C$2:$C$37,$K$2:$K$37,K13,$A$2:$A$37,"<="&A13) -> 100479.7 | K13: =YEAR(B13) -> 2024 | L13: =AVERAGE(OFFSET(C13,-MIN(2,A13-1),0,MIN(3,A13),1)) -> 8651.4 | M13: =C13*_xlfn.XLOOKUP(A13,FX!$A$2:$A$37,FX!$C$2:$C$37) -> 9400.5023 | N13: =C13*(1+Control!$B$4)^(A13/12) -> 8980.261 | O13: =RANK(C13,$C$2:$C$37,0) -> 25 | P13: =IFERROR(C13-C12,0) -> 73.8 | Q13: =IFERROR(E13/D13,0) -> 0.60377558 | R13: =ROUND(IFERROR(D13/F13,0),2) -> 0.49 | S13: =IF(AND(I13>0,G13>0),"sopra",IF(OR(I13<-0.05,G13<0),"sotto","in linea")) -> in linea | T13: ="T"&ROUNDUP(MONTH(B13)/3,0)&"-"&YEAR(B13) -> T4-2024 | U13: =AVERAGEIFS($C$2:$C$37,$A$2:$A$37,">"&(A13-12),$A$2:$A$37,"<="&A13) -> 8373.3083
... A37: =ROW()-1 -> 36 | B37: =EOMONTH(DATE(2024,A37,1),0) -> 46387 | C37: =SUMIFS(Data!$E$2:$E$5761,Data!$A$2:$A$5761,Control!$B$2,Data!$B$2:$B$5761,A37) -> 10243.3 | D37: =SUMIFS(Data!$F$2:$F$5761,Data!$A$2:$A$5761,Control!$B$2,Data!$B$2:$B$5761,A37) -> 555.09 | E37: =SUMIFS(Data!$G$2:$G$5761,Data!$A$2:$A$5761,Control!$B$2,Data!$B$2:$B$5761,A37) -> 334.49 | F37: =SUMIFS(Data!$H$2:$H$5761,Data!$A$2:$A$5761,Control!$B$2,Data!$B$2:$B$5761,A37) -> 975 | G37: =D37-E37 -> 220.6 | H37: {=INDEX(Budget!$B$2:$AK$21,Control!$B$6,MATCH(A37,Budget!$B$1:$AK$1,0))} -> 10523 | I37: =IFERROR(C37/H37-1,0) -> -0.026579873 | J37: =SUMIFS($C$2:$C$37,$K$2:$K$37,K37,$A$2:$A$37,"<="&A37) -> 118690.4 | K37: =YEAR(B37) -> 2026 | L37: =AVERAGE(OFFSET(C37,-MIN(2,A37-1),0,MIN(3,A37),1)) -> 10194.233 | M37: =C37*_xlfn.XLOOKUP(A37,FX!$A$2:$A$37,FX!$C$2:$C$37) -> 11117.053 | N37: =C37*(1+Control!$B$4)^(A37/12) -> 11193.13 | O37: =RANK(C37,$C$2:$C$37,0) -> 2 | P37: =IFERROR(C37-C36,0) -> -8.9 | Q37: =IFERROR(E37/D37,0) -> 0.60258697 | R37: =ROUND(IFERROR(D37/F37,0),2) -> 0.57 | S37: =IF(AND(I37>0,G37>0),"sopra",IF(OR(I37<-0.05,G37<0),"sotto","in linea")) -> in linea | T37: ="T"&ROUNDUP(MONTH(B37)/3,0)&"-"&YEAR(B37) -> T4-2026 | U37: =AVERAGEIFS($C$2:$C$37,$A$2:$A$37,">"&(A37-12),$A$2:$A$37,"<="&A37) -> 9890.8667

Sheet Calc_Bank
A1: Banca | B1: Regione | C1: Volumi | D1: Ricavi | E1: Costi | F1: Margine | G1: Mese prec. | H1: Var. % | I1: Anno prec. | J1: YoY | K1: Quota | L1: Rango | M1: Max mutui | N1: Media prodotti | O1: Prodotti sopra media | P1: Budget | Q1: Gap budget | R1: Segmento | S1: Classe | T1: Codice area | U1: Quartile | V1: Selezionata | W1: Clienti | X1: Ricavo/cliente | Y1: Scenario | Z1: In regione sel. | AA1: Scost. LET | AB1: YTD
A2: =Banks!A2 -> Banca Alpi | B2: =VLOOKUP(A2,Banks!$A$2:$C$21,3,FALSE) -> Nord-Ovest | C2: =SUMIFS(Data!$E:$E,Data!$A:$A,A2,Data!$B:$B,Control!$B$3) -> 6542.2 | D2: =SUMIFS(Data!$F$2:$F$5761,Data!$A$2:$A$5761,A2,Data!$B$2:$B$5761,Control!$B$3) -> 355.72 | E2: =SUMIFS(Data!$G$2:$G$5761,Data!$A$2:$A$5761,A2,Data!$B$2:$B$5761,Control!$B$3) -> 216.07 | F2: =D2-E2 -> 139.65 | G2: =SUMIFS(Data!$E$2:$E$5761,Data!$A$2:$A$5761,A2,Data!$B$2:$B$5761,Control!$B$13) -> 6551.1 | H2: =IFERROR(C2/G2-1,0) -> -0.0013585505 | I2: =SUMIFS(Data!$E$2:$E$5761,Data!$A$2:$A$5761,A2,Data!$B$2:$B$5761,Control!$B$14) -> 5941.6 | J2: =IFERROR(C2/I2-1,0) -> 0.10108388 | K2: =C2/SUM($C$2:$C$21) -> 0.019042369 | L2: =RANK(C2,$C$2:$C$21) -> 20 | M2: =_xlfn.MAXIFS(Data!$E$2:$E$5761,Data!$A$2:$A$5761,A2,Data!$C$2:$C$5761,"Mutui") -> 425.1 | N2: =AVERAGEIFS(Data!$E$2:$E$5761,Data!$A$2:$A$5761,A2,Data!$B$2:$B$5761,Control!$B$3) -> 817.775 | O2: =COUNTIFS(Data!$A$2:$A$5761,A2,Data!$B$2:$B$5761,Control!$B$3,Data!$E$2:$E$5761,">"&N2) -> 4 | P2: =INDEX(Budget!$B$2:$AK$21,MATCH(A2,Budget!$A$2:$A$21,0),MATCH(Control!$B$3,Budget!$B$1:$AK$1,0)) -> 6613 | Q2: =C2-P2 -> -70.8 | R2: =_xlfn.XLOOKUP(A2,Banks!$A$2:$A$21,Banks!$E$2:$E$21) -> Grande | S2: =CHOOSE(IF(R2="Grande",1,IF(R2="Media",2,3)),"A","B","C") -> A | T2: {=_xlfn.SWITCH(B2,"Nord-Ovest","NO","Nord-Est","NE","Centro","CE","Sud","SU","IS")} -> NO | U2: =IF(C2>=PERCENTILE($C$2:$C$21,0.75),"primo quartile",IF(C2<=PERCENTILE($C$2:$C$21,0.25),"ultimo quartile","centrale")) -> ultimo quartile | V2: =IF(A2=Control!$B$2,"<<","") | W2: =SUMIFS(Data!$H$2:$H$5761,Data!$A$2:$A$5761,A2,Data!$B$2:$B$5761,Control!$B$3) -> 690 | X2: =IFERROR(D2/W2,0) -> 0.51553623 | Y2: =C2*(1+Control!$B$4) -> 6738.466 | Z2: =IF(B2=Control!$B$5,C2,0) -> 0 | AA2: =_xlfn.LET(_xlpm.v,C2,_xlpm.b,P2,IF(_xlpm.b=0,0,ROUND((_xlpm.v-_xlpm.b)/_xlpm.b,4))) -> -0.0107 | AB2: {=SUMPRODUCT((Data!$A$2:$A$5761=A2)*(Data!$B$2:$B$5761<=Control!$B$3)*(Data!$J$2:$J$5761=Control!$B$11)*Data!$E$2:$E$5761)} -> 6542.2
A3: =Banks!A3 -> Banca Adriatica | B3: =VLOOKUP(A3,Banks!$A$2:$C$21,3,FALSE) -> Nord-Est | C3: =SUMIFS(Data!$E:$E,Data!$A:$A,A3,Data!$B:$B,Control!$B$3) -> 7649.6 | D3: =SUMIFS(Data!$F$2:$F$5761,Data!$A$2:$A$5761,A3,Data!$B$2:$B$5761,Control!$B$3) -> 415.13 | E3: =SUMIFS(Data!$G$2:$G$5761,Data!$A$2:$A$5761,A3,Data!$B$2:$B$5761,Control!$B$3) -> 250.61 | F3: =D3-E3 -> 164.52 | G3: =SUMIFS(Data!$E$2:$E$5761,Data!$A$2:$A$5761,A3,Data!$B$2:$B$5761,Control!$B$13) -> 7666.8 | H3: =IFERROR(C3/G3-1,0) -> -0.0022434392 | I3: =SUMIFS(Data!$E$2:$E$5761,Data!$A$2:$A$5761,A3,Data!$B$2:$B$5761,Control!$B$14) -> 6980.2 | J3: =IFERROR(C3/I3-1,0) -> 0.095899831 | K3: =C3/SUM($C$2:$C$21) -> 0.022265676 | L3: =RANK(C3,$C$2:$C$21) -> 19 | M3: =_xlfn.MAXIFS(Data!$E$2:$E$5761,Data!$A$2:$A$5761,A3,Data!$C$2:$C$5761,"Mutui") -> 493.7 | N3: =AVERAGEIFS(Data!$E$2:$E$5761,Data!$A$2:$A$5761,A3,Data!$B$2:$B$5761,Control!$B$3) -> 956.2 | O3: =COUNTIFS(Data!$A$2:$A$5761,A3,Data!$B$2:$B$5761,Control!$B$3,Data!$E$2:$E$5761,">"&N3) -> 4 | P3: =INDEX(Budget!$B$2:$AK$21,MATCH(A3,Budget!$A$2:$A$21,0),MATCH(Control!$B$3,Budget!$B$1:$AK$1,0)) -> 7745 | Q3: =C3-P3 -> -95.4 | R3: =_xlfn.XLOOKUP(A3,Banks!$A$2:$A$21,Banks!$E$2:$E$21) -> Media | S3: =CHOOSE(IF(R3="Grande",1,IF(R3="Media",2,3)),"A","B","C") -> B | T3: {=_xlfn.SWITCH(B3,"Nord-Ovest","NO","Nord-Est","NE","Centro","CE","Sud","SU","IS")} -> NE | U3: =IF(C3>=PERCENTILE($C$2:$C$21,0.75),"primo quartile",IF(C3<=PERCENTILE($C$2:$C$21,0.25),"ultimo quartile","centrale")) -> ultimo quartile | V3: =IF(A3=Control!$B$2,"<<","") | W3: =SUMIFS(Data!$H$2:$H$5761,Data!$A$2:$A$5761,A3,Data!$B$2:$B$5761,Control!$B$3) -> 840 | X3: =IFERROR(D3/W3,0) -> 0.49420238 | Y3: =C3*(1+Control!$B$4) -> 7879.088 | Z3: =IF(B3=Control!$B$5,C3,0) -> 0 | AA3: =_xlfn.LET(_xlpm.v,C3,_xlpm.b,P3,IF(_xlpm.b=0,0,ROUND((_xlpm.v-_xlpm.b)/_xlpm.b,4))) -> -0.0123 | AB3: {=SUMPRODUCT((Data!$A$2:$A$5761=A3)*(Data!$B$2:$B$5761<=Control!$B$3)*(Data!$J$2:$J$5761=Control!$B$11)*Data!$E$2:$E$5761)} -> 7649.6
A4: =Banks!A4 -> Banca Tirrena | B4: =VLOOKUP(A4,Banks!$A$2:$C$21,3,FALSE) -> Centro | C4: =SUMIFS(Data!$E:$E,Data!$A:$A,A4,Data!$B:$B,Control!$B$3) -> 8739.1 | D4: =SUMIFS(Data!$F$2:$F$5761,Data!$A$2:$A$5761,A4,Data!$B$2:$B$5761,Control!$B$3) -> 472.04 | E4: =SUMIFS(Data!$G$2:$G$5761,Data!$A$2:$A$5761,A4,Data!$B$2:$B$5761,Control!$B$3) -> 287.57 | F4: =D4-E4 -> 184.47 | G4: =SUMIFS(Data!$E$2:$E$5761,Data!$A$2:$A$5761,A4,Data!$B$2:$B$5761,Control!$B$13) -> 8718.7 | H4: =IFERROR(C4/G4-1,0) -> 0.0023397984 | I4: =SUMIFS(Data!$E$2:$E$5761,Data!$A$2:$A$5761,A4,Data!$B$2:$B$5761,Control!$B$14) -> 8012.1 | J4: =IFERROR(C4/I4-1,0) -> 0.090737759 | K4: =C4/SUM($C$2:$C$21) -> 0.025436881 | L4: =RANK(C4,$C$2:$C$21) -> 18 | M4: =_xlfn.MAXIFS(Data!$E$2:$E$5761,Data!$A$2:$A$5761,A4,Data!$C$2:$C$5761,"Mutui") -> 571.2 | N4: =AVERAGEIFS(Data!$E$2:$E$5761,Data!$A$2:$A$5761,A4,Data!$B$2:$B$5761,Control!$B$3) -> 1092.3875 | O4: =COUNTIFS(Data!$A$2:$A$5761,A4,Data!$B$2:$B$5761,Control!$B$3,Data!$E$2:$E$5761,">"&N4) -> 4 | P4: =INDEX(Budget!$B$2:$AK$21,MATCH(A4,Budget!$A$2:$A$21,0),MATCH(Control!$B$3,Budget!$B$1:$AK$1,0)) -> 8877 | Q4: =C4-P4 -> -137.9 | R4: =_xlfn.XLOOKUP(A4,Banks!$A$2:$A$21,Banks!$E$2:$E$21) -> Grande | S4: =CHOOSE(IF(R4="Grande",1,IF(R4="Media",2,3)),"A","B","C") -> A | T4: {=_xlfn.SWITCH(B4,"Nord-Ovest","NO","Nord-Est","NE","Centro","CE","Sud","SU","IS")} -> CE | U4: =IF(C4>=PERCENTILE($C$2:$C$21,0.75),"primo quartile",IF(C4<=PERCENTILE($C$2:$C$21,0.25),"ultimo quartile","centrale")) -> ultimo quartile | V4: =IF(A4=Control!$B$2,"<<","") -> << | W4: =SUMIFS(Data!$H$2:$H$5761,Data!$A$2:$A$5761,A4,Data!$B$2:$B$5761,Control!$B$3) -> 986 | X4: =IFERROR(D4/W4,0) -> 0.47874239 | Y4: =C4*(1+Control!$B$4) -> 9001.273 | Z4: =IF(B4=Control!$B$5,C4,0) -> 8739.1 | AA4: =_xlfn.LET(_xlpm.v,C4,_xlpm.b,P4,IF(_xlpm.b=0,0,ROUND((_xlpm.v-_xlpm.b)/_xlpm.b,4))) -> -0.0155 | AB4: {=SUMPRODUCT((Data!$A$2:$A$5761=A4)*(Data!$B$2:$B$5761<=Control!$B$3)*(Data!$J$2:$J$5761=Control!$B$11)*Data!$E$2:$E$5761)} -> 8739.1
A5: =Banks!A5 -> Banca Padana | B5: =VLOOKUP(A5,Banks!$A$2:$C$21,3,FALSE) -> Nord-Ovest | C5: =SUMIFS(Data!$E:$E,Data!$A:$A,A5,Data!$B:$B,Control!$B$3) -> 9892.6 | D5: =SUMIFS(Data!$F$2:$F$5761,Data!$A$2:$A$5761,A5,Data!$B$2:$B$5761,Control!$B$3) -> 534.73 | E5: =SUMIFS(Data!$G$2:$G$5761,Data!$A$2:$A$5761,A5,Data!$B$2:$B$5761,Control!$B$3) -> 322.31 | F5: =D5-E5 -> 212.42 | G5: =SUMIFS(Data!$E$2:$E$5761,Data!$A$2:$A$5761,A5,Data!$B$2:$B$5761,Control!$B$13) -> 9822.9 | H5: =IFERROR(C5/G5-1,0) -> 0.0070956642 | I5: =SUMIFS(Data!$E$2:$E$5761,Data!$A$2:$A$5761,A5,Data!$B$2:$B$5761,Control!$B$14) -> 9024.4 | J5: =IFERROR(C5/I5-1,0) -> 0.096205842 | K5: =C5/SUM($C$2:$C$21) -> 0.028794371 | L5: =RANK(C5,$C$2:$C$21) -> 17 | M5: =_xlfn.MAXIFS(Data!$E$2:$E$5761,Data!$A$2:$A$5761,A5,Data!$C$2:$C$5761,"Mutui") -> 624 | N5: =AVERAGEIFS(Data!$E$2:$E$5761,Data!$A$2:$A$5761,A5,Data!$B$2:$B$5761,Control!$B$3) -> 1236.575 | O5: =COUNTIFS(Data!$A$2:$A$5761,A5,Data!$B$2:$B$5761,Control!$B$3,Data!$E$2:$E$5761,">"&N5) -> 4 | P5: =INDEX(Budget!$B$2:$AK$21,MATCH(A5,Budget!$A$2:$A$21,0),MATCH(Control!$B$3,Budget!$B$1:$AK$1,0)) -> 10010 | Q5: =C5-P5 -> -117.4 | R5: =_xlfn.XLOOKUP(A5,Banks!$A$2:$A$21,Banks!$E$2:$E$21) -> Grande | S5: =CHOOSE(IF(R5="Grande",1,IF(R5="Media",2,3)),"A","B","C") -> A | T5: {=_xlfn.SWITCH(B5,"Nord-Ovest","NO","Nord-Est","NE","Centro","CE","Sud","SU","IS")} -> NO | U5: =IF(C5>=PERCENTILE($C$2:$C$21,0.75),"primo quartile",IF(C5<=PERCENTILE($C$2:$C$21,0.25),"ultimo quartile","centrale")) -> ultimo quartile | V5: =IF(A5=Control!$B$2,"<<","") | W5: =SUMIFS(Data!$H$2:$H$5761,Data!$A$2:$A$5761,A5,Data!$B$2:$B$5761,Control!$B$3) -> 1047 | X5: =IFERROR(D5/W5,0) -> 0.51072588 | Y5: =C5*(1+Control!$B$4) -> 10189.378 | Z5: =IF(B5=Control!$B$5,C5,0) -> 0 | AA5: =_xlfn.LET(_xlpm.v,C5,_xlpm.b,P5,IF(_xlpm.b=0,0,ROUND((_xlpm.v-_xlpm.b)/_xlpm.b,4))) -> -0.0117 | AB5: {=SUMPRODUCT((Data!$A$2:$A$5761=A5)*(Data!$B$2:$B$5761<=Control!$B$3)*(Data!$J$2:$J$5761=Control!$B$11)*Data!$E$2:$E$5761)} -> 9892.6
A6: =Banks!A6 -> Banca Etrusca | B6: =VLOOKUP(A6,Banks!$A$2:$C$21,3,FALSE) -> Centro | C6: =SUMIFS(Data!$E:$E,Data!$A:$A,A6,Data!$B:$B,Control!$B$3) -> 10989.1 | D6: =SUMIFS(Data!$F$2:$F$5761,Data!$A$2:$A$5761,A6,Data!$B$2:$B$5761,Control!$B$3) -> 594.2 | E6: =SUMIFS(Data!$G$2:$G$5761,Data!$A$2:$A$5761,A6,Data!$B$2:$B$5761,Control!$B$3) -> 360.56 | F6: =D6-E6 -> 233.64 | G6: =SUMIFS(Data!$E$2:$E$5761,Data!$A$2:$A$5761,A6,Data!$B$2:$B$5761,Control!$B$13) -> 10956.1 | H6: =IFERROR(C6/G6-1,0) -> 0.0030120207 | I6: =SUMIFS(Data!$E$2:$E$5761,Data!$A$2:$A$5761,A6,Data!$B$2:$B$5761,Control!$B$14) -> 9970.8 | J6: =IFERROR(C6/I6-1,0) -> 0.10212821 | K6: =C6/SUM($C$2:$C$21) -> 0.031985952 | L6: =RANK(C6,$C$2:$C$21) -> 16 | M6: =_xlfn.MAXIFS(Data!$E$2:$E$5761,Data!$A$2:$A$5761,A6,Data!$C$2:$C$5761,"Mutui") -> 699.2 | N6: =AVERAGEIFS(Data!$E$2:$E$5761,Data!$A$2:$A$5761,A6,Data!$B$2:$B$5761,Control!$B$3) -> 1373.6375 | O6: =COUNTIFS(Data!$A$2:$A$5761,A6,Data!$B$2:$B$5761,Control!$B$3,Data!$E$2:$E$5761,">"&N6) -> 4 | P6: =INDEX(Budget!$B$2:$AK$21,MATCH(A6,Budget!$A$2:$A$21,0),MATCH(Control!$B$3,Budget!$B$1:$AK$1,0)) -> 11142 | Q6: =C6-P6 -> -152.9 | R6: =_xlfn.XLOOKUP(A6,Banks!$A$2:$A$21,Banks!$E$2:$E$21) -> Media | S6: =CHOOSE(IF(R6="Grande",1,IF(R6="Media",2,3)),"A","B","C") -> B | T6: {=_xlfn.SWITCH(B6,"Nord-Ovest","NO","Nord-Est","NE","Centro","CE","Sud","SU","IS")} -> CE | U6: =IF(C6>=PERCENTILE($C$2:$C$21,0.75),"primo quartile",IF(C6<=PERCENTILE($C$2:$C$21,0.25),"ultimo quartile","centrale")) -> ultimo quartile | V6: =IF(A6=Control!$B$2,"<<","") | W6: =SUMIFS(Data!$H$2:$H$5761,Data!$A$2:$A$5761,A6,Data!$B$2:$B$5761,Control!$B$3) -> 1127 | X6: =IFERROR(D6/W6,0) -> 0.52724046 | Y6: =C6*(1+Control!$B$4) -> 11318.773 | Z6: =IF(B6=Control!$B$5,C6,0) -> 10989.1 | AA6: =_xlfn.LET(_xlpm.v,C6,_xlpm.b,P6,IF(_xlpm.b=0,0,ROUND((_xlpm.v-_xlpm.b)/_xlpm.b,4))) -> -0.0137 | AB6: {=SUMPRODUCT((Data!$A$2:$A$5761=A6)*(Data!$B$2:$B$5761<=Control!$B$3)*(Data!$J$2:$J$5761=Control!$B$11)*Data!$E$2:$E$5761)} -> 10989.1
A7: =Banks!A7 -> Banca Lariana | B7: =VLOOKUP(A7,Banks!$A$2:$C$21,3,FALSE) -> Nord-Ovest | C7: =SUMIFS(Data!$E:$E,Data!$A:$A,A7,Data!$B:$B,Control!$B$3) -> 12105.6 | D7: =SUMIFS(Data!$F$2:$F$5761,Data!$A$2:$A$5761,A7,Data!$B$2:$B$5761,Control!$B$3) -> 653.86 | E7: =SUMIFS(Data!$G$2:$G$5761,Data!$A$2:$A$5761,A7,Data!$B$2:$B$5761,Control!$B$3) -> 394.85 | F7: =D7-E7 -> 259.01 | G7: =SUMIFS(Data!$E$2:$E$5761,Data!$A$2:$A$5761,A7,Data!$B$2:$B$5761,Control!$B$13) -> 12114.3 | H7: =IFERROR(C7/G7-1,0) -> -0.00071815953 | I7: =SUMIFS(Data!$E$2:$E$5761,Data!$A$2:$A$5761,A7,Data!$B$2:$B$5761,Control!$B$14) -> 11120.3 | J7: =IFERROR(C7/I7-1,0) -> 0.088603725 | K7: =C7/SUM($C$2:$C$21) -> 0.035235746 | L7: =RANK(C7,$C$2:$C$21) -> 15 | M7: =_xlfn.MAXIFS(Data!$E$2:$E$5761,Data!$A$2:$A$5761,A7,Data!$C$2:$C$5761,"Mutui") -> 786.7 | N7: =AVERAGEIFS(Data!$E$2:$E$5761,Data!$A$2:$A$5761,A7,Data!$B$2:$B$5761,Control!$B$3) -> 1513.2 | O7: =COUNTIFS(Data!$A$2:$A$5761,A7,Data!$B$2:$B$5761,Control!$B$3,Data!$E$2:$E$5761,">"&N7) -> 4 | P7: =INDEX(Budget!$B$2:$AK$21,MATCH(A7,Budget!$A$2:$A$21,0),MATCH(Control!$B$3,Budget!$B$1:$AK$1,0)) -> 12275 | Q7: =C7-P7 -> -169.4 | R7: =_xlfn.XLOOKUP(A7,Banks!$A$2:$A$21,Banks!$E$2:$E$21) -> Piccola | S7: =CHOOSE(IF(R7="Grande",1,IF(R7="Media",2,3)),"A","B","C") -> C | T7: {=_xlfn.SWITCH(B7,"Nord-Ovest","NO","Nord-Est","NE","Centro","CE","Sud","SU","IS")} -> NO | U7: =IF(C7>=PERCENTILE($C$2:$C$21,0.75),"primo quartile",IF(C7<=PERCENTILE($C$2:$C$21,0.25),"ultimo quartile","centrale")) -> centrale | V7: =IF(A7=Control!$B$2,"<<","") | W7: =SUMIFS(Data!$H$2:$H$5761,Data!$A$2:$A$5761,A7,Data!$B$2:$B$5761,Control!$B$3) -> 1277 | X7: =IFERROR(D7/W7,0) -> 0.51202819 | Y7: =C7*(1+Control!$B$4) -> 12468.768 | Z7: =IF(B7=Control!$B$5,C7,0) -> 0 | AA7: =_xlfn.LET(_xlpm.v,C7,_xlpm.b,P7,IF(_xlpm.b=0,0,ROUND((_xlpm.v-_xlpm.b)/_xlpm.b,4))) -> -0.0138 | AB7: {=SUMPRODUCT((Data!$A$2:$A$5761=A7)*(Data!$B$2:$B$5761<=Control!$B$3)*(Data!$J$2:$J$5761=Control!$B$11)*Data!$E$2:$E$5761)} -> 12105.6
A8: =Banks!A8 -> Banca Sabina | B8: =VLOOKUP(A8,Banks!$A$2:$C$21,3,FALSE) -> Centro | C8: =SUMIFS(Data!$E:$E,Data!$A:$A,A8,Data!$B:$B,Control!$B$3) -> 13300.5 | D8: =SUMIFS(Data!$F$2:$F$5761,Data!$A$2:$A$5761,A8,Data!$B$2:$B$5761,Control!$B$3) -> 718.87 | E8: =SUMIFS(Data!$G$2:$G$5761,Data!$A$2:$A$5761,A8,Data!$B$2:$B$5761,Control!$B$3) -> 434.17 | F8: =D8-E8 -> 284.7 | G8: =SUMIFS(Data!$E$2:$E$5761,Data!$A$2:$A$5761,A8,Data!$B$2:$B$5761,Control!$B$13) -> 13117.7 | H8: =IFERROR(C8/G8-1,0) -> 0.01393537 | I8: =SUMIFS(Data!$E$2:$E$5761,Data!$A$2:$A$5761,A8,Data!$B$2:$B$5761,Control!$B$14) -> 12033 | J8: =IFERROR(C8/I8-1,0) -> 0.10533533 | K8: =C8/SUM($C$2:$C$21) -> 0.038713739 | L8: =RANK(C8,$C$2:$C$21) -> 14 | M8: =_xlfn.MAXIFS(Data!$E$2:$E$5761,Data!$A$2:$A$5761,A8,Data!$C$2:$C$5761,"Mutui") -> 847.9 | N8: =AVERAGEIFS(Data!$E$2:$E$5761,Data!$A$2:$A$5761,A8,Data!$B$2:$B$5761,Control!$B$3) -> 1662.5625 | O8: =COUNTIFS(Data!$A$2:$A$5761,A8,Data!$B$2:$B$5761,Control!$B$3,Data!$E$2:$E$5761,">"&N8) -> 4 | P8: =INDEX(Budget!$B$2:$AK$21,MATCH(A8,Budget!$A$2:$A$21,0),MATCH(Control!$B$3,Budget!$B$1:$AK$1,0)) -> 13407 | Q8: =C8-P8 -> -106.5 | R8: =_xlfn.XLOOKUP(A8,Banks!$A$2:$A$21,Banks!$E$2:$E$21) -> Piccola | S8: =CHOOSE(IF(R8="Grande",1,IF(R8="Media",2,3)),"A","B","C") -> C | T8: {=_xlfn.SWITCH(B8,"Nord-Ovest","NO","Nord-Est","NE","Centro","CE","Sud","SU","IS")} -> CE | U8: =IF(C8>=PERCENTILE($C$2:$C$21,0.75),"primo quartile",IF(C8<=PERCENTILE($C$2:$C$21,0.25),"ultimo quartile","centrale")) -> centrale | V8: =IF(A8=Control!$B$2,"<<","") | W8: =SUMIFS(Data!$H$2:$H$5761,Data!$A$2:$A$5761,A8,Data!$B$2:$B$5761,Control!$B$3) -> 1381 | X8: =IFERROR(D8/W8,0) -> 0.52054308 | Y8: =C8*(1+Control!$B$4) -> 13699.515 | Z8: =IF(B8=Control!$B$5,C8,0) -> 13300.5 | AA8: =_xlfn.LET(_xlpm.v,C8,_xlpm.b,P8,IF(_xlpm.b=0,0,ROUND((_xlpm.v-_xlpm.b)/_xlpm.b,4))) -> -0.0079 | AB8: {=SUMPRODUCT((Data!$A$2:$A$5761=A8)*(Data!$B$2:$B$5761<=Control!$B$3)*(Data!$J$2:$J$5761=Control!$B$11)*Data!$E$2:$E$5761)} -> 13300.5
A9: =Banks!A9 -> Banca Irpina | B9: =VLOOKUP(A9,Banks!$A$2:$C$21,3,FALSE) -> Sud | C9: =SUMIFS(Data!$E:$E,Data!$A:$A,A9,Data!$B:$B,Control!$B$3) -> 14379.3 | D9: =SUMIFS(Data!$F$2:$F$5761,Data!$A$2:$A$5761,A9,Data!$B$2:$B$5761,Control!$B$3) -> 776.25 | E9: =SUMIFS(Data!$G$2:$G$5761,Data!$A$2:$A$5761,A9,Data!$B$2:$B$5761,Control!$B$3) -> 470.41 | F9: =D9-E9 -> 305.84 | G9: =SUMIFS(Data!$E$2:$E$5761,Data!$A$2:$A$5761,A9,Data!$B$2:$B$5761,Control!$B$13) -> 14263.4 | H9: =IFERROR(C9/G9-1,0) -> 0.0081256923 | I9: =SUMIFS(Data!$E$2:$E$5761,Data!$A$2:$A$5761,A9,Data!$B$2:$B$5761,Control!$B$14) -> 13187.6 | J9: =IFERROR(C9/I9-1,0) -> 0.090365192 | K9: =C9/SUM($C$2:$C$21) -> 0.0418538 | L9: =RANK(C9,$C$2:$C$21) -> 13 | M9: =_xlfn.MAXIFS(Data!$E$2:$E$5761,Data!$A$2:$A$5761,A9,Data!$C$2:$C$5761,"Mutui") -> 908.5 | N9: =AVERAGEIFS(Data!$E$2:$E$5761,Data!$A$2:$A$5761,A9,Data!$B$2:$B$5761,Control!$B$3) -> 1797.4125 | O9: =COUNTIFS(Data!$A$2:$A$5761,A9,Data!$B$2:$B$5761,Control!$B$3,Data!$E$2:$E$5761,">"&N9) -> 4 | P9: =INDEX(Budget!$B$2:$AK$21,MATCH(A9,Budget!$A$2:$A$21,0),MATCH(Control!$B$3,Budget!$B$1:$AK$1,0)) -> 14540 | Q9: =C9-P9 -> -160.7 | R9: =_xlfn.XLOOKUP(A9,Banks!$A$2:$A$21,Banks!$E$2:$E$21) -> Piccola | S9: =CHOOSE(IF(R9="Grande",1,IF(R9="Media",2,3)),"A","B","C") -> C | T9: {=_xlfn.SWITCH(B9,"Nord-Ovest","NO","Nord-Est","NE","Centro","CE","Sud","SU","IS")} -> SU | U9: =IF(C9>=PERCENTILE($C$2:$C$21,0.75),"primo quartile",IF(C9<=PERCENTILE($C$2:$C$21,0.25),"ultimo quartile","centrale")) -> centrale | V9: =IF(A9=Control!$B$2,"<<","") | W9: =SUMIFS(Data!$H$2:$H$5761,Data!$A$2:$A$5761,A9,Data!$B$2:$B$5761,Control!$B$3) -> 1514 | X9: =IFERROR(D9/W9,0) -> 0.51271466 | Y9: =C9*(1+Control!$B$4) -> 14810.679 | Z9: =IF(B9=Control!$B$5,C9,0) -> 0 | AA9: =_xlfn.LET(_xlpm.v,C9,_xlpm.b,P9,IF(_xlpm.b=0,0,ROUND((_xlpm.v-_xlpm.b)/_xlpm.b,4))) -> -0.0111 | AB9: {=SUMPRODUCT((Data!$A$2:$A$5761=A9)*(Data!$B$2:$B$5761<=Control!$B$3)*(Data!$J$2:$J$5761=Control!$B$11)*Data!$E$2:$E$5761)} -> 14379.3
A10: =Banks!A10 -> Banca Sannita | B10: =VLOOKUP(A10,Banks!$A$2:$C$21,3,FALSE) -> Sud | C10: =SUMIFS(Data!$E:$E,Data!$A:$A,A10,Data!$B:$B,Control!$B$3) -> 15489.6 | D10: =SUMIFS(Data!$F$2:$F$5761,Data!$A$2:$A$5761,A10,Data!$B$2:$B$5761,Control!$B$3) -> 837.25 | E10: =SUMIFS(Data!$G$2:$G$5761,Data!$A$2:$A$5761,A10,Data!$B$2:$B$5761,Control!$B$3) -> 504.85 | F10: =D10-E10 -> 332.4 | G10: =SUMIFS(Data!$E$2:$E$5761,Data!$A$2:$A$5761,A10,Data!$B$2:$B$5761,Control!$B$13) -> 15359.6 | H10: =IFERROR(C10/G10-1,0) -> 0.0084637621 | I10: =SUMIFS(Data!$E$2:$E$5761,Data!$A$2:$A$5761,A10,Data!$B$2:$B$5761,Control!$B$14) -> 14125.8 | J10: =IFERROR(C10/I10-1,0) -> 0.096546744 | K10: =C10/SUM($C$2:$C$21) -> 0.045085548 | L10: =RANK(C10,$C$2:$C$21) -> 12 | M10: =_xlfn.MAXIFS(Data!$E$2:$E$5761,Data!$A$2:$A$5761,A10,Data!$C$2:$C$5761,"Mutui") -> 958.8 | N10: =AVERAGEIFS(Data!$E$2:$E$5761,Data!$A$2:$A$5761,A10,Data!$B$2:$B$5761,Control!$B$3) -> 1936.2 | O10: =COUNTIFS(Data!$A$2:$A$5761,A10,Data!$B$2:$B$5761,Control!$B$3,Data!$E$2:$E$5761,">"&N10) -> 4 | P10: =INDEX(Budget!$B$2:$AK$21,MATCH(A10,Budget!$A$2:$A$21,0),MATCH(Control!$B$3,Budget!$B$1:$AK$1,0)) -> 15672 | Q10: =C10-P10 -> -182.4 | R10: =_xlfn.XLOOKUP(A10,Banks!$A$2:$A$21,Banks!$E$2:$E$21) -> Media | S10: =CHOOSE(IF(R10="Grande",1,IF(R10="Media",2,3)),"A","B","C") -> B | T10: {=_xlfn.SWITCH(B10,"Nord-Ovest","NO","Nord-Est","NE","Centro","CE","Sud","SU","IS")} -> SU | U10: =IF(C10>=PERCENTILE($C$2:$C$21,0.75),"primo quartile",IF(C10<=PERCENTILE($C$2:$C$21,0.25),"ultimo quartile","centrale")) -> centrale | V10: =IF(A10=Control!$B$2,"<<","") | W10: =SUMIFS(Data!$H$2:$H$5761,Data!$A$2:$A$5761,A10,Data!$B$2:$B$5761,Control!$B$3) -> 1619 | X10: =IFERROR(D10/W10,0) -> 0.51714021 | Y10: =C10*(1+Control!$B$4) -> 15954.288 | Z10: =IF(B10=Control!$B$5,C10,0) -> 0 | AA10: =_xlfn.LET(_xlpm.v,C10,_xlpm.b,P10,IF(_xlpm.b=0,0,ROUND((_xlpm.v-_xlpm.b)/_xlpm.b,4))) -> -0.0116 | AB10: {=SUMPRODUCT((Data!$A$2:$A$5761=A10)*(Data!$B$2:$B$5761<=Control!$B$3)*(Data!$J$2:$J$5761=Control!$B$11)*Data!$E$2:$E$5761)} -> 15489.6
A11: =Banks!A11 -> Banca Ligure | B11: =VLOOKUP(A11,Banks!$A$2:$C$21,3,FALSE) -> Nord-Ovest | C11: =SUMIFS(Data!$E:$E,Data!$A:$A,A11,Data!$B:$B,Control!$B$3) -> 16648 | D11: =SUMIFS(Data!$F$2:$F$5761,Data!$A$2:$A$5761,A11,Data!$B$2:$B$5761,Control!$B$3) -> 897.79 | E11: =SUMIFS(Data!$G$2:$G$5761,Data!$A$2:$A$5761,A11,Data!$B$2:$B$5761,Control!$B$3) -> 540.39 | F11: =D11-E11 -> 357.4 | G11: =SUMIFS(Data!$E$2:$E$5761,Data!$A$2:$A$5761,A11,Data!$B$2:$B$5761,Control!$B$13) -> 16477 | H11: =IFERROR(C11/G11-1,0) -> 0.010378103 | I11: =SUMIFS(Data!$E$2:$E$5761,Data!$A$2:$A$5761,A11,Data!$B$2:$B$5761,Control!$B$14) -> 15173.2 | J11: =IFERROR(C11/I11-1,0) -> 0.097197691 | K11: =C11/SUM($C$2:$C$21) -> 0.048457301 | L11: =RANK(C11,$C$2:$C$21) -> 11 | M11: =_xlfn.MAXIFS(Data!$E$2:$E$5761,Data!$A$2:$A$5761,A11,Data!$C$2:$C$5761,"Mutui") -> 1062.4 | N11: =AVERAGEIFS(Data!$E$2:$E$5761,Data!$A$2:$A$5761,A11,Data!$B$2:$B$5761,Control!$B$3) -> 2081 | O11: =COUNTIFS(Data!$A$2:$A$5761,A11,Data!$B$2:$B$5761,Control!$B$3,Data!$E$2:$E$5761,">"&N11) -> 4 | P11: =INDEX(Budget!$B$2:$AK$21,MATCH(A11,Budget!$A$2:$A$21,0),MATCH(Control!$B$3,Budget!$B$1:$AK$1,0)) -> 16804 | Q11: =C11-P11 -> -156 | R11: =_xlfn.XLOOKUP(A11,Banks!$A$2:$A$21,Banks!$E$2:$E$21) -> Media | S11: =CHOOSE(IF(R11="Grande",1,IF(R11="Media",2,3)),"A","B","C") -> B | T11: {=_xlfn.SWITCH(B11,"Nord-Ovest","NO","Nord-Est","NE","Centro","CE","Sud","SU","IS")} -> NO | U11: =IF(C11>=PERCENTILE($C$2:$C$21,0.75),"primo quartile",IF(C11<=PERCENTILE($C$2:$C$21,0.25),"ultimo quartile","centrale")) -> centrale | V11: =IF(A11=Control!$B$2,"<<","") | W11: =SUMIFS(Data!$H$2:$H$5761,Data!$A$2:$A$5761,A11,Data!$B$2:$B$5761,Control!$B$3) -> 1679 | X11: =IFERROR(D11/W11,0) -> 0.53471709 | Y11: =C11*(1+Control!$B$4) -> 17147.44 | Z11: =IF(B11=Control!$B$5,C11,0) -> 0 | AA11: =_xlfn.LET(_xlpm.v,C11,_xlpm.b,P11,IF(_xlpm.b=0,0,ROUND((_xlpm.v-_xlpm.b)/_xlpm.b,4))) -> -0.0093 | AB11: {=SUMPRODUCT((Data!$A$2:$A$5761=A11)*(Data!$B$2:$B$5761<=Control!$B$3)*(Data!$J$2:$J$5761=Control!$B$11)*Data!$E$2:$E$5761)} -> 16648
A12: =Banks!A12 -> Banca Veneta | B12: =VLOOKUP(A12,Banks!$A$2:$C$21,3,FALSE) -> Nord-Est | C12: =SUMIFS(Data!$E:$E,Data!$A:$A,A12,Data!$B:$B,Control!$B$3) -> 17663.9 | D12: =SUMIFS(Data!$F$2:$F$5761,Data!$A$2:$A$5761,A12,Data!$B$2:$B$5761,Control!$B$3) -> 952.44 | E12: =SUMIFS(Data!$G$2:$G$5761,Data!$A$2:$A$5761,A12,Data!$B$2:$B$5761,Control!$B$3) -> 575.91 | F12: =D12-E12 -> 376.53 | G12: =SUMIFS(Data!$E$2:$E$5761,Data!$A$2:$A$5761,A12,Data!$B$2:$B$5761,Control!$B$13) -> 17610.2 | H12: =IFERROR(C12/G12-1,0) -> 0.0030493691 | I12: =SUMIFS(Data!$E$2:$E$5761,Data!$A$2:$A$5761,A12,Data!$B$2:$B$5761,Control!$B$14) -> 16227.5 | J12: =IFERROR(C12/I12-1,0) -> 0.088516407 | K12: =C12/SUM($C$2:$C$21) -> 0.051414279 | L12: =RANK(C12,$C$2:$C$21) -> 10 | M12: =_xlfn.MAXIFS(Data!$E$2:$E$5761,Data!$A$2:$A$5761,A12,Data!$C$2:$C$5761,"Mutui") -> 1135.6 | N12: =AVERAGEIFS(Data!$E$2:$E$5761,Data!$A$2:$A$5761,A12,Data!$B$2:$B$5761,Control!$B$3) -> 2207.9875 | O12: =COUNTIFS(Data!$A$2:$A$5761,A12,Data!$B$2:$B$5761,Control!$B$3,Data!$E$2:$E$5761,">"&N12) -> 4 | P12: =INDEX(Budget!$B$2:$AK$21,MATCH(A12,Budget!$A$2:$A$21,0),MATCH(Control!$B$3,Budget!$B$1:$AK$1,0)) -> 17937 | Q12: =C12-P12 -> -273.1 | R12: =_xlfn.XLOOKUP(A12,Banks!$A$2:$A$21,Banks!$E$2:$E$21) -> Grande | S12: =CHOOSE(IF(R12="Grande",1,IF(R12="Media",2,3)),"A","B","C") -> A | T12: {=_xlfn.SWITCH(B12,"Nord-Ovest","NO","Nord-Est","NE","Centro","CE","Sud","SU","IS")} -> NE | U12: =IF(C12>=PERCENTILE($C$2:$C$21,0.75),"primo quartile",IF(C12<=PERCENTILE($C$2:$C$21,0.25),"ultimo quartile","centrale")) -> centrale | V12: =IF(A12=Control!$B$2,"<<","") | W12: =SUMIFS(Data!$H$2:$H$5761,Data!$A$2:$A$5761,A12,Data!$B$2:$B$5761,Control!$B$3) -> 1831 | X12: =IFERROR(D12/W12,0) -> 0.52017477 | Y12: =C12*(1+Control!$B$4) -> 18193.817 | Z12: =IF(B12=Control!$B$5,C12,0) -> 0 | AA12: =_xlfn.LET(_xlpm.v,C12,_xlpm.b,P12,IF(_xlpm.b=0,0,ROUND((_xlpm.v-_xlpm.b)/_xlpm.b,4))) -> -0.0152 | AB12: {=SUMPRODUCT((Data!$A$2:$A$5761=A12)*(Data!$B$2:$B$5761<=Control!$B$3)*(Data!$J$2:$J$5761=Control!$B$11)*Data!$E$2:$E$5761)} -> 17663.9
A13: =Banks!A13 -> Banca Friulana | B13: =VLOOKUP(A13,Banks!$A$2:$C$21,3,FALSE) -> Nord-Est | C13: =SUMIFS(Data!$E:$E,Data!$A:$A,A13,Data!$B:$B,Control!$B$3) -> 18941.6 | D13: =SUMIFS(Data!$F$2:$F$5761,Data!$A$2:$A$5761,A13,Data!$B$2:$B$5761,Control!$B$3) -> 1020.23 | E13: =SUMIFS(Data!$G$2:$G$5761,Data!$A$2:$A$5761,A13,Data!$B$2:$B$5761,Control!$B$3) -> 615.31 | F13: =D13-E13 -> 404.92 | G13: =SUMIFS(Data!$E$2:$E$5761,Data!$A$2:$A$5761,A13,Data!$B$2:$B$5761,Control!$B$13) -> 18661.5 | H13: =IFERROR(C13/G13-1,0) -> 0.015009512 | I13: =SUMIFS(Data!$E$2:$E$5761,Data!$A$2:$A$5761,A13,Data!$B$2:$B$5761,Control!$B$14) -> 17231.8 | J13: =IFERROR(C13/I13-1,0) -> 0.099223529 | K13: =C13/SUM($C$2:$C$21) -> 0.055133278 | L13: =RANK(C13,$C$2:$C$21) -> 9 | M13: =_xlfn.MAXIFS(Data!$E$2:$E$5761,Data!$A$2:$A$5761,A13,Data!$C$2:$C$5761,"Mutui") -> 1207 | N13: =AVERAGEIFS(Data!$E$2:$E$5761,Data!$A$2:$A$5761,A13,Data!$B$2:$B$5761,Control!$B$3) -> 2367.7 | O13: =COUNTIFS(Data!$A$2:$A$5761,A13,Data!$B$2:$B$5761,Control!$B$3,Data!$E$2:$E$5761,">"&N13) -> 4 | P13: =INDEX(Budget!$B$2:$AK$21,MATCH(A13,Budget!$A$2:$A$21,0),MATCH(Control!$B$3,Budget!$B$1:$AK$1,0)) -> 19069 | Q13: =C13-P13 -> -127.4 | R13: =_xlfn.XLOOKUP(A13,Banks!$A$2:$A$21,Banks!$E$2:$E$21) -> Media | S13: =CHOOSE(IF(R13="Grande",1,IF(R13="Media",2,3)),"A","B","C") -> B | T13: {=_xlfn.SWITCH(B13,"Nord-Ovest","NO","Nord-Est","NE","Centro","CE","Sud","SU","IS")} -> NE | U13: =IF(C13>=PERCENTILE($C$2:$C$21,0.75),"primo quartile",IF(C13<=PERCENTILE($C$2:$C$21,0.25),"ultimo quartile","centrale")) -> centrale | V13: =IF(A13=Control!$B$2,"<<","") | W13: =SUMIFS(Data!$H$2:$H$5761,Data!$A$2:$A$5761,A13,Data!$B$2:$B$5761,Control!$B$3) -> 1888 | X13: =IFERROR(D13/W13,0) -> 0.54037606 | Y13: =C13*(1+Control!$B$4) -> 19509.848 | Z13: =IF(B13=Control!$B$5,C13,0) -> 0 | AA13: =_xlfn.LET(_xlpm.v,C13,_xlpm.b,P13,IF(_xlpm.b=0,0,ROUND((_xlpm.v-_xlpm.b)/_xlpm.b,4))) -> -0.0067 | AB13: {=SUMPRODUCT((Data!$A$2:$A$5761=A13)*(Data!$B$2:$B$5761<=Control!$B$3)*(Data!$J$2:$J$5761=Control!$B$11)*Data!$E$2:$E$5761)} -> 18941.6
... A21: =Banks!A21 -> Banca Città | B21: =VLOOKUP(A21,Banks!$A$2:$C$21,3,FALSE) -> Centro | C21: =SUMIFS(Data!$E:$E,Data!$A:$A,A21,Data!$B:$B,Control!$B$3) -> 27692.4 | D21: =SUMIFS(Data!$F$2:$F$5761,Data!$A$2:$A$5761,A21,Data!$B$2:$B$5761,Control!$B$3) -> 1493.04 | E21: =SUMIFS(Data!$G$2:$G$5761,Data!$A$2:$A$5761,A21,Data!$B$2:$B$5761,Control!$B$3) -> 899.93 | F21: =D21-E21 -> 593.11 | G21: =SUMIFS(Data!$E$2:$E$5761,Data!$A$2:$A$5761,A21,Data!$B$2:$B$5761,Control!$B$13) -> 27565 | H21: =IFERROR(C21/G21-1,0) -> 0.004621803 | I21: =SUMIFS(Data!$E$2:$E$5761,Data!$A$2:$A$5761,A21,Data!$B$2:$B$5761,Control!$B$14) -> 25464.4 | J21: =IFERROR(C21/I21-1,0) -> 0.087494698 | K21: =C21/SUM($C$2:$C$21) -> 0.080604214 | L21: =RANK(C21,$C$2:$C$21) -> 1 | M21: =_xlfn.MAXIFS(Data!$E$2:$E$5761,Data!$A$2:$A$5761,A21,Data!$C$2:$C$5761,"Mutui") -> 1762 | N21: =AVERAGEIFS(Data!$E$2:$E$5761,Data!$A$2:$A$5761,A21,Data!$B$2:$B$5761,Control!$B$3) -> 3461.55 | O21: =COUNTIFS(Data!$A$2:$A$5761,A21,Data!$B$2:$B$5761,Control!$B$3,Data!$E$2:$E$5761,">"&N21) -> 4 | P21: =INDEX(Budget!$B$2:$AK$21,MATCH(A21,Budget!$A$2:$A$21,0),MATCH(Control!$B$3,Budget!$B$1:$AK$1,0)) -> 28129 | Q21: =C21-P21 -> -436.6 | R21: =_xlfn.XLOOKUP(A21,Banks!$A$2:$A$21,Banks!$E$2:$E$21) -> Grande | S21: =CHOOSE(IF(R21="Grande",1,IF(R21="Media",2,3)),"A","B","C") -> A | T21: {=_xlfn.SWITCH(B21,"Nord-Ovest","NO","Nord-Est","NE","Centro","CE","Sud","SU","IS")} -> CE | U21: =IF(C21>=PERCENTILE($C$2:$C$21,0.75),"primo quartile",IF(C21<=PERCENTILE($C$2:$C$21,0.25),"ultimo quartile","centrale")) -> primo quartile | V21: =IF(A21=Control!$B$2,"<<","") | W21: =SUMIFS(Data!$H$2:$H$5761,Data!$A$2:$A$5761,A21,Data!$B$2:$B$5761,Control!$B$3) -> 2670 | X21: =IFERROR(D21/W21,0) -> 0.55919101 | Y21: =C21*(1+Control!$B$4) -> 28523.172 | Z21: =IF(B21=Control!$B$5,C21,0) -> 27692.4 | AA21: =_xlfn.LET(_xlpm.v,C21,_xlpm.b,P21,IF(_xlpm.b=0,0,ROUND((_xlpm.v-_xlpm.b)/_xlpm.b,4))) -> -0.0155 | AB21: {=SUMPRODUCT((Data!$A$2:$A$5761=A21)*(Data!$B$2:$B$5761<=Control!$B$3)*(Data!$J$2:$J$5761=Control!$B$11)*Data!$E$2:$E$5761)} -> 27692.4
A23: Totale | C23: =SUM(C2:C21) -> 343560.2 | D23: =SUM(D2:D21) -> 18530.43 | E23: =SUM(E2:E21) -> 11192.29 | F23: =SUM(F2:F21) -> 7338.14 | G23: =SUM(G2:G21) -> 340849.5 | K23: =SUM(K2:K21) -> 1

Sheet Calc_Product
A1: Prodotto | B1: Volumi | C1: Ricavi | D1: Costi | E1: Margine | F1: Peso | G1: Margine pesato | H1: Quota | I1: Rango | J1: YTD | K1: Mercato | L1: Quota mercato | M1: Categoria | N1: Riga chiave | O1: Volumi da chiave
